5:return {{["x"] = 5, ["y"] = 15, ["param1"] = 56, ["z"] = 17, ["name"] = "default:wood"}, {["x"] = 5, ["y"] = 16, ["param1"] = 56, ["z"] = 16, ["name"] = "default:wood"}, {["x"] = 5, ["y"] = 16, ["param1"] = 56, ["z"] = 17, ["name"] = "default:wood"}, {["x"] = 5, ["y"] = 16, ["param1"] = 56, ["z"] = 18, ["name"] = "default:wood"}, {["x"] = 5, ["y"] = 17, ["param1"] = 56, ["z"] = 15, ["name"] = "default:wood"}, {["x"] = 5, ["y"] = 17, ["param1"] = 56, ["z"] = 16, ["name"] = "default:wood"}, {["x"] = 5, ["y"] = 17, ["param1"] = 56, ["z"] = 17, ["name"] = "default:wood"}, {["x"] = 5, ["y"] = 17, ["param1"] = 56, ["z"] = 18, ["name"] = "default:wood"}, {["x"] = 5, ["y"] = 17, ["param1"] = 56, ["z"] = 19, ["name"] = "default:wood"}, {["x"] = 5, ["y"] = 18, ["param1"] = 56, ["z"] = 16, ["name"] = "default:wood"}, {["x"] = 5, ["y"] = 18, ["param1"] = 56, ["z"] = 17, ["name"] = "default:wood"}, {["x"] = 5, ["y"] = 18, ["param1"] = 56, ["z"] = 18, ["name"] = "default:wood"}, {["x"] = 5, ["y"] = 18, ["param1"] = 56, ["z"] = 19, ["name"] = "default:wood"}, {["x"] = 5, ["y"] = 18, ["param1"] = 56, ["z"] = 20, ["name"] = "default:wood"}, {["x"] = 5, ["y"] = 19, ["param1"] = 56, ["z"] = 17, ["name"] = "default:wood"}, {["x"] = 5, ["y"] = 19, ["param1"] = 56, ["z"] = 18, ["name"] = "default:wood"}, {["x"] = 5, ["y"] = 19, ["param1"] = 56, ["z"] = 19, ["name"] = "default:wood"}, {["x"] = 5, ["y"] = 19, ["param1"] = 56, ["z"] = 20, ["name"] = "default:wood"}, {["x"] = 5, ["y"] = 19, ["param1"] = 56, ["z"] = 21, ["name"] = "default:wood"}, {["x"] = 5, ["y"] = 20, ["param1"] = 56, ["z"] = 18, ["name"] = "default:wood"}, {["x"] = 5, ["y"] = 20, ["param1"] = 56, ["z"] = 19, ["name"] = "default:wood"}, {["x"] = 5, ["y"] = 20, ["param1"] = 56, ["z"] = 20, ["name"] = "default:wood"}, {["x"] = 5, ["y"] = 20, ["param1"] = 56, ["z"] = 21, ["name"] = "default:wood"}, {["x"] = 5, ["y"] = 20, ["param1"] = 56, ["z"] = 22, ["name"] = "default:wood"}, {["x"] = 5, ["y"] = 21, ["param1"] = 56, ["z"] = 19, ["name"] = "default:wood"}, {["x"] = 5, ["y"] = 21, ["param1"] = 56, ["z"] = 20, ["name"] = "default:wood"}, {["x"] = 5, ["y"] = 21, ["param1"] = 56, ["z"] = 21, ["name"] = "default:wood"}, {["x"] = 5, ["y"] = 21, ["param1"] = 56, ["z"] = 22, ["name"] = "default:wood"}, {["x"] = 5, ["y"] = 21, ["param1"] = 56, ["z"] = 23, ["name"] = "default:wood"}, {["x"] = 5, ["y"] = 22, ["param1"] = 56, ["z"] = 20, ["name"] = "default:wood"}, {["x"] = 5, ["y"] = 22, ["param1"] = 56, ["z"] = 21, ["name"] = "default:wood"}, {["x"] = 5, ["y"] = 22, ["param1"] = 56, ["z"] = 22, ["name"] = "default:wood"}, {["x"] = 5, ["y"] = 22, ["param1"] = 56, ["z"] = 23, ["name"] = "default:wood"}, {["x"] = 5, ["y"] = 22, ["param1"] = 56, ["z"] = 24, ["name"] = "default:wood"}, {["x"] = 5, ["y"] = 23, ["param1"] = 56, ["z"] = 21, ["name"] = "default:wood"}, {["x"] = 5, ["y"] = 23, ["param1"] = 56, ["z"] = 22, ["name"] = "default:wood"}, {["x"] = 5, ["y"] = 23, ["param1"] = 56, ["z"] = 23, ["name"] = "default:wood"}, {["x"] = 5, ["y"] = 23, ["param1"] = 56, ["z"] = 24, ["name"] = "default:wood"}, {["x"] = 5, ["y"] = 23, ["param1"] = 56, ["z"] = 25, ["name"] = "default:wood"}, {["x"] = 5, ["y"] = 24, ["param1"] = 56, ["z"] = 22, ["name"] = "default:wood"}, {["x"] = 5, ["y"] = 24, ["param1"] = 56, ["z"] = 23, ["name"] = "default:wood"}, {["x"] = 5, ["y"] = 24, ["param1"] = 56, ["z"] = 24, ["name"] = "default:wood"}, {["x"] = 5, ["y"] = 24, ["param1"] = 56, ["z"] = 25, ["name"] = "default:wood"}, {["x"] = 5, ["y"] = 24, ["param1"] = 56, ["z"] = 26, ["name"] = "default:wood"}, {["x"] = 5, ["y"] = 25, ["param1"] = 56, ["z"] = 23, ["name"] = "default:wood"}, {["x"] = 5, ["y"] = 25, ["param1"] = 56, ["z"] = 24, ["name"] = "default:wood"}, {["x"] = 5, ["y"] = 25, ["param1"] = 56, ["z"] = 25, ["name"] = "default:wood"}, {["x"] = 5, ["y"] = 25, ["param1"] = 56, ["z"] = 26, ["name"] = "default:wood"}, {["x"] = 5, ["y"] = 26, ["param1"] = 56, ["z"] = 24, ["name"] = "default:wood"}, {["x"] = 5, ["y"] = 26, ["param1"] = 56, ["z"] = 25, ["name"] = "default:wood"}, {["x"] = 5, ["y"] = 26, ["param1"] = 62, ["z"] = 26, ["name"] = "default:junglewood"}, {["x"] = 6, ["y"] = 14, ["param1"] = 56, ["z"] = 18, ["name"] = "default:wood"}, {["x"] = 6, ["y"] = 15, ["param1"] = 56, ["z"] = 17, ["name"] = "default:wood"}, {["x"] = 6, ["y"] = 15, ["param1"] = 56, ["z"] = 18, ["name"] = "default:wood"}, {["x"] = 6, ["y"] = 15, ["param1"] = 56, ["z"] = 19, ["name"] = "default:wood"}, {["x"] = 6, ["y"] = 16, ["param1"] = 56, ["z"] = 16, ["name"] = "default:wood"}, {["x"] = 6, ["y"] = 16, ["param1"] = 56, ["z"] = 17, ["name"] = "default:wood"}, {["x"] = 6, ["y"] = 16, ["param1"] = 56, ["z"] = 18, ["name"] = "default:wood"}, {["x"] = 6, ["y"] = 16, ["param1"] = 56, ["z"] = 19, ["name"] = "default:wood"}, {["x"] = 6, ["y"] = 16, ["param1"] = 56, ["z"] = 20, ["name"] = "default:wood"}, {["x"] = 6, ["y"] = 17, ["param1"] = 56, ["z"] = 15, ["name"] = "default:wood"}, {["x"] = 6, ["y"] = 17, ["param1"] = 56, ["z"] = 16, ["name"] = "default:wood"}, {["x"] = 6, ["y"] = 17, ["param1"] = 56, ["z"] = 17, ["name"] = "default:wood"}, {["x"] = 6, ["y"] = 17, ["param1"] = 56, ["z"] = 18, ["name"] = "default:wood"}, {["x"] = 6, ["y"] = 17, ["param1"] = 56, ["z"] = 19, ["name"] = "default:wood"}, {["x"] = 6, ["y"] = 17, ["param1"] = 56, ["z"] = 20, ["name"] = "default:wood"}, {["x"] = 6, ["y"] = 17, ["param1"] = 56, ["z"] = 21, ["name"] = "default:wood"}, {["x"] = 6, ["y"] = 18, ["param1"] = 56, ["z"] = 14, ["name"] = "default:wood"}, {["x"] = 6, ["y"] = 18, ["param1"] = 56, ["z"] = 15, ["name"] = "default:wood"}, {["x"] = 6, ["y"] = 18, ["param1"] = 56, ["z"] = 16, ["name"] = "default:wood"}, {["x"] = 6, ["y"] = 18, ["param1"] = 56, ["z"] = 17, ["name"] = "default:wood"}, {["x"] = 6, ["y"] = 18, ["param1"] = 56, ["z"] = 18, ["name"] = "default:wood"}, {["x"] = 6, ["y"] = 18, ["param1"] = 56, ["z"] = 19, ["name"] = "default:wood"}, {["x"] = 6, ["y"] = 18, ["param1"] = 56, ["z"] = 20, ["name"] = "default:wood"}, {["x"] = 6, ["y"] = 18, ["param1"] = 56, ["z"] = 21, ["name"] = "default:wood"}, {["x"] = 6, ["y"] = 18, ["param1"] = 56, ["z"] = 22, ["name"] = "default:wood"}, {["x"] = 6, ["y"] = 19, ["param1"] = 56, ["z"] = 15, ["name"] = "default:wood"}, {["x"] = 6, ["y"] = 19, ["param1"] = 56, ["z"] = 16, ["name"] = "default:wood"}, {["x"] = 6, ["y"] = 19, ["param1"] = 56, ["z"] = 17, ["name"] = "default:wood"}, {["x"] = 6, ["y"] = 19, ["param1"] = 56, ["z"] = 18, ["name"] = "default:wood"}, {["x"] = 6, ["y"] = 19, ["param1"] = 56, ["z"] = 19, ["name"] = "default:wood"}, {["x"] = 6, ["y"] = 19, ["param1"] = 56, ["z"] = 20, ["name"] = "default:wood"}, {["x"] = 6, ["y"] = 19, ["param1"] = 56, ["z"] = 21, ["name"] = "default:wood"}, {["x"] = 6, ["y"] = 19, ["param1"] = 56, ["z"] = 22, ["name"] = "default:wood"}, {["x"] = 6, ["y"] = 19, ["param1"] = 56, ["z"] = 23, ["name"] = "default:wood"}, {["x"] = 6, ["y"] = 20, ["param1"] = 56, ["z"] = 16, ["name"] = "default:wood"}, {["x"] = 6, ["y"] = 20, ["param1"] = 56, ["z"] = 17, ["name"] = "default:wood"}, {["x"] = 6, ["y"] = 20, ["param1"] = 56, ["z"] = 18, ["name"] = "default:wood"}, {["x"] = 6, ["y"] = 20, ["param1"] = 56, ["z"] = 19, ["name"] = "default:wood"}, {["x"] = 6, ["y"] = 20, ["param1"] = 56, ["z"] = 20, ["name"] = "default:wood"}, {["x"] = 6, ["y"] = 20, ["param1"] = 56, ["z"] = 21, ["name"] = "default:wood"}, {["x"] = 6, ["y"] = 20, ["param1"] = 56, ["z"] = 22, ["name"] = "default:wood"}, {["x"] = 6, ["y"] = 20, ["param1"] = 56, ["z"] = 23, ["name"] = "default:wood"}, {["x"] = 6, ["y"] = 20, ["param1"] = 56, ["z"] = 24, ["name"] = "default:wood"}, {["x"] = 6, ["y"] = 21, ["param1"] = 56, ["z"] = 17, ["name"] = "default:wood"}, {["x"] = 6, ["y"] = 21, ["param1"] = 56, ["z"] = 18, ["name"] = "default:wood"}, {["x"] = 6, ["y"] = 21, ["param1"] = 56, ["z"] = 19, ["name"] = "default:wood"}, {["x"] = 6, ["y"] = 21, ["param1"] = 56, ["z"] = 20, ["name"] = "default:wood"}, {["x"] = 6, ["y"] = 21, ["param1"] = 56, ["z"] = 21, ["name"] = "default:wood"}, {["x"] = 6, ["y"] = 21, ["param1"] = 56, ["z"] = 22, ["name"] = "default:wood"}, {["x"] = 6, ["y"] = 21, ["param1"] = 56, ["z"] = 23, ["name"] = "default:wood"}, {["x"] = 6, ["y"] = 21, ["param1"] = 56, ["z"] = 24, ["name"] = "default:wood"}, {["x"] = 6, ["y"] = 21, ["param1"] = 56, ["z"] = 25, ["name"] = "default:wood"}, {["x"] = 6, ["y"] = 22, ["param1"] = 56, ["z"] = 18, ["name"] = "default:wood"}, {["x"] = 6, ["y"] = 22, ["param1"] = 56, ["z"] = 19, ["name"] = "default:wood"}, {["x"] = 6, ["y"] = 22, ["param1"] = 56, ["z"] = 20, ["name"] = "default:wood"}, {["x"] = 6, ["y"] = 22, ["param1"] = 56, ["z"] = 21, ["name"] = "default:wood"}, {["x"] = 6, ["y"] = 22, ["param1"] = 56, ["z"] = 22, ["name"] = "default:wood"}, {["x"] = 6, ["y"] = 22, ["param1"] = 56, ["z"] = 23, ["name"] = "default:wood"}, {["x"] = 6, ["y"] = 22, ["param1"] = 56, ["z"] = 24, ["name"] = "default:wood"}, {["x"] = 6, ["y"] = 22, ["param1"] = 56, ["z"] = 25, ["name"] = "default:wood"}, {["x"] = 6, ["y"] = 22, ["param1"] = 56, ["z"] = 26, ["name"] = "default:wood"}, {["x"] = 6, ["y"] = 23, ["param1"] = 56, ["z"] = 19, ["name"] = "default:wood"}, {["x"] = 6, ["y"] = 23, ["param1"] = 56, ["z"] = 20, ["name"] = "default:wood"}, {["x"] = 6, ["y"] = 23, ["param1"] = 56, ["z"] = 21, ["name"] = "default:wood"}, {["x"] = 6, ["y"] = 23, ["param1"] = 56, ["z"] = 22, ["name"] = "default:wood"}, {["x"] = 6, ["y"] = 23, ["param1"] = 56, ["z"] = 23, ["name"] = "default:wood"}, {["x"] = 6, ["y"] = 23, ["param1"] = 56, ["z"] = 24, ["name"] = "default:wood"}, {["x"] = 6, ["y"] = 23, ["param1"] = 56, ["z"] = 25, ["name"] = "default:wood"}, {["x"] = 6, ["y"] = 23, ["param1"] = 56, ["z"] = 26, ["name"] = "default:wood"}, {["x"] = 6, ["y"] = 23, ["param1"] = 56, ["z"] = 27, ["name"] = "default:wood"}, {["x"] = 6, ["y"] = 24, ["param1"] = 56, ["z"] = 20, ["name"] = "default:wood"}, {["x"] = 6, ["y"] = 24, ["param1"] = 56, ["z"] = 21, ["name"] = "default:wood"}, {["x"] = 6, ["y"] = 24, ["param1"] = 56, ["z"] = 22, ["name"] = "default:wood"}, {["x"] = 6, ["y"] = 24, ["param1"] = 56, ["z"] = 23, ["name"] = "default:wood"}, {["x"] = 6, ["y"] = 24, ["param1"] = 56, ["z"] = 24, ["name"] = "default:wood"}, {["x"] = 6, ["y"] = 24, ["param1"] = 56, ["z"] = 25, ["name"] = "default:wood"}, {["x"] = 6, ["y"] = 24, ["param1"] = 56, ["z"] = 26, ["name"] = "default:wood"}, {["x"] = 6, ["y"] = 24, ["param1"] = 62, ["z"] = 27, ["name"] = "default:junglewood"}, {["x"] = 6, ["y"] = 25, ["param1"] = 56, ["z"] = 21, ["name"] = "default:wood"}, {["x"] = 6, ["y"] = 25, ["param1"] = 56, ["z"] = 22, ["name"] = "default:wood"}, {["x"] = 6, ["y"] = 25, ["param1"] = 56, ["z"] = 23, ["name"] = "default:wood"}, {["x"] = 6, ["y"] = 25, ["param1"] = 56, ["z"] = 24, ["name"] = "default:wood"}, {["x"] = 6, ["y"] = 25, ["param1"] = 56, ["z"] = 25, ["name"] = "default:wood"}, {["x"] = 6, ["y"] = 25, ["param1"] = 56, ["z"] = 26, ["name"] = "default:wood"}, {["x"] = 6, ["y"] = 25, ["param1"] = 62, ["z"] = 27, ["name"] = "default:junglewood"}, {["x"] = 6, ["y"] = 26, ["param1"] = 56, ["z"] = 22, ["name"] = "default:wood"}, {["x"] = 6, ["y"] = 26, ["param1"] = 56, ["z"] = 23, ["name"] = "default:wood"}, {["x"] = 6, ["y"] = 26, ["param1"] = 56, ["z"] = 24, ["name"] = "default:wood"}, {["x"] = 6, ["y"] = 26, ["param1"] = 56, ["z"] = 25, ["name"] = "default:wood"}, {["x"] = 6, ["y"] = 26, ["param1"] = 62, ["z"] = 26, ["name"] = "default:junglewood"}, {["x"] = 6, ["y"] = 26, ["param1"] = 62, ["z"] = 27, ["name"] = "default:junglewood"}, {["x"] = 6, ["y"] = 27, ["param1"] = 56, ["z"] = 23, ["name"] = "default:wood"}, {["x"] = 6, ["y"] = 27, ["param1"] = 62, ["z"] = 24, ["name"] = "default:junglewood"}, {["x"] = 6, ["y"] = 27, ["param1"] = 62, ["z"] = 25, ["name"] = "default:junglewood"}, {["x"] = 6, ["y"] = 27, ["param1"] = 62, ["z"] = 26, ["name"] = "default:junglewood"}, {["x"] = 6, ["y"] = 27, ["param1"] = 62, ["z"] = 27, ["name"] = "default:junglewood"}, {["x"] = 6, ["y"] = 28, ["param1"] = 62, ["z"] = 28, ["name"] = "default:junglewood"}, {["x"] = 7, ["y"] = 13, ["param1"] = 56, ["z"] = 19, ["name"] = "default:wood"}, {["x"] = 7, ["y"] = 14, ["param1"] = 56, ["z"] = 18, ["name"] = "default:wood"}, {["x"] = 7, ["y"] = 14, ["param1"] = 56, ["z"] = 19, ["name"] = "default:wood"}, {["x"] = 7, ["y"] = 14, ["param1"] = 56, ["z"] = 20, ["name"] = "default:wood"}, {["x"] = 7, ["y"] = 15, ["param1"] = 56, ["z"] = 17, ["name"] = "default:wood"}, {["x"] = 7, ["y"] = 15, ["param1"] = 56, ["z"] = 18, ["name"] = "default:wood"}, {["x"] = 7, ["y"] = 15, ["param1"] = 56, ["z"] = 19, ["name"] = "default:wood"}, {["x"] = 7, ["y"] = 15, ["param1"] = 56, ["z"] = 20, ["name"] = "default:wood"}, {["x"] = 7, ["y"] = 15, ["param1"] = 56, ["z"] = 21, ["name"] = "default:wood"}, {["x"] = 7, ["y"] = 16, ["param1"] = 56, ["z"] = 16, ["name"] = "default:wood"}, {["x"] = 7, ["y"] = 16, ["param1"] = 56, ["z"] = 17, ["name"] = "default:wood"}, {["x"] = 7, ["y"] = 16, ["param1"] = 56, ["z"] = 18, ["name"] = "default:wood"}, {["x"] = 7, ["y"] = 16, ["param1"] = 56, ["z"] = 19, ["name"] = "default:wood"}, {["x"] = 7, ["y"] = 16, ["param1"] = 56, ["z"] = 20, ["name"] = "default:wood"}, {["x"] = 7, ["y"] = 16, ["param1"] = 56, ["z"] = 21, ["name"] = "default:wood"}, {["x"] = 7, ["y"] = 16, ["param1"] = 56, ["z"] = 22, ["name"] = "default:wood"}, {["x"] = 7, ["y"] = 17, ["param1"] = 56, ["z"] = 15, ["name"] = "default:wood"}, {["x"] = 7, ["y"] = 17, ["param1"] = 56, ["z"] = 16, ["name"] = "default:wood"}, {["x"] = 7, ["y"] = 17, ["param1"] = 56, ["z"] = 17, ["name"] = "default:wood"}, {["x"] = 7, ["y"] = 17, ["param1"] = 56, ["z"] = 18, ["name"] = "default:wood"}, {["x"] = 7, ["y"] = 17, ["param1"] = 56, ["z"] = 19, ["name"] = "default:wood"}, {["x"] = 7, ["y"] = 17, ["param1"] = 56, ["z"] = 20, ["name"] = "default:wood"}, {["x"] = 7, ["y"] = 17, ["param1"] = 56, ["z"] = 21, ["name"] = "default:wood"}, {["x"] = 7, ["y"] = 17, ["param1"] = 56, ["z"] = 22, ["name"] = "default:wood"}, {["x"] = 7, ["y"] = 17, ["param1"] = 56, ["z"] = 23, ["name"] = "default:wood"}, {["x"] = 7, ["y"] = 18, ["param1"] = 56, ["z"] = 14, ["name"] = "default:wood"}, {["x"] = 7, ["y"] = 18, ["param1"] = 56, ["z"] = 15, ["name"] = "default:wood"}, {["x"] = 7, ["y"] = 18, ["param1"] = 56, ["z"] = 16, ["name"] = "default:wood"}, {["x"] = 7, ["y"] = 18, ["param1"] = 56, ["z"] = 17, ["name"] = "default:wood"}, {["x"] = 7, ["y"] = 18, ["param1"] = 56, ["z"] = 18, ["name"] = "default:wood"}, {["x"] = 7, ["y"] = 18, ["param1"] = 56, ["z"] = 19, ["name"] = "default:wood"}, {["x"] = 7, ["y"] = 18, ["param1"] = 56, ["z"] = 20, ["name"] = "default:wood"}, {["x"] = 7, ["y"] = 18, ["param1"] = 56, ["z"] = 21, ["name"] = "default:wood"}, {["x"] = 7, ["y"] = 18, ["param1"] = 56, ["z"] = 22, ["name"] = "default:wood"}, {["x"] = 7, ["y"] = 18, ["param1"] = 56, ["z"] = 23, ["name"] = "default:wood"}, {["x"] = 7, ["y"] = 18, ["param1"] = 56, ["z"] = 24, ["name"] = "default:wood"}, {["x"] = 7, ["y"] = 19, ["param1"] = 56, ["z"] = 13, ["name"] = "default:wood"}, {["x"] = 7, ["y"] = 19, ["param1"] = 56, ["z"] = 14, ["name"] = "default:wood"}, {["x"] = 7, ["y"] = 19, ["param1"] = 56, ["z"] = 15, ["name"] = "default:wood"}, {["x"] = 7, ["y"] = 19, ["param1"] = 56, ["z"] = 16, ["name"] = "default:wood"}, {["x"] = 7, ["y"] = 19, ["param1"] = 56, ["z"] = 17, ["name"] = "default:wood"}, {["x"] = 7, ["y"] = 19, ["param1"] = 56, ["z"] = 18, ["name"] = "default:wood"}, {["x"] = 7, ["y"] = 19, ["param1"] = 56, ["z"] = 19, ["name"] = "default:wood"}, {["x"] = 7, ["y"] = 19, ["param1"] = 56, ["z"] = 20, ["name"] = "default:wood"}, {["x"] = 7, ["y"] = 19, ["param1"] = 56, ["z"] = 21, ["name"] = "default:wood"}, {["x"] = 7, ["y"] = 19, ["param1"] = 56, ["z"] = 22, ["name"] = "default:wood"}, {["x"] = 7, ["y"] = 19, ["param1"] = 56, ["z"] = 23, ["name"] = "default:wood"}, {["x"] = 7, ["y"] = 19, ["param1"] = 56, ["z"] = 24, ["name"] = "default:wood"}, {["x"] = 7, ["y"] = 19, ["param1"] = 56, ["z"] = 25, ["name"] = "default:wood"}, {["x"] = 7, ["y"] = 20, ["param1"] = 56, ["z"] = 14, ["name"] = "default:wood"}, {["x"] = 7, ["y"] = 20, ["param1"] = 56, ["z"] = 15, ["name"] = "default:wood"}, {["x"] = 7, ["y"] = 20, ["param1"] = 56, ["z"] = 16, ["name"] = "default:wood"}, {["x"] = 7, ["y"] = 20, ["param1"] = 56, ["z"] = 17, ["name"] = "default:wood"}, {["x"] = 7, ["y"] = 20, ["param1"] = 56, ["z"] = 18, ["name"] = "default:wood"}, {["x"] = 7, ["y"] = 20, ["param1"] = 56, ["z"] = 19, ["name"] = "default:wood"}, {["x"] = 7, ["y"] = 20, ["param1"] = 56, ["z"] = 20, ["name"] = "default:wood"}, {["x"] = 7, ["y"] = 20, ["param1"] = 56, ["z"] = 21, ["name"] = "default:wood"}, {["x"] = 7, ["y"] = 20, ["param1"] = 56, ["z"] = 22, ["name"] = "default:wood"}, {["x"] = 7, ["y"] = 20, ["param1"] = 56, ["z"] = 23, ["name"] = "default:wood"}, {["x"] = 7, ["y"] = 20, ["param1"] = 56, ["z"] = 24, ["name"] = "default:wood"}, {["x"] = 7, ["y"] = 20, ["param1"] = 56, ["z"] = 25, ["name"] = "default:wood"}, {["x"] = 7, ["y"] = 20, ["param1"] = 56, ["z"] = 26, ["name"] = "default:wood"}, {["x"] = 7, ["y"] = 21, ["z"] = 15, ["name"] = "default:wood"}, {["x"] = 7, ["y"] = 21, ["z"] = 16, ["name"] = "default:wood"}, {["x"] = 7, ["y"] = 21, ["param1"] = 56, ["z"] = 17, ["name"] = "default:wood"}, {["x"] = 7, ["y"] = 21, ["param1"] = 56, ["z"] = 18, ["name"] = "default:wood"}, {["x"] = 7, ["y"] = 21, ["param1"] = 56, ["z"] = 19, ["name"] = "default:wood"}, {["x"] = 7, ["y"] = 21, ["param1"] = 56, ["z"] = 20, ["name"] = "default:wood"}, {["x"] = 7, ["y"] = 21, ["param1"] = 56, ["z"] = 21, ["name"] = "default:wood"}, {["x"] = 7, ["y"] = 21, ["param1"] = 56, ["z"] = 22, ["name"] = "default:wood"}, {["x"] = 7, ["y"] = 21, ["param1"] = 56, ["z"] = 23, ["name"] = "default:wood"}, {["x"] = 7, ["y"] = 21, ["param1"] = 56, ["z"] = 24, ["name"] = "default:wood"}, {["x"] = 7, ["y"] = 21, ["param1"] = 56, ["z"] = 25, ["name"] = "default:wood"}, {["x"] = 7, ["y"] = 21, ["param1"] = 56, ["z"] = 26, ["name"] = "default:wood"}, {["x"] = 7, ["y"] = 21, ["param1"] = 56, ["z"] = 27, ["name"] = "default:wood"}, {["x"] = 7, ["y"] = 22, ["param1"] = 56, ["z"] = 16, ["name"] = "default:wood"}, {["x"] = 7, ["y"] = 22, ["param1"] = 56, ["z"] = 17, ["name"] = "default:wood"}, {["x"] = 7, ["y"] = 22, ["param1"] = 56, ["z"] = 18, ["name"] = "default:wood"}, {["x"] = 7, ["y"] = 22, ["param1"] = 56, ["z"] = 19, ["name"] = "default:wood"}, {["x"] = 7, ["y"] = 22, ["param1"] = 56, ["z"] = 20, ["name"] = "default:wood"}, {["x"] = 7, ["y"] = 22, ["param1"] = 56, ["z"] = 21, ["name"] = "default:wood"}, {["x"] = 7, ["y"] = 22, ["param1"] = 56, ["z"] = 22, ["name"] = "default:wood"}, {["x"] = 7, ["y"] = 22, ["param1"] = 56, ["z"] = 23, ["name"] = "default:wood"}, {["x"] = 7, ["y"] = 22, ["param1"] = 56, ["z"] = 24, ["name"] = "default:wood"}, {["x"] = 7, ["y"] = 22, ["param1"] = 56, ["z"] = 25, ["name"] = "default:wood"}, {["x"] = 7, ["y"] = 22, ["param1"] = 56, ["z"] = 26, ["name"] = "default:wood"}, {["x"] = 7, ["y"] = 22, ["param1"] = 56, ["z"] = 27, ["name"] = "default:wood"}, {["x"] = 7, ["y"] = 22, ["param1"] = 56, ["z"] = 28, ["name"] = "default:wood"}, {["x"] = 7, ["y"] = 23, ["param1"] = 56, ["z"] = 17, ["name"] = "default:wood"}, {["x"] = 7, ["y"] = 23, ["param1"] = 56, ["z"] = 18, ["name"] = "default:wood"}, {["x"] = 7, ["y"] = 23, ["param1"] = 56, ["z"] = 19, ["name"] = "default:wood"}, {["x"] = 7, ["y"] = 23, ["param1"] = 56, ["z"] = 20, ["name"] = "default:wood"}, {["x"] = 7, ["y"] = 23, ["param1"] = 56, ["z"] = 21, ["name"] = "default:wood"}, {["x"] = 7, ["y"] = 23, ["param1"] = 56, ["z"] = 22, ["name"] = "default:wood"}, {["x"] = 7, ["y"] = 23, ["param1"] = 56, ["z"] = 23, ["name"] = "default:wood"}, {["x"] = 7, ["y"] = 23, ["param1"] = 56, ["z"] = 24, ["name"] = "default:wood"}, {["x"] = 7, ["y"] = 23, ["param1"] = 56, ["z"] = 25, ["name"] = "default:wood"}, {["x"] = 7, ["y"] = 23, ["param1"] = 56, ["z"] = 26, ["name"] = "default:wood"}, {["x"] = 7, ["y"] = 23, ["param1"] = 56, ["z"] = 27, ["name"] = "default:wood"}, {["x"] = 7, ["y"] = 23, ["param1"] = 62, ["z"] = 28, ["name"] = "default:junglewood"}, {["x"] = 7, ["y"] = 24, ["param1"] = 56, ["z"] = 18, ["name"] = "default:wood"}, {["x"] = 7, ["y"] = 24, ["param1"] = 56, ["z"] = 19, ["name"] = "default:wood"}, {["x"] = 7, ["y"] = 24, ["param1"] = 56, ["z"] = 20, ["name"] = "default:wood"}, {["x"] = 7, ["y"] = 24, ["param1"] = 56, ["z"] = 21, ["name"] = "default:wood"}, {["x"] = 7, ["y"] = 24, ["param1"] = 56, ["z"] = 22, ["name"] = "default:wood"}, {["x"] = 7, ["y"] = 24, ["param1"] = 56, ["z"] = 23, ["name"] = "default:wood"}, {["x"] = 7, ["y"] = 24, ["param1"] = 56, ["z"] = 24, ["name"] = "default:wood"}, {["x"] = 7, ["y"] = 24, ["param1"] = 56, ["z"] = 25, ["name"] = "default:wood"}, {["x"] = 7, ["y"] = 24, ["param1"] = 56, ["z"] = 26, ["name"] = "default:wood"}, {["x"] = 7, ["y"] = 24, ["param1"] = 62, ["z"] = 27, ["name"] = "default:junglewood"}, {["x"] = 7, ["y"] = 24, ["param1"] = 62, ["z"] = 28, ["name"] = "default:junglewood"}, {["x"] = 7, ["y"] = 25, ["param1"] = 56, ["z"] = 19, ["name"] = "default:wood"}, {["x"] = 7, ["y"] = 25, ["param1"] = 56, ["z"] = 20, ["name"] = "default:wood"}, {["x"] = 7, ["y"] = 25, ["param1"] = 56, ["z"] = 21, ["name"] = "default:wood"}, {["x"] = 7, ["y"] = 25, ["param1"] = 56, ["z"] = 22, ["name"] = "default:wood"}, {["x"] = 7, ["y"] = 25, ["param1"] = 56, ["z"] = 23, ["name"] = "default:wood"}, {["x"] = 7, ["y"] = 25, ["param1"] = 56, ["z"] = 24, ["name"] = "default:wood"}, {["x"] = 7, ["y"] = 25, ["param1"] = 56, ["z"] = 25, ["name"] = "default:wood"}, {["x"] = 7, ["y"] = 25, ["param1"] = 56, ["z"] = 26, ["name"] = "default:wood"}, {["x"] = 7, ["y"] = 25, ["param1"] = 62, ["z"] = 27, ["name"] = "default:junglewood"}, {["x"] = 7, ["y"] = 25, ["param1"] = 62, ["z"] = 28, ["name"] = "default:junglewood"}, {["x"] = 7, ["y"] = 26, ["param1"] = 56, ["z"] = 20, ["name"] = "default:wood"}, {["x"] = 7, ["y"] = 26, ["param1"] = 56, ["z"] = 21, ["name"] = "default:wood"}, {["x"] = 7, ["y"] = 26, ["param1"] = 56, ["z"] = 22, ["name"] = "default:wood"}, {["x"] = 7, ["y"] = 26, ["param1"] = 56, ["z"] = 23, ["name"] = "default:wood"}, {["x"] = 7, ["y"] = 26, ["param1"] = 56, ["z"] = 24, ["name"] = "default:wood"}, {["x"] = 7, ["y"] = 26, ["param1"] = 56, ["z"] = 25, ["name"] = "default:wood"}, {["x"] = 7, ["y"] = 26, ["param1"] = 62, ["z"] = 26, ["name"] = "default:junglewood"}, {["x"] = 7, ["y"] = 26, ["param1"] = 62, ["z"] = 27, ["name"] = "default:junglewood"}, {["x"] = 7, ["y"] = 26, ["param1"] = 62, ["z"] = 28, ["name"] = "default:junglewood"}, {["x"] = 7, ["y"] = 27, ["param1"] = 56, ["z"] = 21, ["name"] = "default:wood"}, {["x"] = 7, ["y"] = 27, ["param1"] = 56, ["z"] = 22, ["name"] = "default:wood"}, {["x"] = 7, ["y"] = 27, ["param1"] = 56, ["z"] = 23, ["name"] = "default:wood"}, {["x"] = 7, ["y"] = 27, ["param1"] = 62, ["z"] = 24, ["name"] = "default:junglewood"}, {["x"] = 7, ["y"] = 27, ["param1"] = 62, ["z"] = 25, ["name"] = "default:junglewood"}, {["x"] = 7, ["y"] = 27, ["param1"] = 62, ["z"] = 26, ["name"] = "default:junglewood"}, {["x"] = 7, ["y"] = 27, ["param1"] = 62, ["z"] = 27, ["name"] = "default:junglewood"}, {["x"] = 7, ["y"] = 27, ["param1"] = 62, ["z"] = 28, ["name"] = "default:junglewood"}, {["x"] = 7, ["y"] = 27, ["param1"] = 62, ["z"] = 29, ["name"] = "default:junglewood"}, {["x"] = 7, ["y"] = 28, ["param1"] = 56, ["z"] = 22, ["name"] = "default:wood"}, {["x"] = 7, ["y"] = 28, ["param1"] = 62, ["z"] = 23, ["name"] = "default:junglewood"}, {["x"] = 7, ["y"] = 28, ["param1"] = 62, ["z"] = 24, ["name"] = "default:junglewood"}, {["x"] = 7, ["y"] = 28, ["param1"] = 62, ["z"] = 25, ["name"] = "default:junglewood"}, {["x"] = 7, ["y"] = 28, ["param1"] = 62, ["z"] = 26, ["name"] = "default:junglewood"}, {["x"] = 7, ["y"] = 28, ["param1"] = 62, ["z"] = 27, ["name"] = "default:junglewood"}, {["x"] = 7, ["y"] = 28, ["param1"] = 62, ["z"] = 28, ["name"] = "default:junglewood"}, {["x"] = 7, ["y"] = 28, ["param1"] = 62, ["z"] = 29, ["name"] = "default:junglewood"}, {["x"] = 7, ["y"] = 29, ["param1"] = 62, ["z"] = 27, ["name"] = "default:junglewood"}, {["x"] = 7, ["y"] = 29, ["param1"] = 62, ["z"] = 28, ["name"] = "default:junglewood"}, {["x"] = 7, ["y"] = 29, ["param1"] = 62, ["z"] = 29, ["name"] = "default:junglewood"}, {["x"] = 8, ["y"] = 13, ["param1"] = 56, ["z"] = 19, ["name"] = "default:wood"}, {["x"] = 8, ["y"] = 14, ["param1"] = 56, ["z"] = 18, ["name"] = "default:wood"}, {["x"] = 8, ["y"] = 14, ["param1"] = 56, ["z"] = 19, ["name"] = "default:wood"}, {["x"] = 8, ["y"] = 14, ["param1"] = 56, ["z"] = 20, ["name"] = "default:wood"}, {["x"] = 8, ["y"] = 15, ["param1"] = 56, ["z"] = 17, ["name"] = "default:wood"}, {["x"] = 8, ["y"] = 15, ["param1"] = 56, ["z"] = 18, ["name"] = "default:wood"}, {["x"] = 8, ["y"] = 15, ["param1"] = 56, ["z"] = 19, ["name"] = "default:wood"}, {["x"] = 8, ["y"] = 15, ["param1"] = 56, ["z"] = 20, ["name"] = "default:wood"}, {["x"] = 8, ["y"] = 15, ["param1"] = 56, ["z"] = 21, ["name"] = "default:wood"}, {["x"] = 8, ["y"] = 16, ["param1"] = 56, ["z"] = 16, ["name"] = "default:wood"}, {["x"] = 8, ["y"] = 16, ["param1"] = 56, ["z"] = 17, ["name"] = "default:wood"}, {["x"] = 8, ["y"] = 16, ["param1"] = 56, ["z"] = 18, ["name"] = "default:wood"}, {["x"] = 8, ["y"] = 16, ["param1"] = 56, ["z"] = 19, ["name"] = "default:wood"}, {["x"] = 8, ["y"] = 16, ["param1"] = 56, ["z"] = 20, ["name"] = "default:wood"}, {["x"] = 8, ["y"] = 16, ["param1"] = 56, ["z"] = 21, ["name"] = "default:wood"}, {["x"] = 8, ["y"] = 16, ["param1"] = 56, ["z"] = 22, ["name"] = "default:wood"}, {["x"] = 8, ["y"] = 17, ["param1"] = 56, ["z"] = 15, ["name"] = "default:wood"}, {["x"] = 8, ["y"] = 17, ["param1"] = 56, ["z"] = 16, ["name"] = "default:wood"}, {["x"] = 8, ["y"] = 17, ["param1"] = 56, ["z"] = 17, ["name"] = "default:wood"}, {["x"] = 8, ["y"] = 17, ["param1"] = 56, ["z"] = 18, ["name"] = "default:wood"}, {["x"] = 8, ["y"] = 17, ["param1"] = 56, ["z"] = 19, ["name"] = "default:wood"}, {["x"] = 8, ["y"] = 17, ["param1"] = 56, ["z"] = 20, ["name"] = "default:wood"}, {["x"] = 8, ["y"] = 17, ["param1"] = 56, ["z"] = 21, ["name"] = "default:wood"}, {["x"] = 8, ["y"] = 17, ["param1"] = 56, ["z"] = 22, ["name"] = "default:wood"}, {["x"] = 8, ["y"] = 17, ["param1"] = 56, ["z"] = 23, ["name"] = "default:wood"}, {["x"] = 8, ["y"] = 18, ["param1"] = 56, ["z"] = 14, ["name"] = "default:wood"}, {["x"] = 8, ["y"] = 18, ["param1"] = 56, ["z"] = 15, ["name"] = "default:wood"}, {["x"] = 8, ["y"] = 18, ["param1"] = 56, ["z"] = 16, ["name"] = "default:wood"}, {["x"] = 8, ["y"] = 18, ["param1"] = 56, ["z"] = 17, ["name"] = "default:wood"}, {["x"] = 8, ["y"] = 18, ["param1"] = 56, ["z"] = 18, ["name"] = "default:wood"}, {["x"] = 8, ["y"] = 18, ["param1"] = 56, ["z"] = 19, ["name"] = "default:wood"}, {["x"] = 8, ["y"] = 18, ["param1"] = 56, ["z"] = 20, ["name"] = "default:wood"}, {["x"] = 8, ["y"] = 18, ["param1"] = 56, ["z"] = 21, ["name"] = "default:wood"}, {["x"] = 8, ["y"] = 18, ["param1"] = 56, ["z"] = 22, ["name"] = "default:wood"}, {["x"] = 8, ["y"] = 18, ["param1"] = 56, ["z"] = 23, ["name"] = "default:wood"}, {["x"] = 8, ["y"] = 18, ["param1"] = 56, ["z"] = 24, ["name"] = "default:wood"}, {["x"] = 8, ["y"] = 19, ["param1"] = 56, ["z"] = 13, ["name"] = "default:wood"}, {["x"] = 8, ["y"] = 19, ["param1"] = 56, ["z"] = 14, ["name"] = "default:wood"}, {["x"] = 8, ["y"] = 19, ["param1"] = 56, ["z"] = 15, ["name"] = "default:wood"}, {["x"] = 8, ["y"] = 19, ["param1"] = 56, ["z"] = 16, ["name"] = "default:wood"}, {["x"] = 8, ["y"] = 19, ["param1"] = 56, ["z"] = 17, ["name"] = "default:wood"}, {["x"] = 8, ["y"] = 19, ["param1"] = 56, ["z"] = 18, ["name"] = "default:wood"}, {["x"] = 8, ["y"] = 19, ["param1"] = 56, ["z"] = 19, ["name"] = "default:wood"}, {["x"] = 8, ["y"] = 19, ["param1"] = 56, ["z"] = 20, ["name"] = "default:wood"}, {["x"] = 8, ["y"] = 19, ["param1"] = 56, ["z"] = 21, ["name"] = "default:wood"}, {["x"] = 8, ["y"] = 19, ["param1"] = 56, ["z"] = 22, ["name"] = "default:wood"}, {["x"] = 8, ["y"] = 19, ["param1"] = 56, ["z"] = 23, ["name"] = "default:wood"}, {["x"] = 8, ["y"] = 19, ["param1"] = 56, ["z"] = 24, ["name"] = "default:wood"}, {["x"] = 8, ["y"] = 19, ["param1"] = 56, ["z"] = 25, ["name"] = "default:wood"}, {["x"] = 8, ["y"] = 20, ["param1"] = 56, ["z"] = 14, ["name"] = "default:wood"}, {["x"] = 8, ["y"] = 20, ["param1"] = 56, ["z"] = 15, ["name"] = "default:wood"}, {["x"] = 8, ["y"] = 20, ["param1"] = 56, ["z"] = 16, ["name"] = "default:wood"}, {["x"] = 8, ["y"] = 20, ["param1"] = 56, ["z"] = 17, ["name"] = "default:wood"}, {["x"] = 8, ["y"] = 20, ["param1"] = 56, ["z"] = 18, ["name"] = "default:wood"}, {["x"] = 8, ["y"] = 20, ["param1"] = 56, ["z"] = 19, ["name"] = "default:wood"}, {["x"] = 8, ["y"] = 20, ["param1"] = 56, ["z"] = 20, ["name"] = "default:wood"}, {["x"] = 8, ["y"] = 20, ["param1"] = 56, ["z"] = 21, ["name"] = "default:wood"}, {["x"] = 8, ["y"] = 20, ["param1"] = 56, ["z"] = 22, ["name"] = "default:wood"}, {["x"] = 8, ["y"] = 20, ["param1"] = 56, ["z"] = 23, ["name"] = "default:wood"}, {["x"] = 8, ["y"] = 20, ["param1"] = 56, ["z"] = 24, ["name"] = "default:wood"}, {["x"] = 8, ["y"] = 20, ["param1"] = 56, ["z"] = 25, ["name"] = "default:wood"}, {["x"] = 8, ["y"] = 20, ["param1"] = 56, ["z"] = 26, ["name"] = "default:wood"}, {["x"] = 8, ["y"] = 21, ["z"] = 15, ["name"] = "default:wood"}, {["x"] = 8, ["y"] = 21, ["z"] = 16, ["name"] = "default:wood"}, {["x"] = 8, ["y"] = 21, ["param1"] = 56, ["z"] = 17, ["name"] = "default:wood"}, {["x"] = 8, ["y"] = 21, ["param1"] = 56, ["z"] = 18, ["name"] = "default:wood"}, {["x"] = 8, ["y"] = 21, ["param1"] = 56, ["z"] = 19, ["name"] = "default:wood"}, {["x"] = 8, ["y"] = 21, ["param1"] = 56, ["z"] = 20, ["name"] = "default:wood"}, {["x"] = 8, ["y"] = 21, ["param1"] = 56, ["z"] = 21, ["name"] = "default:wood"}, {["x"] = 8, ["y"] = 21, ["param1"] = 56, ["z"] = 22, ["name"] = "default:wood"}, {["x"] = 8, ["y"] = 21, ["param1"] = 56, ["z"] = 23, ["name"] = "default:wood"}, {["x"] = 8, ["y"] = 21, ["param1"] = 56, ["z"] = 24, ["name"] = "default:wood"}, {["x"] = 8, ["y"] = 21, ["param1"] = 56, ["z"] = 25, ["name"] = "default:wood"}, {["x"] = 8, ["y"] = 21, ["param1"] = 56, ["z"] = 26, ["name"] = "default:wood"}, {["x"] = 8, ["y"] = 21, ["param1"] = 56, ["z"] = 27, ["name"] = "default:wood"}, {["x"] = 8, ["y"] = 22, ["param1"] = 56, ["z"] = 16, ["name"] = "default:wood"}, {["x"] = 8, ["y"] = 22, ["param1"] = 56, ["z"] = 17, ["name"] = "default:wood"}, {["x"] = 8, ["y"] = 22, ["param1"] = 56, ["z"] = 18, ["name"] = "default:wood"}, {["x"] = 8, ["y"] = 22, ["param1"] = 56, ["z"] = 19, ["name"] = "default:wood"}, {["x"] = 8, ["y"] = 22, ["param1"] = 56, ["z"] = 20, ["name"] = "default:wood"}, {["x"] = 8, ["y"] = 22, ["param1"] = 56, ["z"] = 21, ["name"] = "default:wood"}, {["x"] = 8, ["y"] = 22, ["param1"] = 56, ["z"] = 22, ["name"] = "default:wood"}, {["x"] = 8, ["y"] = 22, ["param1"] = 56, ["z"] = 23, ["name"] = "default:wood"}, {["x"] = 8, ["y"] = 22, ["param1"] = 56, ["z"] = 24, ["name"] = "default:wood"}, {["x"] = 8, ["y"] = 22, ["param1"] = 56, ["z"] = 25, ["name"] = "default:wood"}, {["x"] = 8, ["y"] = 22, ["param1"] = 56, ["z"] = 26, ["name"] = "default:wood"}, {["x"] = 8, ["y"] = 22, ["param1"] = 56, ["z"] = 27, ["name"] = "default:wood"}, {["x"] = 8, ["y"] = 22, ["param1"] = 56, ["z"] = 28, ["name"] = "default:wood"}, {["x"] = 8, ["y"] = 23, ["param1"] = 56, ["z"] = 17, ["name"] = "default:wood"}, {["x"] = 8, ["y"] = 23, ["param1"] = 56, ["z"] = 18, ["name"] = "default:wood"}, {["x"] = 8, ["y"] = 23, ["param1"] = 56, ["z"] = 19, ["name"] = "default:wood"}, {["x"] = 8, ["y"] = 23, ["param1"] = 56, ["z"] = 20, ["name"] = "default:wood"}, {["x"] = 8, ["y"] = 23, ["param1"] = 56, ["z"] = 21, ["name"] = "default:wood"}, {["x"] = 8, ["y"] = 23, ["param1"] = 56, ["z"] = 22, ["name"] = "default:wood"}, {["x"] = 8, ["y"] = 23, ["param1"] = 56, ["z"] = 23, ["name"] = "default:wood"}, {["x"] = 8, ["y"] = 23, ["param1"] = 56, ["z"] = 24, ["name"] = "default:wood"}, {["x"] = 8, ["y"] = 23, ["param1"] = 56, ["z"] = 25, ["name"] = "default:wood"}, {["x"] = 8, ["y"] = 23, ["param1"] = 56, ["z"] = 26, ["name"] = "default:wood"}, {["x"] = 8, ["y"] = 23, ["param1"] = 56, ["z"] = 27, ["name"] = "default:wood"}, {["x"] = 8, ["y"] = 23, ["param1"] = 62, ["z"] = 28, ["name"] = "default:junglewood"}, {["x"] = 8, ["y"] = 24, ["param1"] = 56, ["z"] = 18, ["name"] = "default:wood"}, {["x"] = 8, ["y"] = 24, ["param1"] = 56, ["z"] = 19, ["name"] = "default:wood"}, {["x"] = 8, ["y"] = 24, ["param1"] = 56, ["z"] = 20, ["name"] = "default:wood"}, {["x"] = 8, ["y"] = 24, ["param1"] = 56, ["z"] = 21, ["name"] = "default:wood"}, {["x"] = 8, ["y"] = 24, ["param1"] = 56, ["z"] = 22, ["name"] = "default:wood"}, {["x"] = 8, ["y"] = 24, ["param1"] = 56, ["z"] = 23, ["name"] = "default:wood"}, {["x"] = 8, ["y"] = 24, ["param1"] = 56, ["z"] = 24, ["name"] = "default:wood"}, {["x"] = 8, ["y"] = 24, ["param1"] = 56, ["z"] = 25, ["name"] = "default:wood"}, {["x"] = 8, ["y"] = 24, ["param1"] = 56, ["z"] = 26, ["name"] = "default:wood"}, {["x"] = 8, ["y"] = 24, ["param1"] = 62, ["z"] = 27, ["name"] = "default:junglewood"}, {["x"] = 8, ["y"] = 24, ["param1"] = 62, ["z"] = 28, ["name"] = "default:junglewood"}, {["x"] = 8, ["y"] = 25, ["param1"] = 56, ["z"] = 19, ["name"] = "default:wood"}, {["x"] = 8, ["y"] = 25, ["param1"] = 56, ["z"] = 20, ["name"] = "default:wood"}, {["x"] = 8, ["y"] = 25, ["param1"] = 56, ["z"] = 21, ["name"] = "default:wood"}, {["x"] = 8, ["y"] = 25, ["param1"] = 56, ["z"] = 22, ["name"] = "default:wood"}, {["x"] = 8, ["y"] = 25, ["param1"] = 56, ["z"] = 23, ["name"] = "default:wood"}, {["x"] = 8, ["y"] = 25, ["param1"] = 56, ["z"] = 24, ["name"] = "default:wood"}, {["x"] = 8, ["y"] = 25, ["param1"] = 56, ["z"] = 25, ["name"] = "default:wood"}, {["x"] = 8, ["y"] = 25, ["param1"] = 56, ["z"] = 26, ["name"] = "default:wood"}, {["x"] = 8, ["y"] = 25, ["param1"] = 62, ["z"] = 27, ["name"] = "default:junglewood"}, {["x"] = 8, ["y"] = 25, ["param1"] = 62, ["z"] = 28, ["name"] = "default:junglewood"}, {["x"] = 8, ["y"] = 26, ["param1"] = 56, ["z"] = 20, ["name"] = "default:wood"}, {["x"] = 8, ["y"] = 26, ["param1"] = 56, ["z"] = 21, ["name"] = "default:wood"}, {["x"] = 8, ["y"] = 26, ["param1"] = 56, ["z"] = 22, ["name"] = "default:wood"}, {["x"] = 8, ["y"] = 26, ["param1"] = 56, ["z"] = 23, ["name"] = "default:wood"}, {["x"] = 8, ["y"] = 26, ["param1"] = 56, ["z"] = 24, ["name"] = "default:wood"}, {["x"] = 8, ["y"] = 26, ["param1"] = 56, ["z"] = 25, ["name"] = "default:wood"}, {["x"] = 8, ["y"] = 26, ["param1"] = 62, ["z"] = 26, ["name"] = "default:junglewood"}, {["x"] = 8, ["y"] = 26, ["param1"] = 62, ["z"] = 27, ["name"] = "default:junglewood"}, {["x"] = 8, ["y"] = 26, ["param1"] = 62, ["z"] = 28, ["name"] = "default:junglewood"}, {["x"] = 8, ["y"] = 27, ["param1"] = 56, ["z"] = 21, ["name"] = "default:wood"}, {["x"] = 8, ["y"] = 27, ["param1"] = 56, ["z"] = 22, ["name"] = "default:wood"}, {["x"] = 8, ["y"] = 27, ["param1"] = 56, ["z"] = 23, ["name"] = "default:wood"}, {["x"] = 8, ["y"] = 27, ["param1"] = 62, ["z"] = 24, ["name"] = "default:junglewood"}, {["x"] = 8, ["y"] = 27, ["param1"] = 62, ["z"] = 25, ["name"] = "default:junglewood"}, {["x"] = 8, ["y"] = 27, ["param1"] = 62, ["z"] = 26, ["name"] = "default:junglewood"}, {["x"] = 8, ["y"] = 27, ["param1"] = 62, ["z"] = 27, ["name"] = "default:junglewood"}, {["x"] = 8, ["y"] = 27, ["param1"] = 62, ["z"] = 28, ["name"] = "default:junglewood"}, {["x"] = 8, ["y"] = 27, ["param1"] = 62, ["z"] = 29, ["name"] = "default:junglewood"}, {["x"] = 8, ["y"] = 28, ["param1"] = 56, ["z"] = 22, ["name"] = "default:wood"}, {["x"] = 8, ["y"] = 28, ["param1"] = 62, ["z"] = 23, ["name"] = "default:junglewood"}, {["x"] = 8, ["y"] = 28, ["param1"] = 62, ["z"] = 24, ["name"] = "default:junglewood"}, {["x"] = 8, ["y"] = 28, ["param1"] = 62, ["z"] = 25, ["name"] = "default:junglewood"}, {["x"] = 8, ["y"] = 28, ["param1"] = 62, ["z"] = 26, ["name"] = "default:junglewood"}, {["x"] = 8, ["y"] = 28, ["param1"] = 62, ["z"] = 27, ["name"] = "default:junglewood"}, {["x"] = 8, ["y"] = 28, ["param1"] = 62, ["z"] = 28, ["name"] = "default:junglewood"}, {["x"] = 8, ["y"] = 28, ["param1"] = 62, ["z"] = 29, ["name"] = "default:junglewood"}, {["x"] = 8, ["y"] = 29, ["param1"] = 62, ["z"] = 27, ["name"] = "default:junglewood"}, {["x"] = 8, ["y"] = 29, ["param1"] = 62, ["z"] = 28, ["name"] = "default:junglewood"}, {["x"] = 8, ["y"] = 29, ["param1"] = 62, ["z"] = 29, ["name"] = "default:junglewood"}, {["x"] = 8, ["y"] = 29, ["param1"] = 62, ["z"] = 30, ["name"] = "default:junglewood"}, {["x"] = 8, ["y"] = 30, ["param1"] = 62, ["z"] = 29, ["name"] = "default:junglewood"}, {["x"] = 8, ["y"] = 30, ["param1"] = 62, ["z"] = 30, ["name"] = "default:junglewood"}, {["x"] = 8, ["y"] = 31, ["param1"] = 62, ["z"] = 31, ["name"] = "default:junglewood"}, {["x"] = 9, ["y"] = 13, ["param1"] = 56, ["z"] = 19, ["name"] = "default:wood"}, {["x"] = 9, ["y"] = 14, ["param1"] = 56, ["z"] = 18, ["name"] = "default:wood"}, {["x"] = 9, ["y"] = 14, ["param1"] = 56, ["z"] = 19, ["name"] = "default:wood"}, {["x"] = 9, ["y"] = 14, ["param1"] = 56, ["z"] = 20, ["name"] = "default:wood"}, {["x"] = 9, ["y"] = 15, ["param1"] = 56, ["z"] = 17, ["name"] = "default:wood"}, {["x"] = 9, ["y"] = 15, ["param1"] = 56, ["z"] = 18, ["name"] = "default:wood"}, {["x"] = 9, ["y"] = 15, ["param1"] = 56, ["z"] = 19, ["name"] = "default:wood"}, {["x"] = 9, ["y"] = 15, ["param1"] = 56, ["z"] = 20, ["name"] = "default:wood"}, {["x"] = 9, ["y"] = 15, ["param1"] = 56, ["z"] = 21, ["name"] = "default:wood"}, {["x"] = 9, ["y"] = 16, ["param1"] = 56, ["z"] = 16, ["name"] = "default:wood"}, {["x"] = 9, ["y"] = 16, ["param1"] = 56, ["z"] = 17, ["name"] = "default:wood"}, {["x"] = 9, ["y"] = 16, ["param1"] = 56, ["z"] = 18, ["name"] = "default:wood"}, {["x"] = 9, ["y"] = 16, ["param1"] = 56, ["z"] = 19, ["name"] = "default:wood"}, {["x"] = 9, ["y"] = 16, ["param1"] = 56, ["z"] = 20, ["name"] = "default:wood"}, {["x"] = 9, ["y"] = 16, ["param1"] = 56, ["z"] = 21, ["name"] = "default:wood"}, {["x"] = 9, ["y"] = 16, ["param1"] = 56, ["z"] = 22, ["name"] = "default:wood"}, {["x"] = 9, ["y"] = 17, ["param1"] = 56, ["z"] = 15, ["name"] = "default:wood"}, {["x"] = 9, ["y"] = 17, ["param1"] = 56, ["z"] = 16, ["name"] = "default:wood"}, {["x"] = 9, ["y"] = 17, ["param1"] = 56, ["z"] = 17, ["name"] = "default:wood"}, {["x"] = 9, ["y"] = 17, ["param1"] = 56, ["z"] = 18, ["name"] = "default:wood"}, {["x"] = 9, ["y"] = 17, ["param1"] = 56, ["z"] = 19, ["name"] = "default:wood"}, {["x"] = 9, ["y"] = 17, ["param1"] = 56, ["z"] = 20, ["name"] = "default:wood"}, {["x"] = 9, ["y"] = 17, ["param1"] = 56, ["z"] = 21, ["name"] = "default:wood"}, {["x"] = 9, ["y"] = 17, ["param1"] = 56, ["z"] = 22, ["name"] = "default:wood"}, {["x"] = 9, ["y"] = 17, ["param1"] = 56, ["z"] = 23, ["name"] = "default:wood"}, {["x"] = 9, ["y"] = 18, ["param1"] = 56, ["z"] = 14, ["name"] = "default:wood"}, {["x"] = 9, ["y"] = 18, ["param1"] = 56, ["z"] = 15, ["name"] = "default:wood"}, {["x"] = 9, ["y"] = 18, ["param1"] = 56, ["z"] = 16, ["name"] = "default:wood"}, {["x"] = 9, ["y"] = 18, ["param1"] = 56, ["z"] = 17, ["name"] = "default:wood"}, {["x"] = 9, ["y"] = 18, ["param1"] = 56, ["z"] = 18, ["name"] = "default:wood"}, {["x"] = 9, ["y"] = 18, ["param1"] = 56, ["z"] = 19, ["name"] = "default:wood"}, {["x"] = 9, ["y"] = 18, ["param1"] = 56, ["z"] = 20, ["name"] = "default:wood"}, {["x"] = 9, ["y"] = 18, ["param1"] = 56, ["z"] = 21, ["name"] = "default:wood"}, {["x"] = 9, ["y"] = 18, ["param1"] = 56, ["z"] = 22, ["name"] = "default:wood"}, {["x"] = 9, ["y"] = 18, ["param1"] = 56, ["z"] = 23, ["name"] = "default:wood"}, {["x"] = 9, ["y"] = 18, ["param1"] = 56, ["z"] = 24, ["name"] = "default:wood"}, {["x"] = 9, ["y"] = 19, ["param1"] = 56, ["z"] = 13, ["name"] = "default:wood"}, {["x"] = 9, ["y"] = 19, ["param1"] = 56, ["z"] = 14, ["name"] = "default:wood"}, {["x"] = 9, ["y"] = 19, ["param1"] = 56, ["z"] = 15, ["name"] = "default:wood"}, {["x"] = 9, ["y"] = 19, ["param1"] = 56, ["z"] = 16, ["name"] = "default:wood"}, {["x"] = 9, ["y"] = 19, ["param1"] = 56, ["z"] = 17, ["name"] = "default:wood"}, {["x"] = 9, ["y"] = 19, ["param1"] = 56, ["z"] = 18, ["name"] = "default:wood"}, {["x"] = 9, ["y"] = 19, ["param1"] = 56, ["z"] = 19, ["name"] = "default:wood"}, {["x"] = 9, ["y"] = 19, ["param1"] = 56, ["z"] = 20, ["name"] = "default:wood"}, {["x"] = 9, ["y"] = 19, ["param1"] = 56, ["z"] = 21, ["name"] = "default:wood"}, {["x"] = 9, ["y"] = 19, ["param1"] = 56, ["z"] = 22, ["name"] = "default:wood"}, {["x"] = 9, ["y"] = 19, ["param1"] = 56, ["z"] = 23, ["name"] = "default:wood"}, {["x"] = 9, ["y"] = 19, ["param1"] = 56, ["z"] = 24, ["name"] = "default:wood"}, {["x"] = 9, ["y"] = 19, ["param1"] = 56, ["z"] = 25, ["name"] = "default:wood"}, {["x"] = 9, ["y"] = 20, ["param1"] = 56, ["z"] = 14, ["name"] = "default:wood"}, {["x"] = 9, ["y"] = 20, ["param1"] = 56, ["z"] = 15, ["name"] = "default:wood"}, {["x"] = 9, ["y"] = 20, ["param1"] = 56, ["z"] = 16, ["name"] = "default:wood"}, {["x"] = 9, ["y"] = 20, ["param1"] = 56, ["z"] = 17, ["name"] = "default:wood"}, {["x"] = 9, ["y"] = 20, ["param1"] = 56, ["z"] = 18, ["name"] = "default:wood"}, {["x"] = 9, ["y"] = 20, ["param1"] = 56, ["z"] = 19, ["name"] = "default:wood"}, {["x"] = 9, ["y"] = 20, ["param1"] = 56, ["z"] = 20, ["name"] = "default:wood"}, {["x"] = 9, ["y"] = 20, ["param1"] = 56, ["z"] = 21, ["name"] = "default:wood"}, {["x"] = 9, ["y"] = 20, ["param1"] = 56, ["z"] = 22, ["name"] = "default:wood"}, {["x"] = 9, ["y"] = 20, ["param1"] = 56, ["z"] = 23, ["name"] = "default:wood"}, {["x"] = 9, ["y"] = 20, ["param1"] = 56, ["z"] = 24, ["name"] = "default:wood"}, {["x"] = 9, ["y"] = 20, ["param1"] = 56, ["z"] = 25, ["name"] = "default:wood"}, {["x"] = 9, ["y"] = 20, ["param1"] = 56, ["z"] = 26, ["name"] = "default:wood"}, {["x"] = 9, ["y"] = 21, ["z"] = 15, ["name"] = "default:wood"}, {["x"] = 9, ["y"] = 21, ["z"] = 16, ["name"] = "default:wood"}, {["x"] = 9, ["y"] = 21, ["param1"] = 56, ["z"] = 17, ["name"] = "default:wood"}, {["x"] = 9, ["y"] = 21, ["param1"] = 56, ["z"] = 18, ["name"] = "default:wood"}, {["x"] = 9, ["y"] = 21, ["param1"] = 56, ["z"] = 19, ["name"] = "default:wood"}, {["x"] = 9, ["y"] = 21, ["param1"] = 56, ["z"] = 20, ["name"] = "default:wood"}, {["x"] = 9, ["y"] = 21, ["param1"] = 56, ["z"] = 21, ["name"] = "default:wood"}, {["x"] = 9, ["y"] = 21, ["param1"] = 56, ["z"] = 22, ["name"] = "default:wood"}, {["x"] = 9, ["y"] = 21, ["param1"] = 56, ["z"] = 23, ["name"] = "default:wood"}, {["x"] = 9, ["y"] = 21, ["param1"] = 56, ["z"] = 24, ["name"] = "default:wood"}, {["x"] = 9, ["y"] = 21, ["param1"] = 56, ["z"] = 25, ["name"] = "default:wood"}, {["x"] = 9, ["y"] = 21, ["param1"] = 56, ["z"] = 26, ["name"] = "default:wood"}, {["x"] = 9, ["y"] = 21, ["param1"] = 56, ["z"] = 27, ["name"] = "default:wood"}, {["x"] = 9, ["y"] = 22, ["param1"] = 56, ["z"] = 16, ["name"] = "default:wood"}, {["x"] = 9, ["y"] = 22, ["param1"] = 56, ["z"] = 17, ["name"] = "default:wood"}, {["x"] = 9, ["y"] = 22, ["param1"] = 56, ["z"] = 18, ["name"] = "default:wood"}, {["x"] = 9, ["y"] = 22, ["param1"] = 56, ["z"] = 19, ["name"] = "default:wood"}, {["x"] = 9, ["y"] = 22, ["param1"] = 56, ["z"] = 20, ["name"] = "default:wood"}, {["x"] = 9, ["y"] = 22, ["param1"] = 56, ["z"] = 21, ["name"] = "default:wood"}, {["x"] = 9, ["y"] = 22, ["param1"] = 56, ["z"] = 22, ["name"] = "default:wood"}, {["x"] = 9, ["y"] = 22, ["param1"] = 56, ["z"] = 23, ["name"] = "default:wood"}, {["x"] = 9, ["y"] = 22, ["param1"] = 56, ["z"] = 24, ["name"] = "default:wood"}, {["x"] = 9, ["y"] = 22, ["param1"] = 56, ["z"] = 25, ["name"] = "default:wood"}, {["x"] = 9, ["y"] = 22, ["param1"] = 56, ["z"] = 26, ["name"] = "default:wood"}, {["x"] = 9, ["y"] = 22, ["param1"] = 56, ["z"] = 27, ["name"] = "default:wood"}, {["x"] = 9, ["y"] = 22, ["param1"] = 56, ["z"] = 28, ["name"] = "default:wood"}, {["x"] = 9, ["y"] = 23, ["param1"] = 56, ["z"] = 17, ["name"] = "default:wood"}, {["x"] = 9, ["y"] = 23, ["param1"] = 56, ["z"] = 18, ["name"] = "default:wood"}, {["x"] = 9, ["y"] = 23, ["param1"] = 56, ["z"] = 19, ["name"] = "default:wood"}, {["x"] = 9, ["y"] = 23, ["param1"] = 56, ["z"] = 20, ["name"] = "default:wood"}, {["x"] = 9, ["y"] = 23, ["param1"] = 56, ["z"] = 21, ["name"] = "default:wood"}, {["x"] = 9, ["y"] = 23, ["param1"] = 56, ["z"] = 22, ["name"] = "default:wood"}, {["x"] = 9, ["y"] = 23, ["param1"] = 56, ["z"] = 23, ["name"] = "default:wood"}, {["x"] = 9, ["y"] = 23, ["param1"] = 56, ["z"] = 24, ["name"] = "default:wood"}, {["x"] = 9, ["y"] = 23, ["param1"] = 56, ["z"] = 25, ["name"] = "default:wood"}, {["x"] = 9, ["y"] = 23, ["param1"] = 56, ["z"] = 26, ["name"] = "default:wood"}, {["x"] = 9, ["y"] = 23, ["param1"] = 56, ["z"] = 27, ["name"] = "default:wood"}, {["x"] = 9, ["y"] = 23, ["param1"] = 62, ["z"] = 28, ["name"] = "default:junglewood"}, {["x"] = 9, ["y"] = 24, ["param1"] = 56, ["z"] = 18, ["name"] = "default:wood"}, {["x"] = 9, ["y"] = 24, ["param1"] = 56, ["z"] = 19, ["name"] = "default:wood"}, {["x"] = 9, ["y"] = 24, ["param1"] = 56, ["z"] = 20, ["name"] = "default:wood"}, {["x"] = 9, ["y"] = 24, ["param1"] = 56, ["z"] = 21, ["name"] = "default:wood"}, {["x"] = 9, ["y"] = 24, ["param1"] = 56, ["z"] = 22, ["name"] = "default:wood"}, {["x"] = 9, ["y"] = 24, ["param1"] = 56, ["z"] = 23, ["name"] = "default:wood"}, {["x"] = 9, ["y"] = 24, ["param1"] = 56, ["z"] = 24, ["name"] = "default:wood"}, {["x"] = 9, ["y"] = 24, ["param1"] = 56, ["z"] = 25, ["name"] = "default:wood"}, {["x"] = 9, ["y"] = 24, ["param1"] = 56, ["z"] = 26, ["name"] = "default:wood"}, {["x"] = 9, ["y"] = 24, ["param1"] = 62, ["z"] = 27, ["name"] = "default:junglewood"}, {["x"] = 9, ["y"] = 24, ["param1"] = 62, ["z"] = 28, ["name"] = "default:junglewood"}, {["x"] = 9, ["y"] = 25, ["param1"] = 56, ["z"] = 19, ["name"] = "default:wood"}, {["x"] = 9, ["y"] = 25, ["param1"] = 56, ["z"] = 20, ["name"] = "default:wood"}, {["x"] = 9, ["y"] = 25, ["param1"] = 56, ["z"] = 21, ["name"] = "default:wood"}, {["x"] = 9, ["y"] = 25, ["param1"] = 56, ["z"] = 22, ["name"] = "default:wood"}, {["x"] = 9, ["y"] = 25, ["param1"] = 56, ["z"] = 23, ["name"] = "default:wood"}, {["x"] = 9, ["y"] = 25, ["param1"] = 56, ["z"] = 24, ["name"] = "default:wood"}, {["x"] = 9, ["y"] = 25, ["param1"] = 56, ["z"] = 25, ["name"] = "default:wood"}, {["x"] = 9, ["y"] = 25, ["param1"] = 56, ["z"] = 26, ["name"] = "default:wood"}, {["x"] = 9, ["y"] = 25, ["param1"] = 62, ["z"] = 27, ["name"] = "default:junglewood"}, {["x"] = 9, ["y"] = 25, ["param1"] = 62, ["z"] = 28, ["name"] = "default:junglewood"}, {["x"] = 9, ["y"] = 26, ["param1"] = 56, ["z"] = 20, ["name"] = "default:wood"}, {["x"] = 9, ["y"] = 26, ["param1"] = 56, ["z"] = 21, ["name"] = "default:wood"}, {["x"] = 9, ["y"] = 26, ["param1"] = 56, ["z"] = 22, ["name"] = "default:wood"}, {["x"] = 9, ["y"] = 26, ["param1"] = 56, ["z"] = 23, ["name"] = "default:wood"}, {["x"] = 9, ["y"] = 26, ["param1"] = 56, ["z"] = 24, ["name"] = "default:wood"}, {["x"] = 9, ["y"] = 26, ["param1"] = 56, ["z"] = 25, ["name"] = "default:wood"}, {["x"] = 9, ["y"] = 26, ["param1"] = 62, ["z"] = 26, ["name"] = "default:junglewood"}, {["x"] = 9, ["y"] = 26, ["param1"] = 62, ["z"] = 27, ["name"] = "default:junglewood"}, {["x"] = 9, ["y"] = 26, ["param1"] = 62, ["z"] = 28, ["name"] = "default:junglewood"}, {["x"] = 9, ["y"] = 27, ["param1"] = 56, ["z"] = 21, ["name"] = "default:wood"}, {["x"] = 9, ["y"] = 27, ["param1"] = 56, ["z"] = 22, ["name"] = "default:wood"}, {["x"] = 9, ["y"] = 27, ["param1"] = 56, ["z"] = 23, ["name"] = "default:wood"}, {["x"] = 9, ["y"] = 27, ["param1"] = 62, ["z"] = 24, ["name"] = "default:junglewood"}, {["x"] = 9, ["y"] = 27, ["param1"] = 62, ["z"] = 25, ["name"] = "default:junglewood"}, {["x"] = 9, ["y"] = 27, ["param1"] = 62, ["z"] = 26, ["name"] = "default:junglewood"}, {["x"] = 9, ["y"] = 27, ["param1"] = 62, ["z"] = 27, ["name"] = "default:junglewood"}, {["x"] = 9, ["y"] = 27, ["param1"] = 62, ["z"] = 28, ["name"] = "default:junglewood"}, {["x"] = 9, ["y"] = 27, ["param1"] = 62, ["z"] = 29, ["name"] = "default:junglewood"}, {["x"] = 9, ["y"] = 28, ["param1"] = 56, ["z"] = 22, ["name"] = "default:wood"}, {["x"] = 9, ["y"] = 28, ["param1"] = 62, ["z"] = 23, ["name"] = "default:junglewood"}, {["x"] = 9, ["y"] = 28, ["param1"] = 62, ["z"] = 24, ["name"] = "default:junglewood"}, {["x"] = 9, ["y"] = 28, ["param1"] = 62, ["z"] = 25, ["name"] = "default:junglewood"}, {["x"] = 9, ["y"] = 28, ["param1"] = 62, ["z"] = 26, ["name"] = "default:junglewood"}, {["x"] = 9, ["y"] = 28, ["param1"] = 62, ["z"] = 27, ["name"] = "default:junglewood"}, {["x"] = 9, ["y"] = 28, ["param1"] = 62, ["z"] = 28, ["name"] = "default:junglewood"}, {["x"] = 9, ["y"] = 28, ["param1"] = 62, ["z"] = 29, ["name"] = "default:junglewood"}, {["x"] = 9, ["y"] = 29, ["param1"] = 62, ["z"] = 27, ["name"] = "default:junglewood"}, {["x"] = 9, ["y"] = 29, ["param1"] = 62, ["z"] = 28, ["name"] = "default:junglewood"}, {["x"] = 9, ["y"] = 29, ["param1"] = 62, ["z"] = 29, ["name"] = "default:junglewood"}, {["x"] = 10, ["y"] = 14, ["param1"] = 56, ["z"] = 18, ["name"] = "default:wood"}, {["x"] = 10, ["y"] = 15, ["param1"] = 56, ["z"] = 17, ["name"] = "default:wood"}, {["x"] = 10, ["y"] = 15, ["param1"] = 56, ["z"] = 18, ["name"] = "default:wood"}, {["x"] = 10, ["y"] = 15, ["param1"] = 56, ["z"] = 19, ["name"] = "default:wood"}, {["x"] = 10, ["y"] = 16, ["param1"] = 56, ["z"] = 16, ["name"] = "default:wood"}, {["x"] = 10, ["y"] = 16, ["param1"] = 56, ["z"] = 17, ["name"] = "default:wood"}, {["x"] = 10, ["y"] = 16, ["param1"] = 56, ["z"] = 18, ["name"] = "default:wood"}, {["x"] = 10, ["y"] = 16, ["param1"] = 56, ["z"] = 19, ["name"] = "default:wood"}, {["x"] = 10, ["y"] = 16, ["param1"] = 56, ["z"] = 20, ["name"] = "default:wood"}, {["x"] = 10, ["y"] = 17, ["param1"] = 56, ["z"] = 15, ["name"] = "default:wood"}, {["x"] = 10, ["y"] = 17, ["param1"] = 56, ["z"] = 16, ["name"] = "default:wood"}, {["x"] = 10, ["y"] = 17, ["param1"] = 56, ["z"] = 17, ["name"] = "default:wood"}, {["x"] = 10, ["y"] = 17, ["param1"] = 56, ["z"] = 18, ["name"] = "default:wood"}, {["x"] = 10, ["y"] = 17, ["param1"] = 56, ["z"] = 19, ["name"] = "default:wood"}, {["x"] = 10, ["y"] = 17, ["param1"] = 56, ["z"] = 20, ["name"] = "default:wood"}, {["x"] = 10, ["y"] = 17, ["param1"] = 56, ["z"] = 21, ["name"] = "default:wood"}, {["x"] = 10, ["y"] = 18, ["param1"] = 56, ["z"] = 14, ["name"] = "default:wood"}, {["x"] = 10, ["y"] = 18, ["param1"] = 56, ["z"] = 15, ["name"] = "default:wood"}, {["x"] = 10, ["y"] = 18, ["param1"] = 56, ["z"] = 16, ["name"] = "default:wood"}, {["x"] = 10, ["y"] = 18, ["param1"] = 56, ["z"] = 17, ["name"] = "default:wood"}, {["x"] = 10, ["y"] = 18, ["param1"] = 56, ["z"] = 18, ["name"] = "default:wood"}, {["x"] = 10, ["y"] = 18, ["param1"] = 56, ["z"] = 19, ["name"] = "default:wood"}, {["x"] = 10, ["y"] = 18, ["param1"] = 56, ["z"] = 20, ["name"] = "default:wood"}, {["x"] = 10, ["y"] = 18, ["param1"] = 56, ["z"] = 21, ["name"] = "default:wood"}, {["x"] = 10, ["y"] = 18, ["param1"] = 56, ["z"] = 22, ["name"] = "default:wood"}, {["x"] = 10, ["y"] = 19, ["param1"] = 56, ["z"] = 15, ["name"] = "default:wood"}, {["x"] = 10, ["y"] = 19, ["param1"] = 56, ["z"] = 16, ["name"] = "default:wood"}, {["x"] = 10, ["y"] = 19, ["param1"] = 56, ["z"] = 17, ["name"] = "default:wood"}, {["x"] = 10, ["y"] = 19, ["param1"] = 56, ["z"] = 18, ["name"] = "default:wood"}, {["x"] = 10, ["y"] = 19, ["param1"] = 56, ["z"] = 19, ["name"] = "default:wood"}, {["x"] = 10, ["y"] = 19, ["param1"] = 56, ["z"] = 20, ["name"] = "default:wood"}, {["x"] = 10, ["y"] = 19, ["param1"] = 56, ["z"] = 21, ["name"] = "default:wood"}, {["x"] = 10, ["y"] = 19, ["param1"] = 56, ["z"] = 22, ["name"] = "default:wood"}, {["x"] = 10, ["y"] = 19, ["param1"] = 56, ["z"] = 23, ["name"] = "default:wood"}, {["x"] = 10, ["y"] = 20, ["param1"] = 56, ["z"] = 16, ["name"] = "default:wood"}, {["x"] = 10, ["y"] = 20, ["param1"] = 56, ["z"] = 17, ["name"] = "default:wood"}, {["x"] = 10, ["y"] = 20, ["param1"] = 56, ["z"] = 18, ["name"] = "default:wood"}, {["x"] = 10, ["y"] = 20, ["param1"] = 56, ["z"] = 19, ["name"] = "default:wood"}, {["x"] = 10, ["y"] = 20, ["param1"] = 56, ["z"] = 20, ["name"] = "default:wood"}, {["x"] = 10, ["y"] = 20, ["param1"] = 56, ["z"] = 21, ["name"] = "default:wood"}, {["x"] = 10, ["y"] = 20, ["param1"] = 56, ["z"] = 22, ["name"] = "default:wood"}, {["x"] = 10, ["y"] = 20, ["param1"] = 56, ["z"] = 23, ["name"] = "default:wood"}, {["x"] = 10, ["y"] = 20, ["param1"] = 56, ["z"] = 24, ["name"] = "default:wood"}, {["x"] = 10, ["y"] = 21, ["param1"] = 56, ["z"] = 17, ["name"] = "default:wood"}, {["x"] = 10, ["y"] = 21, ["param1"] = 56, ["z"] = 18, ["name"] = "default:wood"}, {["x"] = 10, ["y"] = 21, ["param1"] = 56, ["z"] = 19, ["name"] = "default:wood"}, {["x"] = 10, ["y"] = 21, ["param1"] = 56, ["z"] = 20, ["name"] = "default:wood"}, {["x"] = 10, ["y"] = 21, ["param1"] = 56, ["z"] = 21, ["name"] = "default:wood"}, {["x"] = 10, ["y"] = 21, ["param1"] = 56, ["z"] = 22, ["name"] = "default:wood"}, {["x"] = 10, ["y"] = 21, ["param1"] = 56, ["z"] = 23, ["name"] = "default:wood"}, {["x"] = 10, ["y"] = 21, ["param1"] = 56, ["z"] = 24, ["name"] = "default:wood"}, {["x"] = 10, ["y"] = 21, ["param1"] = 56, ["z"] = 25, ["name"] = "default:wood"}, {["x"] = 10, ["y"] = 22, ["param1"] = 56, ["z"] = 18, ["name"] = "default:wood"}, {["x"] = 10, ["y"] = 22, ["param1"] = 56, ["z"] = 19, ["name"] = "default:wood"}, {["x"] = 10, ["y"] = 22, ["param1"] = 56, ["z"] = 20, ["name"] = "default:wood"}, {["x"] = 10, ["y"] = 22, ["param1"] = 56, ["z"] = 21, ["name"] = "default:wood"}, {["x"] = 10, ["y"] = 22, ["param1"] = 56, ["z"] = 22, ["name"] = "default:wood"}, {["x"] = 10, ["y"] = 22, ["param1"] = 56, ["z"] = 23, ["name"] = "default:wood"}, {["x"] = 10, ["y"] = 22, ["param1"] = 56, ["z"] = 24, ["name"] = "default:wood"}, {["x"] = 10, ["y"] = 22, ["param1"] = 56, ["z"] = 25, ["name"] = "default:wood"}, {["x"] = 10, ["y"] = 22, ["param1"] = 56, ["z"] = 26, ["name"] = "default:wood"}, {["x"] = 10, ["y"] = 23, ["param1"] = 56, ["z"] = 19, ["name"] = "default:wood"}, {["x"] = 10, ["y"] = 23, ["param1"] = 56, ["z"] = 20, ["name"] = "default:wood"}, {["x"] = 10, ["y"] = 23, ["param1"] = 56, ["z"] = 21, ["name"] = "default:wood"}, {["x"] = 10, ["y"] = 23, ["param1"] = 56, ["z"] = 22, ["name"] = "default:wood"}, {["x"] = 10, ["y"] = 23, ["param1"] = 56, ["z"] = 23, ["name"] = "default:wood"}, {["x"] = 10, ["y"] = 23, ["param1"] = 56, ["z"] = 24, ["name"] = "default:wood"}, {["x"] = 10, ["y"] = 23, ["param1"] = 56, ["z"] = 25, ["name"] = "default:wood"}, {["x"] = 10, ["y"] = 23, ["param1"] = 56, ["z"] = 26, ["name"] = "default:wood"}, {["x"] = 10, ["y"] = 23, ["param1"] = 56, ["z"] = 27, ["name"] = "default:wood"}, {["x"] = 10, ["y"] = 24, ["param1"] = 56, ["z"] = 20, ["name"] = "default:wood"}, {["x"] = 10, ["y"] = 24, ["param1"] = 56, ["z"] = 21, ["name"] = "default:wood"}, {["x"] = 10, ["y"] = 24, ["param1"] = 56, ["z"] = 22, ["name"] = "default:wood"}, {["x"] = 10, ["y"] = 24, ["param1"] = 56, ["z"] = 23, ["name"] = "default:wood"}, {["x"] = 10, ["y"] = 24, ["param1"] = 56, ["z"] = 24, ["name"] = "default:wood"}, {["x"] = 10, ["y"] = 24, ["param1"] = 56, ["z"] = 25, ["name"] = "default:wood"}, {["x"] = 10, ["y"] = 24, ["param1"] = 56, ["z"] = 26, ["name"] = "default:wood"}, {["x"] = 10, ["y"] = 24, ["param1"] = 62, ["z"] = 27, ["name"] = "default:junglewood"}, {["x"] = 10, ["y"] = 25, ["param1"] = 56, ["z"] = 21, ["name"] = "default:wood"}, {["x"] = 10, ["y"] = 25, ["param1"] = 56, ["z"] = 22, ["name"] = "default:wood"}, {["x"] = 10, ["y"] = 25, ["param1"] = 56, ["z"] = 23, ["name"] = "default:wood"}, {["x"] = 10, ["y"] = 25, ["param1"] = 56, ["z"] = 24, ["name"] = "default:wood"}, {["x"] = 10, ["y"] = 25, ["param1"] = 56, ["z"] = 25, ["name"] = "default:wood"}, {["x"] = 10, ["y"] = 25, ["param1"] = 56, ["z"] = 26, ["name"] = "default:wood"}, {["x"] = 10, ["y"] = 25, ["param1"] = 62, ["z"] = 27, ["name"] = "default:junglewood"}, {["x"] = 10, ["y"] = 26, ["param1"] = 56, ["z"] = 22, ["name"] = "default:wood"}, {["x"] = 10, ["y"] = 26, ["param1"] = 56, ["z"] = 23, ["name"] = "default:wood"}, {["x"] = 10, ["y"] = 26, ["param1"] = 56, ["z"] = 24, ["name"] = "default:wood"}, {["x"] = 10, ["y"] = 26, ["param1"] = 56, ["z"] = 25, ["name"] = "default:wood"}, {["x"] = 10, ["y"] = 26, ["param1"] = 62, ["z"] = 26, ["name"] = "default:junglewood"}, {["x"] = 10, ["y"] = 26, ["param1"] = 62, ["z"] = 27, ["name"] = "default:junglewood"}, {["x"] = 10, ["y"] = 27, ["param1"] = 56, ["z"] = 23, ["name"] = "default:wood"}, {["x"] = 10, ["y"] = 27, ["param1"] = 62, ["z"] = 24, ["name"] = "default:junglewood"}, {["x"] = 10, ["y"] = 27, ["param1"] = 62, ["z"] = 25, ["name"] = "default:junglewood"}, {["x"] = 10, ["y"] = 27, ["param1"] = 62, ["z"] = 26, ["name"] = "default:junglewood"}, {["x"] = 10, ["y"] = 27, ["param1"] = 62, ["z"] = 27, ["name"] = "default:junglewood"}, {["x"] = 10, ["y"] = 28, ["param1"] = 62, ["z"] = 28, ["name"] = "default:junglewood"}, {["x"] = 11, ["y"] = 15, ["param1"] = 56, ["z"] = 17, ["name"] = "default:wood"}, {["x"] = 11, ["y"] = 16, ["param1"] = 56, ["z"] = 16, ["name"] = "default:wood"}, {["x"] = 11, ["y"] = 16, ["param1"] = 56, ["z"] = 17, ["name"] = "default:wood"}, {["x"] = 11, ["y"] = 16, ["param1"] = 56, ["z"] = 18, ["name"] = "default:wood"}, {["x"] = 11, ["y"] = 17, ["param1"] = 56, ["z"] = 15, ["name"] = "default:wood"}, {["x"] = 11, ["y"] = 17, ["param1"] = 56, ["z"] = 16, ["name"] = "default:wood"}, {["x"] = 11, ["y"] = 17, ["param1"] = 56, ["z"] = 17, ["name"] = "default:wood"}, {["x"] = 11, ["y"] = 17, ["param1"] = 56, ["z"] = 18, ["name"] = "default:wood"}, {["x"] = 11, ["y"] = 17, ["param1"] = 56, ["z"] = 19, ["name"] = "default:wood"}, {["x"] = 11, ["y"] = 18, ["param1"] = 56, ["z"] = 16, ["name"] = "default:wood"}, {["x"] = 11, ["y"] = 18, ["param1"] = 56, ["z"] = 17, ["name"] = "default:wood"}, {["x"] = 11, ["y"] = 18, ["param1"] = 56, ["z"] = 18, ["name"] = "default:wood"}, {["x"] = 11, ["y"] = 18, ["param1"] = 56, ["z"] = 19, ["name"] = "default:wood"}, {["x"] = 11, ["y"] = 18, ["param1"] = 56, ["z"] = 20, ["name"] = "default:wood"}, {["x"] = 11, ["y"] = 19, ["param1"] = 56, ["z"] = 17, ["name"] = "default:wood"}, {["x"] = 11, ["y"] = 19, ["param1"] = 56, ["z"] = 18, ["name"] = "default:wood"}, {["x"] = 11, ["y"] = 19, ["param1"] = 56, ["z"] = 19, ["name"] = "default:wood"}, {["x"] = 11, ["y"] = 19, ["param1"] = 56, ["z"] = 20, ["name"] = "default:wood"}, {["x"] = 11, ["y"] = 19, ["param1"] = 56, ["z"] = 21, ["name"] = "default:wood"}, {["x"] = 11, ["y"] = 20, ["param1"] = 56, ["z"] = 18, ["name"] = "default:wood"}, {["x"] = 11, ["y"] = 20, ["param1"] = 56, ["z"] = 19, ["name"] = "default:wood"}, {["x"] = 11, ["y"] = 20, ["param1"] = 56, ["z"] = 20, ["name"] = "default:wood"}, {["x"] = 11, ["y"] = 20, ["param1"] = 56, ["z"] = 21, ["name"] = "default:wood"}, {["x"] = 11, ["y"] = 20, ["param1"] = 56, ["z"] = 22, ["name"] = "default:wood"}, {["x"] = 11, ["y"] = 21, ["param1"] = 56, ["z"] = 19, ["name"] = "default:wood"}, {["x"] = 11, ["y"] = 21, ["param1"] = 56, ["z"] = 20, ["name"] = "default:wood"}, {["x"] = 11, ["y"] = 21, ["param1"] = 56, ["z"] = 21, ["name"] = "default:wood"}, {["x"] = 11, ["y"] = 21, ["param1"] = 56, ["z"] = 22, ["name"] = "default:wood"}, {["x"] = 11, ["y"] = 21, ["param1"] = 56, ["z"] = 23, ["name"] = "default:wood"}, {["x"] = 11, ["y"] = 22, ["param1"] = 56, ["z"] = 20, ["name"] = "default:wood"}, {["x"] = 11, ["y"] = 22, ["param1"] = 56, ["z"] = 21, ["name"] = "default:wood"}, {["x"] = 11, ["y"] = 22, ["param1"] = 56, ["z"] = 22, ["name"] = "default:wood"}, {["x"] = 11, ["y"] = 22, ["param1"] = 56, ["z"] = 23, ["name"] = "default:wood"}, {["x"] = 11, ["y"] = 22, ["param1"] = 56, ["z"] = 24, ["name"] = "default:wood"}, {["x"] = 11, ["y"] = 23, ["param1"] = 56, ["z"] = 21, ["name"] = "default:wood"}, {["x"] = 11, ["y"] = 23, ["param1"] = 56, ["z"] = 22, ["name"] = "default:wood"}, {["x"] = 11, ["y"] = 23, ["param1"] = 56, ["z"] = 23, ["name"] = "default:wood"}, {["x"] = 11, ["y"] = 23, ["param1"] = 56, ["z"] = 24, ["name"] = "default:wood"}, {["x"] = 11, ["y"] = 23, ["param1"] = 56, ["z"] = 25, ["name"] = "default:wood"}, {["x"] = 11, ["y"] = 24, ["param1"] = 56, ["z"] = 22, ["name"] = "default:wood"}, {["x"] = 11, ["y"] = 24, ["param1"] = 56, ["z"] = 23, ["name"] = "default:wood"}, {["x"] = 11, ["y"] = 24, ["param1"] = 56, ["z"] = 24, ["name"] = "default:wood"}, {["x"] = 11, ["y"] = 24, ["param1"] = 56, ["z"] = 25, ["name"] = "default:wood"}, {["x"] = 11, ["y"] = 24, ["param1"] = 56, ["z"] = 26, ["name"] = "default:wood"}, {["x"] = 11, ["y"] = 25, ["param1"] = 56, ["z"] = 23, ["name"] = "default:wood"}, {["x"] = 11, ["y"] = 25, ["param1"] = 56, ["z"] = 24, ["name"] = "default:wood"}, {["x"] = 11, ["y"] = 25, ["param1"] = 56, ["z"] = 25, ["name"] = "default:wood"}, {["x"] = 11, ["y"] = 25, ["param1"] = 56, ["z"] = 26, ["name"] = "default:wood"}, {["x"] = 11, ["y"] = 26, ["param1"] = 56, ["z"] = 24, ["name"] = "default:wood"}, {["x"] = 11, ["y"] = 26, ["param1"] = 56, ["z"] = 25, ["name"] = "default:wood"}, {["x"] = 11, ["y"] = 26, ["param1"] = 62, ["z"] = 26, ["name"] = "default:junglewood"}}