5:return {{["x"] = 5, ["y"] = 0, ["param1"] = 56, ["z"] = 16, ["name"] = "default:wood"}, {["x"] = 5, ["y"] = 0, ["param1"] = 56, ["z"] = 17, ["name"] = "default:wood"}, {["x"] = 5, ["y"] = 0, ["param1"] = 56, ["z"] = 18, ["name"] = "default:wood"}, {["x"] = 5, ["y"] = 1, ["param1"] = 56, ["z"] = 15, ["name"] = "default:wood"}, {["x"] = 5, ["y"] = 1, ["param1"] = 56, ["z"] = 16, ["name"] = "default:wood"}, {["x"] = 5, ["y"] = 1, ["param1"] = 56, ["z"] = 17, ["name"] = "default:wood"}, {["x"] = 5, ["y"] = 1, ["param1"] = 56, ["z"] = 18, ["name"] = "default:wood"}, {["x"] = 5, ["y"] = 1, ["param1"] = 56, ["z"] = 19, ["name"] = "default:wood"}, {["x"] = 5, ["y"] = 2, ["param1"] = 56, ["z"] = 16, ["name"] = "default:wood"}, {["x"] = 5, ["y"] = 2, ["param1"] = 56, ["z"] = 17, ["name"] = "default:wood"}, {["x"] = 5, ["y"] = 2, ["param1"] = 56, ["z"] = 18, ["name"] = "default:wood"}, {["x"] = 5, ["y"] = 2, ["param1"] = 56, ["z"] = 19, ["name"] = "default:wood"}, {["x"] = 5, ["y"] = 2, ["param1"] = 56, ["z"] = 20, ["name"] = "default:wood"}, {["x"] = 5, ["y"] = 3, ["param1"] = 56, ["z"] = 17, ["name"] = "default:wood"}, {["x"] = 5, ["y"] = 3, ["param1"] = 56, ["z"] = 18, ["name"] = "default:wood"}, {["x"] = 5, ["y"] = 3, ["param1"] = 56, ["z"] = 19, ["name"] = "default:wood"}, {["x"] = 5, ["y"] = 3, ["param1"] = 56, ["z"] = 20, ["name"] = "default:wood"}, {["x"] = 5, ["y"] = 3, ["param1"] = 56, ["z"] = 21, ["name"] = "default:wood"}, {["x"] = 5, ["y"] = 4, ["param1"] = 56, ["z"] = 18, ["name"] = "default:wood"}, {["x"] = 5, ["y"] = 4, ["param1"] = 56, ["z"] = 19, ["name"] = "default:wood"}, {["x"] = 5, ["y"] = 4, ["param1"] = 56, ["z"] = 20, ["name"] = "default:wood"}, {["x"] = 5, ["y"] = 4, ["param1"] = 56, ["z"] = 21, ["name"] = "default:wood"}, {["x"] = 5, ["y"] = 4, ["param1"] = 56, ["z"] = 22, ["name"] = "default:wood"}, {["x"] = 5, ["y"] = 5, ["param1"] = 56, ["z"] = 19, ["name"] = "default:wood"}, {["x"] = 5, ["y"] = 5, ["param1"] = 56, ["z"] = 20, ["name"] = "default:wood"}, {["x"] = 5, ["y"] = 5, ["param1"] = 56, ["z"] = 21, ["name"] = "default:wood"}, {["x"] = 5, ["y"] = 5, ["param1"] = 56, ["z"] = 22, ["name"] = "default:wood"}, {["x"] = 5, ["y"] = 5, ["param1"] = 56, ["z"] = 23, ["name"] = "default:wood"}, {["x"] = 5, ["y"] = 6, ["param1"] = 56, ["z"] = 20, ["name"] = "default:wood"}, {["x"] = 5, ["y"] = 6, ["param1"] = 56, ["z"] = 21, ["name"] = "default:wood"}, {["x"] = 5, ["y"] = 6, ["param1"] = 56, ["z"] = 22, ["name"] = "default:wood"}, {["x"] = 5, ["y"] = 6, ["param1"] = 56, ["z"] = 23, ["name"] = "default:wood"}, {["x"] = 5, ["y"] = 6, ["param1"] = 56, ["z"] = 24, ["name"] = "default:wood"}, {["x"] = 5, ["y"] = 7, ["param1"] = 56, ["z"] = 21, ["name"] = "default:wood"}, {["x"] = 5, ["y"] = 7, ["param1"] = 56, ["z"] = 22, ["name"] = "default:wood"}, {["x"] = 5, ["y"] = 7, ["param1"] = 56, ["z"] = 23, ["name"] = "default:wood"}, {["x"] = 5, ["y"] = 7, ["param1"] = 56, ["z"] = 24, ["name"] = "default:wood"}, {["x"] = 5, ["y"] = 7, ["param1"] = 56, ["z"] = 25, ["name"] = "default:wood"}, {["x"] = 5, ["y"] = 8, ["param1"] = 56, ["z"] = 22, ["name"] = "default:wood"}, {["x"] = 5, ["y"] = 8, ["param1"] = 56, ["z"] = 23, ["name"] = "default:wood"}, {["x"] = 5, ["y"] = 8, ["param1"] = 56, ["z"] = 24, ["name"] = "default:wood"}, {["x"] = 5, ["y"] = 8, ["param1"] = 56, ["z"] = 25, ["name"] = "default:wood"}, {["x"] = 5, ["y"] = 8, ["param1"] = 56, ["z"] = 26, ["name"] = "default:wood"}, {["x"] = 5, ["y"] = 9, ["param1"] = 56, ["z"] = 23, ["name"] = "default:wood"}, {["x"] = 5, ["y"] = 9, ["param1"] = 56, ["z"] = 24, ["name"] = "default:wood"}, {["x"] = 5, ["y"] = 9, ["param1"] = 56, ["z"] = 25, ["name"] = "default:wood"}, {["x"] = 5, ["y"] = 9, ["param1"] = 56, ["z"] = 26, ["name"] = "default:wood"}, {["x"] = 5, ["y"] = 9, ["param1"] = 56, ["z"] = 27, ["name"] = "default:wood"}, {["x"] = 5, ["y"] = 10, ["param1"] = 56, ["z"] = 24, ["name"] = "default:wood"}, {["x"] = 5, ["y"] = 10, ["param1"] = 56, ["z"] = 25, ["name"] = "default:wood"}, {["x"] = 5, ["y"] = 10, ["param1"] = 56, ["z"] = 26, ["name"] = "default:wood"}, {["x"] = 5, ["y"] = 10, ["param1"] = 56, ["z"] = 27, ["name"] = "default:wood"}, {["x"] = 5, ["y"] = 10, ["param1"] = 56, ["z"] = 28, ["name"] = "default:wood"}, {["x"] = 5, ["y"] = 11, ["param1"] = 56, ["z"] = 25, ["name"] = "default:wood"}, {["x"] = 5, ["y"] = 11, ["param1"] = 56, ["z"] = 26, ["name"] = "default:wood"}, {["x"] = 5, ["y"] = 11, ["param1"] = 56, ["z"] = 27, ["name"] = "default:wood"}, {["x"] = 5, ["y"] = 11, ["param1"] = 56, ["z"] = 28, ["name"] = "default:wood"}, {["x"] = 5, ["y"] = 11, ["param1"] = 56, ["z"] = 29, ["name"] = "default:wood"}, {["x"] = 5, ["y"] = 12, ["param1"] = 56, ["z"] = 26, ["name"] = "default:wood"}, {["x"] = 5, ["y"] = 12, ["param1"] = 56, ["z"] = 27, ["name"] = "default:wood"}, {["x"] = 5, ["y"] = 12, ["param1"] = 56, ["z"] = 28, ["name"] = "default:wood"}, {["x"] = 5, ["y"] = 12, ["param1"] = 56, ["z"] = 29, ["name"] = "default:wood"}, {["x"] = 5, ["y"] = 12, ["param1"] = 56, ["z"] = 30, ["name"] = "default:wood"}, {["x"] = 5, ["y"] = 13, ["param1"] = 56, ["z"] = 27, ["name"] = "default:wood"}, {["x"] = 5, ["y"] = 13, ["param1"] = 56, ["z"] = 28, ["name"] = "default:wood"}, {["x"] = 5, ["y"] = 13, ["param1"] = 56, ["z"] = 29, ["name"] = "default:wood"}, {["x"] = 5, ["y"] = 13, ["param1"] = 56, ["z"] = 30, ["name"] = "default:wood"}, {["x"] = 5, ["y"] = 13, ["param1"] = 56, ["z"] = 31, ["name"] = "default:wood"}, {["x"] = 5, ["y"] = 14, ["param1"] = 56, ["z"] = 28, ["name"] = "default:wood"}, {["x"] = 5, ["y"] = 14, ["param1"] = 56, ["z"] = 29, ["name"] = "default:wood"}, {["x"] = 5, ["y"] = 14, ["param1"] = 56, ["z"] = 30, ["name"] = "default:wood"}, {["x"] = 5, ["y"] = 14, ["param1"] = 56, ["z"] = 31, ["name"] = "default:wood"}, {["x"] = 5, ["y"] = 14, ["z"] = 32, ["name"] = "default:wood"}, {["x"] = 5, ["y"] = 15, ["param1"] = 56, ["z"] = 29, ["name"] = "default:wood"}, {["x"] = 5, ["y"] = 15, ["param1"] = 56, ["z"] = 30, ["name"] = "default:wood"}, {["x"] = 5, ["y"] = 15, ["param1"] = 56, ["z"] = 31, ["name"] = "default:wood"}, {["x"] = 5, ["y"] = 15, ["z"] = 32, ["name"] = "default:wood"}, {["x"] = 5, ["y"] = 16, ["z"] = 30, ["name"] = "default:wood"}, {["x"] = 5, ["y"] = 16, ["z"] = 31, ["name"] = "default:wood"}, {["x"] = 6, ["y"] = 0, ["param1"] = 56, ["z"] = 16, ["name"] = "default:wood"}, {["x"] = 6, ["y"] = 0, ["param1"] = 56, ["z"] = 17, ["name"] = "default:wood"}, {["x"] = 6, ["y"] = 0, ["param1"] = 56, ["z"] = 18, ["name"] = "default:wood"}, {["x"] = 6, ["y"] = 0, ["param1"] = 56, ["z"] = 19, ["name"] = "default:wood"}, {["x"] = 6, ["y"] = 0, ["param1"] = 56, ["z"] = 20, ["name"] = "default:wood"}, {["x"] = 6, ["y"] = 1, ["param1"] = 56, ["z"] = 15, ["name"] = "default:wood"}, {["x"] = 6, ["y"] = 1, ["param1"] = 56, ["z"] = 16, ["name"] = "default:wood"}, {["x"] = 6, ["y"] = 1, ["param1"] = 56, ["z"] = 17, ["name"] = "default:wood"}, {["x"] = 6, ["y"] = 1, ["param1"] = 56, ["z"] = 18, ["name"] = "default:wood"}, {["x"] = 6, ["y"] = 1, ["param1"] = 56, ["z"] = 19, ["name"] = "default:wood"}, {["x"] = 6, ["y"] = 1, ["param1"] = 56, ["z"] = 20, ["name"] = "default:wood"}, {["x"] = 6, ["y"] = 1, ["param1"] = 56, ["z"] = 21, ["name"] = "default:wood"}, {["x"] = 6, ["y"] = 2, ["param1"] = 56, ["z"] = 14, ["name"] = "default:wood"}, {["x"] = 6, ["y"] = 2, ["param1"] = 56, ["z"] = 15, ["name"] = "default:wood"}, {["x"] = 6, ["y"] = 2, ["param1"] = 56, ["z"] = 16, ["name"] = "default:wood"}, {["x"] = 6, ["y"] = 2, ["param1"] = 56, ["z"] = 17, ["name"] = "default:wood"}, {["x"] = 6, ["y"] = 2, ["param1"] = 56, ["z"] = 18, ["name"] = "default:wood"}, {["x"] = 6, ["y"] = 2, ["param1"] = 56, ["z"] = 19, ["name"] = "default:wood"}, {["x"] = 6, ["y"] = 2, ["param1"] = 56, ["z"] = 20, ["name"] = "default:wood"}, {["x"] = 6, ["y"] = 2, ["param1"] = 56, ["z"] = 21, ["name"] = "default:wood"}, {["x"] = 6, ["y"] = 2, ["param1"] = 56, ["z"] = 22, ["name"] = "default:wood"}, {["x"] = 6, ["y"] = 3, ["param1"] = 56, ["z"] = 15, ["name"] = "default:wood"}, {["x"] = 6, ["y"] = 3, ["param1"] = 56, ["z"] = 16, ["name"] = "default:wood"}, {["x"] = 6, ["y"] = 3, ["param1"] = 56, ["z"] = 17, ["name"] = "default:wood"}, {["x"] = 6, ["y"] = 3, ["param1"] = 56, ["z"] = 18, ["name"] = "default:wood"}, {["x"] = 6, ["y"] = 3, ["param1"] = 56, ["z"] = 19, ["name"] = "default:wood"}, {["x"] = 6, ["y"] = 3, ["param1"] = 56, ["z"] = 20, ["name"] = "default:wood"}, {["x"] = 6, ["y"] = 3, ["param1"] = 56, ["z"] = 21, ["name"] = "default:wood"}, {["x"] = 6, ["y"] = 3, ["param1"] = 56, ["z"] = 22, ["name"] = "default:wood"}, {["x"] = 6, ["y"] = 3, ["param1"] = 56, ["z"] = 23, ["name"] = "default:wood"}, {["x"] = 6, ["y"] = 4, ["param1"] = 56, ["z"] = 16, ["name"] = "default:wood"}, {["x"] = 6, ["y"] = 4, ["param1"] = 56, ["z"] = 17, ["name"] = "default:wood"}, {["x"] = 6, ["y"] = 4, ["param1"] = 56, ["z"] = 18, ["name"] = "default:wood"}, {["x"] = 6, ["y"] = 4, ["param1"] = 56, ["z"] = 19, ["name"] = "default:wood"}, {["x"] = 6, ["y"] = 4, ["param1"] = 56, ["z"] = 20, ["name"] = "default:wood"}, {["x"] = 6, ["y"] = 4, ["param1"] = 56, ["z"] = 21, ["name"] = "default:wood"}, {["x"] = 6, ["y"] = 4, ["param1"] = 56, ["z"] = 22, ["name"] = "default:wood"}, {["x"] = 6, ["y"] = 4, ["param1"] = 56, ["z"] = 23, ["name"] = "default:wood"}, {["x"] = 6, ["y"] = 4, ["param1"] = 56, ["z"] = 24, ["name"] = "default:wood"}, {["x"] = 6, ["y"] = 5, ["param1"] = 56, ["z"] = 17, ["name"] = "default:wood"}, {["x"] = 6, ["y"] = 5, ["param1"] = 56, ["z"] = 18, ["name"] = "default:wood"}, {["x"] = 6, ["y"] = 5, ["param1"] = 56, ["z"] = 19, ["name"] = "default:wood"}, {["x"] = 6, ["y"] = 5, ["param1"] = 56, ["z"] = 20, ["name"] = "default:wood"}, {["x"] = 6, ["y"] = 5, ["param1"] = 56, ["z"] = 21, ["name"] = "default:wood"}, {["x"] = 6, ["y"] = 5, ["param1"] = 56, ["z"] = 22, ["name"] = "default:wood"}, {["x"] = 6, ["y"] = 5, ["param1"] = 56, ["z"] = 23, ["name"] = "default:wood"}, {["x"] = 6, ["y"] = 5, ["param1"] = 56, ["z"] = 24, ["name"] = "default:wood"}, {["x"] = 6, ["y"] = 5, ["param1"] = 56, ["z"] = 25, ["name"] = "default:wood"}, {["x"] = 6, ["y"] = 6, ["param1"] = 56, ["z"] = 18, ["name"] = "default:wood"}, {["x"] = 6, ["y"] = 6, ["param1"] = 56, ["z"] = 19, ["name"] = "default:wood"}, {["x"] = 6, ["y"] = 6, ["param1"] = 56, ["z"] = 20, ["name"] = "default:wood"}, {["x"] = 6, ["y"] = 6, ["param1"] = 56, ["z"] = 21, ["name"] = "default:wood"}, {["x"] = 6, ["y"] = 6, ["param1"] = 56, ["z"] = 22, ["name"] = "default:wood"}, {["x"] = 6, ["y"] = 6, ["param1"] = 56, ["z"] = 23, ["name"] = "default:wood"}, {["x"] = 6, ["y"] = 6, ["param1"] = 56, ["z"] = 24, ["name"] = "default:wood"}, {["x"] = 6, ["y"] = 6, ["param1"] = 56, ["z"] = 25, ["name"] = "default:wood"}, {["x"] = 6, ["y"] = 6, ["param1"] = 56, ["z"] = 26, ["name"] = "default:wood"}, {["x"] = 6, ["y"] = 7, ["param1"] = 56, ["z"] = 19, ["name"] = "default:wood"}, {["x"] = 6, ["y"] = 7, ["param1"] = 56, ["z"] = 20, ["name"] = "default:wood"}, {["x"] = 6, ["y"] = 7, ["param1"] = 56, ["z"] = 21, ["name"] = "default:wood"}, {["x"] = 6, ["y"] = 7, ["param1"] = 56, ["z"] = 22, ["name"] = "default:wood"}, {["x"] = 6, ["y"] = 7, ["param1"] = 56, ["z"] = 23, ["name"] = "default:wood"}, {["x"] = 6, ["y"] = 7, ["param1"] = 56, ["z"] = 24, ["name"] = "default:wood"}, {["x"] = 6, ["y"] = 7, ["param1"] = 56, ["z"] = 25, ["name"] = "default:wood"}, {["x"] = 6, ["y"] = 7, ["param1"] = 56, ["z"] = 26, ["name"] = "default:wood"}, {["x"] = 6, ["y"] = 7, ["param1"] = 56, ["z"] = 27, ["name"] = "default:wood"}, {["x"] = 6, ["y"] = 8, ["param1"] = 56, ["z"] = 20, ["name"] = "default:wood"}, {["x"] = 6, ["y"] = 8, ["param1"] = 56, ["z"] = 21, ["name"] = "default:wood"}, {["x"] = 6, ["y"] = 8, ["param1"] = 56, ["z"] = 22, ["name"] = "default:wood"}, {["x"] = 6, ["y"] = 8, ["param1"] = 56, ["z"] = 23, ["name"] = "default:wood"}, {["x"] = 6, ["y"] = 8, ["param1"] = 56, ["z"] = 24, ["name"] = "default:wood"}, {["x"] = 6, ["y"] = 8, ["param1"] = 56, ["z"] = 25, ["name"] = "default:wood"}, {["x"] = 6, ["y"] = 8, ["param1"] = 56, ["z"] = 26, ["name"] = "default:wood"}, {["x"] = 6, ["y"] = 8, ["param1"] = 56, ["z"] = 27, ["name"] = "default:wood"}, {["x"] = 6, ["y"] = 8, ["param1"] = 56, ["z"] = 28, ["name"] = "default:wood"}, {["x"] = 6, ["y"] = 9, ["param1"] = 56, ["z"] = 21, ["name"] = "default:wood"}, {["x"] = 6, ["y"] = 9, ["param1"] = 56, ["z"] = 22, ["name"] = "default:wood"}, {["x"] = 6, ["y"] = 9, ["param1"] = 56, ["z"] = 23, ["name"] = "default:wood"}, {["x"] = 6, ["y"] = 9, ["param1"] = 56, ["z"] = 24, ["name"] = "default:wood"}, {["x"] = 6, ["y"] = 9, ["param1"] = 56, ["z"] = 25, ["name"] = "default:wood"}, {["x"] = 6, ["y"] = 9, ["param1"] = 56, ["z"] = 26, ["name"] = "default:wood"}, {["x"] = 6, ["y"] = 9, ["param1"] = 56, ["z"] = 27, ["name"] = "default:wood"}, {["x"] = 6, ["y"] = 9, ["param1"] = 56, ["z"] = 28, ["name"] = "default:wood"}, {["x"] = 6, ["y"] = 9, ["param1"] = 56, ["z"] = 29, ["name"] = "default:wood"}, {["x"] = 6, ["y"] = 10, ["param1"] = 56, ["z"] = 22, ["name"] = "default:wood"}, {["x"] = 6, ["y"] = 10, ["param1"] = 56, ["z"] = 23, ["name"] = "default:wood"}, {["x"] = 6, ["y"] = 10, ["param1"] = 56, ["z"] = 24, ["name"] = "default:wood"}, {["x"] = 6, ["y"] = 10, ["param1"] = 56, ["z"] = 25, ["name"] = "default:wood"}, {["x"] = 6, ["y"] = 10, ["param1"] = 56, ["z"] = 26, ["name"] = "default:wood"}, {["x"] = 6, ["y"] = 10, ["param1"] = 56, ["z"] = 27, ["name"] = "default:wood"}, {["x"] = 6, ["y"] = 10, ["param1"] = 56, ["z"] = 28, ["name"] = "default:wood"}, {["x"] = 6, ["y"] = 10, ["param1"] = 56, ["z"] = 29, ["name"] = "default:wood"}, {["x"] = 6, ["y"] = 10, ["param1"] = 56, ["z"] = 30, ["name"] = "default:wood"}, {["x"] = 6, ["y"] = 11, ["param1"] = 56, ["z"] = 23, ["name"] = "default:wood"}, {["x"] = 6, ["y"] = 11, ["param1"] = 56, ["z"] = 24, ["name"] = "default:wood"}, {["x"] = 6, ["y"] = 11, ["param1"] = 56, ["z"] = 25, ["name"] = "default:wood"}, {["x"] = 6, ["y"] = 11, ["param1"] = 56, ["z"] = 26, ["name"] = "default:wood"}, {["x"] = 6, ["y"] = 11, ["param1"] = 56, ["z"] = 27, ["name"] = "default:wood"}, {["x"] = 6, ["y"] = 11, ["param1"] = 56, ["z"] = 28, ["name"] = "default:wood"}, {["x"] = 6, ["y"] = 11, ["param1"] = 56, ["z"] = 29, ["name"] = "default:wood"}, {["x"] = 6, ["y"] = 11, ["param1"] = 56, ["z"] = 30, ["name"] = "default:wood"}, {["x"] = 6, ["y"] = 11, ["param1"] = 56, ["z"] = 31, ["name"] = "default:wood"}, {["x"] = 6, ["y"] = 12, ["param1"] = 56, ["z"] = 24, ["name"] = "default:wood"}, {["x"] = 6, ["y"] = 12, ["param1"] = 56, ["z"] = 25, ["name"] = "default:wood"}, {["x"] = 6, ["y"] = 12, ["param1"] = 56, ["z"] = 26, ["name"] = "default:wood"}, {["x"] = 6, ["y"] = 12, ["param1"] = 56, ["z"] = 27, ["name"] = "default:wood"}, {["x"] = 6, ["y"] = 12, ["param1"] = 56, ["z"] = 28, ["name"] = "default:wood"}, {["x"] = 6, ["y"] = 12, ["param1"] = 56, ["z"] = 29, ["name"] = "default:wood"}, {["x"] = 6, ["y"] = 12, ["param1"] = 56, ["z"] = 30, ["name"] = "default:wood"}, {["x"] = 6, ["y"] = 12, ["param1"] = 56, ["z"] = 31, ["name"] = "default:wood"}, {["x"] = 6, ["y"] = 12, ["z"] = 32, ["name"] = "default:wood"}, {["x"] = 6, ["y"] = 13, ["param1"] = 56, ["z"] = 25, ["name"] = "default:wood"}, {["x"] = 6, ["y"] = 13, ["param1"] = 56, ["z"] = 26, ["name"] = "default:wood"}, {["x"] = 6, ["y"] = 13, ["param1"] = 56, ["z"] = 27, ["name"] = "default:wood"}, {["x"] = 6, ["y"] = 13, ["param1"] = 56, ["z"] = 28, ["name"] = "default:wood"}, {["x"] = 6, ["y"] = 13, ["param1"] = 56, ["z"] = 29, ["name"] = "default:wood"}, {["x"] = 6, ["y"] = 13, ["param1"] = 56, ["z"] = 30, ["name"] = "default:wood"}, {["x"] = 6, ["y"] = 13, ["param1"] = 56, ["z"] = 31, ["name"] = "default:wood"}, {["x"] = 6, ["y"] = 13, ["z"] = 32, ["name"] = "default:wood"}, {["x"] = 6, ["y"] = 13, ["z"] = 33, ["name"] = "default:wood"}, {["x"] = 6, ["y"] = 14, ["param1"] = 56, ["z"] = 26, ["name"] = "default:wood"}, {["x"] = 6, ["y"] = 14, ["param1"] = 56, ["z"] = 27, ["name"] = "default:wood"}, {["x"] = 6, ["y"] = 14, ["param1"] = 56, ["z"] = 28, ["name"] = "default:wood"}, {["x"] = 6, ["y"] = 14, ["param1"] = 56, ["z"] = 29, ["name"] = "default:wood"}, {["x"] = 6, ["y"] = 14, ["param1"] = 56, ["z"] = 30, ["name"] = "default:wood"}, {["x"] = 6, ["y"] = 14, ["param1"] = 56, ["z"] = 31, ["name"] = "default:wood"}, {["x"] = 6, ["y"] = 14, ["z"] = 32, ["name"] = "default:wood"}, {["x"] = 6, ["y"] = 14, ["z"] = 33, ["name"] = "default:wood"}, {["x"] = 6, ["y"] = 15, ["param1"] = 56, ["z"] = 27, ["name"] = "default:wood"}, {["x"] = 6, ["y"] = 15, ["param1"] = 56, ["z"] = 28, ["name"] = "default:wood"}, {["x"] = 6, ["y"] = 15, ["param1"] = 56, ["z"] = 29, ["name"] = "default:wood"}, {["x"] = 6, ["y"] = 15, ["param1"] = 56, ["z"] = 30, ["name"] = "default:wood"}, {["x"] = 6, ["y"] = 15, ["param1"] = 56, ["z"] = 31, ["name"] = "default:wood"}, {["x"] = 6, ["y"] = 15, ["z"] = 32, ["name"] = "default:wood"}, {["x"] = 6, ["y"] = 16, ["z"] = 28, ["name"] = "default:wood"}, {["x"] = 6, ["y"] = 16, ["z"] = 29, ["name"] = "default:wood"}, {["x"] = 6, ["y"] = 16, ["z"] = 30, ["name"] = "default:wood"}, {["x"] = 6, ["y"] = 16, ["z"] = 31, ["name"] = "default:wood"}, {["x"] = 6, ["y"] = 17, ["z"] = 29, ["name"] = "default:wood"}, {["x"] = 6, ["y"] = 17, ["z"] = 30, ["name"] = "default:wood"}, {["x"] = 7, ["y"] = 0, ["param1"] = 56, ["z"] = 16, ["name"] = "default:wood"}, {["x"] = 7, ["y"] = 0, ["param1"] = 56, ["z"] = 17, ["name"] = "default:wood"}, {["x"] = 7, ["y"] = 0, ["param1"] = 56, ["z"] = 18, ["name"] = "default:wood"}, {["x"] = 7, ["y"] = 0, ["param1"] = 56, ["z"] = 19, ["name"] = "default:wood"}, {["x"] = 7, ["y"] = 0, ["param1"] = 56, ["z"] = 20, ["name"] = "default:wood"}, {["x"] = 7, ["y"] = 0, ["param1"] = 56, ["z"] = 21, ["name"] = "default:wood"}, {["x"] = 7, ["y"] = 0, ["param1"] = 56, ["z"] = 22, ["name"] = "default:wood"}, {["x"] = 7, ["y"] = 1, ["param1"] = 56, ["z"] = 15, ["name"] = "default:wood"}, {["x"] = 7, ["y"] = 1, ["param1"] = 56, ["z"] = 16, ["name"] = "default:wood"}, {["x"] = 7, ["y"] = 1, ["param1"] = 56, ["z"] = 17, ["name"] = "default:wood"}, {["x"] = 7, ["y"] = 1, ["param1"] = 56, ["z"] = 18, ["name"] = "default:wood"}, {["x"] = 7, ["y"] = 1, ["param1"] = 56, ["z"] = 19, ["name"] = "default:wood"}, {["x"] = 7, ["y"] = 1, ["param1"] = 56, ["z"] = 20, ["name"] = "default:wood"}, {["x"] = 7, ["y"] = 1, ["param1"] = 56, ["z"] = 21, ["name"] = "default:wood"}, {["x"] = 7, ["y"] = 1, ["param1"] = 56, ["z"] = 22, ["name"] = "default:wood"}, {["x"] = 7, ["y"] = 1, ["param1"] = 56, ["z"] = 23, ["name"] = "default:wood"}, {["x"] = 7, ["y"] = 2, ["param1"] = 56, ["z"] = 14, ["name"] = "default:wood"}, {["x"] = 7, ["y"] = 2, ["param1"] = 56, ["z"] = 15, ["name"] = "default:wood"}, {["x"] = 7, ["y"] = 2, ["param1"] = 56, ["z"] = 16, ["name"] = "default:wood"}, {["x"] = 7, ["y"] = 2, ["param1"] = 56, ["z"] = 17, ["name"] = "default:wood"}, {["x"] = 7, ["y"] = 2, ["param1"] = 56, ["z"] = 18, ["name"] = "default:wood"}, {["x"] = 7, ["y"] = 2, ["param1"] = 56, ["z"] = 19, ["name"] = "default:wood"}, {["x"] = 7, ["y"] = 2, ["param1"] = 56, ["z"] = 20, ["name"] = "default:wood"}, {["x"] = 7, ["y"] = 2, ["param1"] = 56, ["z"] = 21, ["name"] = "default:wood"}, {["x"] = 7, ["y"] = 2, ["param1"] = 56, ["z"] = 22, ["name"] = "default:wood"}, {["x"] = 7, ["y"] = 2, ["param1"] = 56, ["z"] = 23, ["name"] = "default:wood"}, {["x"] = 7, ["y"] = 2, ["param1"] = 56, ["z"] = 24, ["name"] = "default:wood"}, {["x"] = 7, ["y"] = 3, ["param1"] = 56, ["z"] = 13, ["name"] = "default:wood"}, {["x"] = 7, ["y"] = 3, ["param1"] = 56, ["z"] = 14, ["name"] = "default:wood"}, {["x"] = 7, ["y"] = 3, ["param1"] = 56, ["z"] = 15, ["name"] = "default:wood"}, {["x"] = 7, ["y"] = 3, ["param1"] = 56, ["z"] = 16, ["name"] = "default:wood"}, {["x"] = 7, ["y"] = 3, ["param1"] = 56, ["z"] = 17, ["name"] = "default:wood"}, {["x"] = 7, ["y"] = 3, ["param1"] = 56, ["z"] = 18, ["name"] = "default:wood"}, {["x"] = 7, ["y"] = 3, ["param1"] = 56, ["z"] = 19, ["name"] = "default:wood"}, {["x"] = 7, ["y"] = 3, ["param1"] = 56, ["z"] = 20, ["name"] = "default:wood"}, {["x"] = 7, ["y"] = 3, ["param1"] = 56, ["z"] = 21, ["name"] = "default:wood"}, {["x"] = 7, ["y"] = 3, ["param1"] = 56, ["z"] = 22, ["name"] = "default:wood"}, {["x"] = 7, ["y"] = 3, ["param1"] = 56, ["z"] = 23, ["name"] = "default:wood"}, {["x"] = 7, ["y"] = 3, ["param1"] = 56, ["z"] = 24, ["name"] = "default:wood"}, {["x"] = 7, ["y"] = 3, ["param1"] = 56, ["z"] = 25, ["name"] = "default:wood"}, {["x"] = 7, ["y"] = 4, ["param1"] = 56, ["z"] = 14, ["name"] = "default:wood"}, {["x"] = 7, ["y"] = 4, ["param1"] = 56, ["z"] = 15, ["name"] = "default:wood"}, {["x"] = 7, ["y"] = 4, ["param1"] = 56, ["z"] = 16, ["name"] = "default:wood"}, {["x"] = 7, ["y"] = 4, ["param1"] = 56, ["z"] = 17, ["name"] = "default:wood"}, {["x"] = 7, ["y"] = 4, ["param1"] = 56, ["z"] = 18, ["name"] = "default:wood"}, {["x"] = 7, ["y"] = 4, ["param1"] = 56, ["z"] = 19, ["name"] = "default:wood"}, {["x"] = 7, ["y"] = 4, ["param1"] = 56, ["z"] = 20, ["name"] = "default:wood"}, {["x"] = 7, ["y"] = 4, ["param1"] = 56, ["z"] = 21, ["name"] = "default:wood"}, {["x"] = 7, ["y"] = 4, ["param1"] = 56, ["z"] = 22, ["name"] = "default:wood"}, {["x"] = 7, ["y"] = 4, ["param1"] = 56, ["z"] = 23, ["name"] = "default:wood"}, {["x"] = 7, ["y"] = 4, ["param1"] = 56, ["z"] = 24, ["name"] = "default:wood"}, {["x"] = 7, ["y"] = 4, ["param1"] = 56, ["z"] = 25, ["name"] = "default:wood"}, {["x"] = 7, ["y"] = 4, ["param1"] = 56, ["z"] = 26, ["name"] = "default:wood"}, {["x"] = 7, ["y"] = 5, ["param1"] = 56, ["z"] = 15, ["name"] = "default:wood"}, {["x"] = 7, ["y"] = 5, ["param1"] = 56, ["z"] = 16, ["name"] = "default:wood"}, {["x"] = 7, ["y"] = 5, ["param1"] = 56, ["z"] = 17, ["name"] = "default:wood"}, {["x"] = 7, ["y"] = 5, ["param1"] = 56, ["z"] = 18, ["name"] = "default:wood"}, {["x"] = 7, ["y"] = 5, ["param1"] = 56, ["z"] = 19, ["name"] = "default:wood"}, {["x"] = 7, ["y"] = 5, ["param1"] = 56, ["z"] = 20, ["name"] = "default:wood"}, {["x"] = 7, ["y"] = 5, ["param1"] = 56, ["z"] = 21, ["name"] = "default:wood"}, {["x"] = 7, ["y"] = 5, ["param1"] = 56, ["z"] = 22, ["name"] = "default:wood"}, {["x"] = 7, ["y"] = 5, ["param1"] = 56, ["z"] = 23, ["name"] = "default:wood"}, {["x"] = 7, ["y"] = 5, ["param1"] = 56, ["z"] = 24, ["name"] = "default:wood"}, {["x"] = 7, ["y"] = 5, ["param1"] = 56, ["z"] = 25, ["name"] = "default:wood"}, {["x"] = 7, ["y"] = 5, ["param1"] = 56, ["z"] = 26, ["name"] = "default:wood"}, {["x"] = 7, ["y"] = 5, ["param1"] = 56, ["z"] = 27, ["name"] = "default:wood"}, {["x"] = 7, ["y"] = 6, ["param1"] = 56, ["z"] = 16, ["name"] = "default:wood"}, {["x"] = 7, ["y"] = 6, ["param1"] = 56, ["z"] = 17, ["name"] = "default:wood"}, {["x"] = 7, ["y"] = 6, ["param1"] = 56, ["z"] = 18, ["name"] = "default:wood"}, {["x"] = 7, ["y"] = 6, ["param1"] = 56, ["z"] = 19, ["name"] = "default:wood"}, {["x"] = 7, ["y"] = 6, ["param1"] = 56, ["z"] = 20, ["name"] = "default:wood"}, {["x"] = 7, ["y"] = 6, ["param1"] = 56, ["z"] = 21, ["name"] = "default:wood"}, {["x"] = 7, ["y"] = 6, ["param1"] = 56, ["z"] = 22, ["name"] = "default:wood"}, {["x"] = 7, ["y"] = 6, ["param1"] = 56, ["z"] = 23, ["name"] = "default:wood"}, {["x"] = 7, ["y"] = 6, ["param1"] = 56, ["z"] = 24, ["name"] = "default:wood"}, {["x"] = 7, ["y"] = 6, ["param1"] = 56, ["z"] = 25, ["name"] = "default:wood"}, {["x"] = 7, ["y"] = 6, ["param1"] = 56, ["z"] = 26, ["name"] = "default:wood"}, {["x"] = 7, ["y"] = 6, ["param1"] = 56, ["z"] = 27, ["name"] = "default:wood"}, {["x"] = 7, ["y"] = 6, ["param1"] = 56, ["z"] = 28, ["name"] = "default:wood"}, {["x"] = 7, ["y"] = 7, ["param1"] = 56, ["z"] = 17, ["name"] = "default:wood"}, {["x"] = 7, ["y"] = 7, ["param1"] = 56, ["z"] = 18, ["name"] = "default:wood"}, {["x"] = 7, ["y"] = 7, ["param1"] = 56, ["z"] = 19, ["name"] = "default:wood"}, {["x"] = 7, ["y"] = 7, ["param1"] = 56, ["z"] = 20, ["name"] = "default:wood"}, {["x"] = 7, ["y"] = 7, ["param1"] = 56, ["z"] = 21, ["name"] = "default:wood"}, {["x"] = 7, ["y"] = 7, ["param1"] = 56, ["z"] = 22, ["name"] = "default:wood"}, {["x"] = 7, ["y"] = 7, ["param1"] = 56, ["z"] = 23, ["name"] = "default:wood"}, {["x"] = 7, ["y"] = 7, ["param1"] = 56, ["z"] = 24, ["name"] = "default:wood"}, {["x"] = 7, ["y"] = 7, ["param1"] = 56, ["z"] = 25, ["name"] = "default:wood"}, {["x"] = 7, ["y"] = 7, ["param1"] = 56, ["z"] = 26, ["name"] = "default:wood"}, {["x"] = 7, ["y"] = 7, ["param1"] = 56, ["z"] = 27, ["name"] = "default:wood"}, {["x"] = 7, ["y"] = 7, ["param1"] = 56, ["z"] = 28, ["name"] = "default:wood"}, {["x"] = 7, ["y"] = 7, ["param1"] = 56, ["z"] = 29, ["name"] = "default:wood"}, {["x"] = 7, ["y"] = 8, ["param1"] = 56, ["z"] = 18, ["name"] = "default:wood"}, {["x"] = 7, ["y"] = 8, ["param1"] = 56, ["z"] = 19, ["name"] = "default:wood"}, {["x"] = 7, ["y"] = 8, ["param1"] = 56, ["z"] = 20, ["name"] = "default:wood"}, {["x"] = 7, ["y"] = 8, ["param1"] = 56, ["z"] = 21, ["name"] = "default:wood"}, {["x"] = 7, ["y"] = 8, ["param1"] = 56, ["z"] = 22, ["name"] = "default:wood"}, {["x"] = 7, ["y"] = 8, ["param1"] = 56, ["z"] = 23, ["name"] = "default:wood"}, {["x"] = 7, ["y"] = 8, ["param1"] = 56, ["z"] = 24, ["name"] = "default:wood"}, {["x"] = 7, ["y"] = 8, ["param1"] = 56, ["z"] = 25, ["name"] = "default:wood"}, {["x"] = 7, ["y"] = 8, ["param1"] = 56, ["z"] = 26, ["name"] = "default:wood"}, {["x"] = 7, ["y"] = 8, ["param1"] = 56, ["z"] = 27, ["name"] = "default:wood"}, {["x"] = 7, ["y"] = 8, ["param1"] = 56, ["z"] = 28, ["name"] = "default:wood"}, {["x"] = 7, ["y"] = 8, ["param1"] = 56, ["z"] = 29, ["name"] = "default:wood"}, {["x"] = 7, ["y"] = 8, ["param1"] = 56, ["z"] = 30, ["name"] = "default:wood"}, {["x"] = 7, ["y"] = 9, ["param1"] = 56, ["z"] = 19, ["name"] = "default:wood"}, {["x"] = 7, ["y"] = 9, ["param1"] = 56, ["z"] = 20, ["name"] = "default:wood"}, {["x"] = 7, ["y"] = 9, ["param1"] = 56, ["z"] = 21, ["name"] = "default:wood"}, {["x"] = 7, ["y"] = 9, ["param1"] = 56, ["z"] = 22, ["name"] = "default:wood"}, {["x"] = 7, ["y"] = 9, ["param1"] = 56, ["z"] = 23, ["name"] = "default:wood"}, {["x"] = 7, ["y"] = 9, ["param1"] = 56, ["z"] = 24, ["name"] = "default:wood"}, {["x"] = 7, ["y"] = 9, ["param1"] = 56, ["z"] = 25, ["name"] = "default:wood"}, {["x"] = 7, ["y"] = 9, ["param1"] = 56, ["z"] = 26, ["name"] = "default:wood"}, {["x"] = 7, ["y"] = 9, ["param1"] = 56, ["z"] = 27, ["name"] = "default:wood"}, {["x"] = 7, ["y"] = 9, ["param1"] = 56, ["z"] = 28, ["name"] = "default:wood"}, {["x"] = 7, ["y"] = 9, ["param1"] = 56, ["z"] = 29, ["name"] = "default:wood"}, {["x"] = 7, ["y"] = 9, ["param1"] = 56, ["z"] = 30, ["name"] = "default:wood"}, {["x"] = 7, ["y"] = 9, ["param1"] = 56, ["z"] = 31, ["name"] = "default:wood"}, {["x"] = 7, ["y"] = 10, ["param1"] = 56, ["z"] = 20, ["name"] = "default:wood"}, {["x"] = 7, ["y"] = 10, ["param1"] = 56, ["z"] = 21, ["name"] = "default:wood"}, {["x"] = 7, ["y"] = 10, ["param1"] = 56, ["z"] = 22, ["name"] = "default:wood"}, {["x"] = 7, ["y"] = 10, ["param1"] = 56, ["z"] = 23, ["name"] = "default:wood"}, {["x"] = 7, ["y"] = 10, ["param1"] = 56, ["z"] = 24, ["name"] = "default:wood"}, {["x"] = 7, ["y"] = 10, ["param1"] = 56, ["z"] = 25, ["name"] = "default:wood"}, {["x"] = 7, ["y"] = 10, ["param1"] = 56, ["z"] = 26, ["name"] = "default:wood"}, {["x"] = 7, ["y"] = 10, ["param1"] = 56, ["z"] = 27, ["name"] = "default:wood"}, {["x"] = 7, ["y"] = 10, ["param1"] = 56, ["z"] = 28, ["name"] = "default:wood"}, {["x"] = 7, ["y"] = 10, ["param1"] = 56, ["z"] = 29, ["name"] = "default:wood"}, {["x"] = 7, ["y"] = 10, ["param1"] = 56, ["z"] = 30, ["name"] = "default:wood"}, {["x"] = 7, ["y"] = 10, ["param1"] = 56, ["z"] = 31, ["name"] = "default:wood"}, {["x"] = 7, ["y"] = 10, ["z"] = 32, ["name"] = "default:wood"}, {["x"] = 7, ["y"] = 11, ["param1"] = 56, ["z"] = 21, ["name"] = "default:wood"}, {["x"] = 7, ["y"] = 11, ["param1"] = 56, ["z"] = 22, ["name"] = "default:wood"}, {["x"] = 7, ["y"] = 11, ["param1"] = 56, ["z"] = 23, ["name"] = "default:wood"}, {["x"] = 7, ["y"] = 11, ["param1"] = 56, ["z"] = 24, ["name"] = "default:wood"}, {["x"] = 7, ["y"] = 11, ["param1"] = 56, ["z"] = 25, ["name"] = "default:wood"}, {["x"] = 7, ["y"] = 11, ["param1"] = 56, ["z"] = 26, ["name"] = "default:wood"}, {["x"] = 7, ["y"] = 11, ["param1"] = 56, ["z"] = 27, ["name"] = "default:wood"}, {["x"] = 7, ["y"] = 11, ["param1"] = 56, ["z"] = 28, ["name"] = "default:wood"}, {["x"] = 7, ["y"] = 11, ["param1"] = 56, ["z"] = 29, ["name"] = "default:wood"}, {["x"] = 7, ["y"] = 11, ["param1"] = 56, ["z"] = 30, ["name"] = "default:wood"}, {["x"] = 7, ["y"] = 11, ["param1"] = 56, ["z"] = 31, ["name"] = "default:wood"}, {["x"] = 7, ["y"] = 11, ["z"] = 32, ["name"] = "default:wood"}, {["x"] = 7, ["y"] = 11, ["z"] = 33, ["name"] = "default:wood"}, {["x"] = 7, ["y"] = 12, ["param1"] = 56, ["z"] = 22, ["name"] = "default:wood"}, {["x"] = 7, ["y"] = 12, ["param1"] = 56, ["z"] = 23, ["name"] = "default:wood"}, {["x"] = 7, ["y"] = 12, ["param1"] = 56, ["z"] = 24, ["name"] = "default:wood"}, {["x"] = 7, ["y"] = 12, ["param1"] = 56, ["z"] = 25, ["name"] = "default:wood"}, {["x"] = 7, ["y"] = 12, ["param1"] = 56, ["z"] = 26, ["name"] = "default:wood"}, {["x"] = 7, ["y"] = 12, ["param1"] = 56, ["z"] = 27, ["name"] = "default:wood"}, {["x"] = 7, ["y"] = 12, ["param1"] = 56, ["z"] = 28, ["name"] = "default:wood"}, {["x"] = 7, ["y"] = 12, ["param1"] = 56, ["z"] = 29, ["name"] = "default:wood"}, {["x"] = 7, ["y"] = 12, ["param1"] = 56, ["z"] = 30, ["name"] = "default:wood"}, {["x"] = 7, ["y"] = 12, ["param1"] = 56, ["z"] = 31, ["name"] = "default:wood"}, {["x"] = 7, ["y"] = 12, ["z"] = 32, ["name"] = "default:wood"}, {["x"] = 7, ["y"] = 12, ["z"] = 33, ["name"] = "default:wood"}, {["x"] = 7, ["y"] = 12, ["z"] = 34, ["name"] = "default:wood"}, {["x"] = 7, ["y"] = 13, ["param1"] = 56, ["z"] = 23, ["name"] = "default:wood"}, {["x"] = 7, ["y"] = 13, ["param1"] = 56, ["z"] = 24, ["name"] = "default:wood"}, {["x"] = 7, ["y"] = 13, ["param1"] = 56, ["z"] = 25, ["name"] = "default:wood"}, {["x"] = 7, ["y"] = 13, ["param1"] = 56, ["z"] = 26, ["name"] = "default:wood"}, {["x"] = 7, ["y"] = 13, ["param1"] = 56, ["z"] = 27, ["name"] = "default:wood"}, {["x"] = 7, ["y"] = 13, ["param1"] = 56, ["z"] = 28, ["name"] = "default:wood"}, {["x"] = 7, ["y"] = 13, ["param1"] = 56, ["z"] = 29, ["name"] = "default:wood"}, {["x"] = 7, ["y"] = 13, ["param1"] = 56, ["z"] = 30, ["name"] = "default:wood"}, {["x"] = 7, ["y"] = 13, ["param1"] = 56, ["z"] = 31, ["name"] = "default:wood"}, {["x"] = 7, ["y"] = 13, ["z"] = 32, ["name"] = "default:wood"}, {["x"] = 7, ["y"] = 13, ["z"] = 33, ["name"] = "default:wood"}, {["x"] = 7, ["y"] = 13, ["z"] = 34, ["name"] = "default:wood"}, {["x"] = 7, ["y"] = 14, ["param1"] = 56, ["z"] = 24, ["name"] = "default:wood"}, {["x"] = 7, ["y"] = 14, ["param1"] = 56, ["z"] = 25, ["name"] = "default:wood"}, {["x"] = 7, ["y"] = 14, ["param1"] = 56, ["z"] = 26, ["name"] = "default:wood"}, {["x"] = 7, ["y"] = 14, ["param1"] = 56, ["z"] = 27, ["name"] = "default:wood"}, {["x"] = 7, ["y"] = 14, ["param1"] = 56, ["z"] = 28, ["name"] = "default:wood"}, {["x"] = 7, ["y"] = 14, ["param1"] = 56, ["z"] = 29, ["name"] = "default:wood"}, {["x"] = 7, ["y"] = 14, ["param1"] = 56, ["z"] = 30, ["name"] = "default:wood"}, {["x"] = 7, ["y"] = 14, ["param1"] = 56, ["z"] = 31, ["name"] = "default:wood"}, {["x"] = 7, ["y"] = 14, ["z"] = 32, ["name"] = "default:wood"}, {["x"] = 7, ["y"] = 14, ["z"] = 33, ["name"] = "default:wood"}, {["x"] = 7, ["y"] = 15, ["param1"] = 56, ["z"] = 25, ["name"] = "default:wood"}, {["x"] = 7, ["y"] = 15, ["param1"] = 56, ["z"] = 26, ["name"] = "default:wood"}, {["x"] = 7, ["y"] = 15, ["param1"] = 56, ["z"] = 27, ["name"] = "default:wood"}, {["x"] = 7, ["y"] = 15, ["param1"] = 56, ["z"] = 28, ["name"] = "default:wood"}, {["x"] = 7, ["y"] = 15, ["param1"] = 56, ["z"] = 29, ["name"] = "default:wood"}, {["x"] = 7, ["y"] = 15, ["param1"] = 56, ["z"] = 30, ["name"] = "default:wood"}, {["x"] = 7, ["y"] = 15, ["param1"] = 56, ["z"] = 31, ["name"] = "default:wood"}, {["x"] = 7, ["y"] = 15, ["z"] = 32, ["name"] = "default:wood"}, {["x"] = 7, ["y"] = 16, ["z"] = 26, ["name"] = "default:wood"}, {["x"] = 7, ["y"] = 16, ["z"] = 27, ["name"] = "default:wood"}, {["x"] = 7, ["y"] = 16, ["z"] = 28, ["name"] = "default:wood"}, {["x"] = 7, ["y"] = 16, ["z"] = 29, ["name"] = "default:wood"}, {["x"] = 7, ["y"] = 16, ["z"] = 30, ["name"] = "default:wood"}, {["x"] = 7, ["y"] = 16, ["z"] = 31, ["name"] = "default:wood"}, {["x"] = 7, ["y"] = 17, ["z"] = 27, ["name"] = "default:wood"}, {["x"] = 7, ["y"] = 17, ["z"] = 28, ["name"] = "default:wood"}, {["x"] = 7, ["y"] = 17, ["z"] = 29, ["name"] = "default:wood"}, {["x"] = 7, ["y"] = 17, ["z"] = 30, ["name"] = "default:wood"}, {["x"] = 7, ["y"] = 18, ["z"] = 28, ["name"] = "default:wood"}, {["x"] = 7, ["y"] = 18, ["z"] = 29, ["name"] = "default:wood"}, {["x"] = 8, ["y"] = 0, ["param1"] = 56, ["z"] = 16, ["name"] = "default:wood"}, {["x"] = 8, ["y"] = 0, ["param1"] = 56, ["z"] = 17, ["name"] = "default:wood"}, {["x"] = 8, ["y"] = 0, ["param1"] = 56, ["z"] = 18, ["name"] = "default:wood"}, {["x"] = 8, ["y"] = 0, ["param1"] = 56, ["z"] = 19, ["name"] = "default:wood"}, {["x"] = 8, ["y"] = 0, ["param1"] = 56, ["z"] = 20, ["name"] = "default:wood"}, {["x"] = 8, ["y"] = 0, ["param1"] = 56, ["z"] = 21, ["name"] = "default:wood"}, {["x"] = 8, ["y"] = 0, ["param1"] = 56, ["z"] = 22, ["name"] = "default:wood"}, {["x"] = 8, ["y"] = 1, ["param1"] = 56, ["z"] = 15, ["name"] = "default:wood"}, {["x"] = 8, ["y"] = 1, ["param1"] = 56, ["z"] = 16, ["name"] = "default:wood"}, {["x"] = 8, ["y"] = 1, ["param1"] = 56, ["z"] = 17, ["name"] = "default:wood"}, {["x"] = 8, ["y"] = 1, ["param1"] = 56, ["z"] = 18, ["name"] = "default:wood"}, {["x"] = 8, ["y"] = 1, ["param1"] = 56, ["z"] = 19, ["name"] = "default:wood"}, {["x"] = 8, ["y"] = 1, ["param1"] = 56, ["z"] = 20, ["name"] = "default:wood"}, {["x"] = 8, ["y"] = 1, ["param1"] = 56, ["z"] = 21, ["name"] = "default:wood"}, {["x"] = 8, ["y"] = 1, ["param1"] = 56, ["z"] = 22, ["name"] = "default:wood"}, {["x"] = 8, ["y"] = 1, ["param1"] = 56, ["z"] = 23, ["name"] = "default:wood"}, {["x"] = 8, ["y"] = 2, ["param1"] = 56, ["z"] = 14, ["name"] = "default:wood"}, {["x"] = 8, ["y"] = 2, ["param1"] = 56, ["z"] = 15, ["name"] = "default:wood"}, {["x"] = 8, ["y"] = 2, ["param1"] = 56, ["z"] = 16, ["name"] = "default:wood"}, {["x"] = 8, ["y"] = 2, ["param1"] = 56, ["z"] = 17, ["name"] = "default:wood"}, {["x"] = 8, ["y"] = 2, ["param1"] = 56, ["z"] = 18, ["name"] = "default:wood"}, {["x"] = 8, ["y"] = 2, ["param1"] = 56, ["z"] = 19, ["name"] = "default:wood"}, {["x"] = 8, ["y"] = 2, ["param1"] = 56, ["z"] = 20, ["name"] = "default:wood"}, {["x"] = 8, ["y"] = 2, ["param1"] = 56, ["z"] = 21, ["name"] = "default:wood"}, {["x"] = 8, ["y"] = 2, ["param1"] = 56, ["z"] = 22, ["name"] = "default:wood"}, {["x"] = 8, ["y"] = 2, ["param1"] = 56, ["z"] = 23, ["name"] = "default:wood"}, {["x"] = 8, ["y"] = 2, ["param1"] = 56, ["z"] = 24, ["name"] = "default:wood"}, {["x"] = 8, ["y"] = 3, ["param1"] = 56, ["z"] = 13, ["name"] = "default:wood"}, {["x"] = 8, ["y"] = 3, ["param1"] = 56, ["z"] = 14, ["name"] = "default:wood"}, {["x"] = 8, ["y"] = 3, ["param1"] = 56, ["z"] = 15, ["name"] = "default:wood"}, {["x"] = 8, ["y"] = 3, ["param1"] = 56, ["z"] = 16, ["name"] = "default:wood"}, {["x"] = 8, ["y"] = 3, ["param1"] = 56, ["z"] = 17, ["name"] = "default:wood"}, {["x"] = 8, ["y"] = 3, ["param1"] = 56, ["z"] = 18, ["name"] = "default:wood"}, {["x"] = 8, ["y"] = 3, ["param1"] = 56, ["z"] = 19, ["name"] = "default:wood"}, {["x"] = 8, ["y"] = 3, ["param1"] = 56, ["z"] = 20, ["name"] = "default:wood"}, {["x"] = 8, ["y"] = 3, ["param1"] = 56, ["z"] = 21, ["name"] = "default:wood"}, {["x"] = 8, ["y"] = 3, ["param1"] = 56, ["z"] = 22, ["name"] = "default:wood"}, {["x"] = 8, ["y"] = 3, ["param1"] = 56, ["z"] = 23, ["name"] = "default:wood"}, {["x"] = 8, ["y"] = 3, ["param1"] = 56, ["z"] = 24, ["name"] = "default:wood"}, {["x"] = 8, ["y"] = 3, ["param1"] = 56, ["z"] = 25, ["name"] = "default:wood"}, {["x"] = 8, ["y"] = 4, ["param1"] = 56, ["z"] = 14, ["name"] = "default:wood"}, {["x"] = 8, ["y"] = 4, ["param1"] = 56, ["z"] = 15, ["name"] = "default:wood"}, {["x"] = 8, ["y"] = 4, ["param1"] = 56, ["z"] = 16, ["name"] = "default:wood"}, {["x"] = 8, ["y"] = 4, ["param1"] = 56, ["z"] = 17, ["name"] = "default:wood"}, {["x"] = 8, ["y"] = 4, ["param1"] = 56, ["z"] = 18, ["name"] = "default:wood"}, {["x"] = 8, ["y"] = 4, ["param1"] = 56, ["z"] = 19, ["name"] = "default:wood"}, {["x"] = 8, ["y"] = 4, ["param1"] = 56, ["z"] = 20, ["name"] = "default:wood"}, {["x"] = 8, ["y"] = 4, ["param1"] = 56, ["z"] = 21, ["name"] = "default:wood"}, {["x"] = 8, ["y"] = 4, ["param1"] = 56, ["z"] = 22, ["name"] = "default:wood"}, {["x"] = 8, ["y"] = 4, ["param1"] = 56, ["z"] = 23, ["name"] = "default:wood"}, {["x"] = 8, ["y"] = 4, ["param1"] = 56, ["z"] = 24, ["name"] = "default:wood"}, {["x"] = 8, ["y"] = 4, ["param1"] = 56, ["z"] = 25, ["name"] = "default:wood"}, {["x"] = 8, ["y"] = 4, ["param1"] = 56, ["z"] = 26, ["name"] = "default:wood"}, {["x"] = 8, ["y"] = 5, ["param1"] = 56, ["z"] = 15, ["name"] = "default:wood"}, {["x"] = 8, ["y"] = 5, ["param1"] = 56, ["z"] = 16, ["name"] = "default:wood"}, {["x"] = 8, ["y"] = 5, ["param1"] = 56, ["z"] = 17, ["name"] = "default:wood"}, {["x"] = 8, ["y"] = 5, ["param1"] = 56, ["z"] = 18, ["name"] = "default:wood"}, {["x"] = 8, ["y"] = 5, ["param1"] = 56, ["z"] = 19, ["name"] = "default:wood"}, {["x"] = 8, ["y"] = 5, ["param1"] = 56, ["z"] = 20, ["name"] = "default:wood"}, {["x"] = 8, ["y"] = 5, ["param1"] = 56, ["z"] = 21, ["name"] = "default:wood"}, {["x"] = 8, ["y"] = 5, ["param1"] = 56, ["z"] = 22, ["name"] = "default:wood"}, {["x"] = 8, ["y"] = 5, ["param1"] = 56, ["z"] = 23, ["name"] = "default:wood"}, {["x"] = 8, ["y"] = 5, ["param1"] = 56, ["z"] = 24, ["name"] = "default:wood"}, {["x"] = 8, ["y"] = 5, ["param1"] = 56, ["z"] = 25, ["name"] = "default:wood"}, {["x"] = 8, ["y"] = 5, ["param1"] = 56, ["z"] = 26, ["name"] = "default:wood"}, {["x"] = 8, ["y"] = 5, ["param1"] = 56, ["z"] = 27, ["name"] = "default:wood"}, {["x"] = 8, ["y"] = 6, ["param1"] = 56, ["z"] = 16, ["name"] = "default:wood"}, {["x"] = 8, ["y"] = 6, ["param1"] = 56, ["z"] = 17, ["name"] = "default:wood"}, {["x"] = 8, ["y"] = 6, ["param1"] = 56, ["z"] = 18, ["name"] = "default:wood"}, {["x"] = 8, ["y"] = 6, ["param1"] = 56, ["z"] = 19, ["name"] = "default:wood"}, {["x"] = 8, ["y"] = 6, ["param1"] = 56, ["z"] = 20, ["name"] = "default:wood"}, {["x"] = 8, ["y"] = 6, ["param1"] = 56, ["z"] = 21, ["name"] = "default:wood"}, {["x"] = 8, ["y"] = 6, ["param1"] = 56, ["z"] = 22, ["name"] = "default:wood"}, {["x"] = 8, ["y"] = 6, ["param1"] = 56, ["z"] = 23, ["name"] = "default:wood"}, {["x"] = 8, ["y"] = 6, ["param1"] = 56, ["z"] = 24, ["name"] = "default:wood"}, {["x"] = 8, ["y"] = 6, ["param1"] = 56, ["z"] = 25, ["name"] = "default:wood"}, {["x"] = 8, ["y"] = 6, ["param1"] = 56, ["z"] = 26, ["name"] = "default:wood"}, {["x"] = 8, ["y"] = 6, ["param1"] = 56, ["z"] = 27, ["name"] = "default:wood"}, {["x"] = 8, ["y"] = 6, ["param1"] = 56, ["z"] = 28, ["name"] = "default:wood"}, {["x"] = 8, ["y"] = 7, ["param1"] = 56, ["z"] = 17, ["name"] = "default:wood"}, {["x"] = 8, ["y"] = 7, ["param1"] = 56, ["z"] = 18, ["name"] = "default:wood"}, {["x"] = 8, ["y"] = 7, ["param1"] = 56, ["z"] = 19, ["name"] = "default:wood"}, {["x"] = 8, ["y"] = 7, ["param1"] = 56, ["z"] = 20, ["name"] = "default:wood"}, {["x"] = 8, ["y"] = 7, ["param1"] = 56, ["z"] = 21, ["name"] = "default:wood"}, {["x"] = 8, ["y"] = 7, ["param1"] = 56, ["z"] = 22, ["name"] = "default:wood"}, {["x"] = 8, ["y"] = 7, ["param1"] = 56, ["z"] = 23, ["name"] = "default:wood"}, {["x"] = 8, ["y"] = 7, ["param1"] = 56, ["z"] = 24, ["name"] = "default:wood"}, {["x"] = 8, ["y"] = 7, ["param1"] = 56, ["z"] = 25, ["name"] = "default:wood"}, {["x"] = 8, ["y"] = 7, ["param1"] = 56, ["z"] = 26, ["name"] = "default:wood"}, {["x"] = 8, ["y"] = 7, ["param1"] = 56, ["z"] = 27, ["name"] = "default:wood"}, {["x"] = 8, ["y"] = 7, ["param1"] = 56, ["z"] = 28, ["name"] = "default:wood"}, {["x"] = 8, ["y"] = 7, ["param1"] = 56, ["z"] = 29, ["name"] = "default:wood"}, {["x"] = 8, ["y"] = 8, ["param1"] = 56, ["z"] = 18, ["name"] = "default:wood"}, {["x"] = 8, ["y"] = 8, ["param1"] = 56, ["z"] = 19, ["name"] = "default:wood"}, {["x"] = 8, ["y"] = 8, ["param1"] = 56, ["z"] = 20, ["name"] = "default:wood"}, {["x"] = 8, ["y"] = 8, ["param1"] = 56, ["z"] = 21, ["name"] = "default:wood"}, {["x"] = 8, ["y"] = 8, ["param1"] = 56, ["z"] = 22, ["name"] = "default:wood"}, {["x"] = 8, ["y"] = 8, ["param1"] = 56, ["z"] = 23, ["name"] = "default:wood"}, {["x"] = 8, ["y"] = 8, ["param1"] = 56, ["z"] = 24, ["name"] = "default:wood"}, {["x"] = 8, ["y"] = 8, ["param1"] = 56, ["z"] = 25, ["name"] = "default:wood"}, {["x"] = 8, ["y"] = 8, ["param1"] = 56, ["z"] = 26, ["name"] = "default:wood"}, {["x"] = 8, ["y"] = 8, ["param1"] = 56, ["z"] = 27, ["name"] = "default:wood"}, {["x"] = 8, ["y"] = 8, ["param1"] = 56, ["z"] = 28, ["name"] = "default:wood"}, {["x"] = 8, ["y"] = 8, ["param1"] = 56, ["z"] = 29, ["name"] = "default:wood"}, {["x"] = 8, ["y"] = 8, ["param1"] = 56, ["z"] = 30, ["name"] = "default:wood"}, {["x"] = 8, ["y"] = 9, ["param1"] = 56, ["z"] = 19, ["name"] = "default:wood"}, {["x"] = 8, ["y"] = 9, ["param1"] = 56, ["z"] = 20, ["name"] = "default:wood"}, {["x"] = 8, ["y"] = 9, ["param1"] = 56, ["z"] = 21, ["name"] = "default:wood"}, {["x"] = 8, ["y"] = 9, ["param1"] = 56, ["z"] = 22, ["name"] = "default:wood"}, {["x"] = 8, ["y"] = 9, ["param1"] = 56, ["z"] = 23, ["name"] = "default:wood"}, {["x"] = 8, ["y"] = 9, ["param1"] = 56, ["z"] = 24, ["name"] = "default:wood"}, {["x"] = 8, ["y"] = 9, ["param1"] = 56, ["z"] = 25, ["name"] = "default:wood"}, {["x"] = 8, ["y"] = 9, ["param1"] = 56, ["z"] = 26, ["name"] = "default:wood"}, {["x"] = 8, ["y"] = 9, ["param1"] = 56, ["z"] = 27, ["name"] = "default:wood"}, {["x"] = 8, ["y"] = 9, ["param1"] = 56, ["z"] = 28, ["name"] = "default:wood"}, {["x"] = 8, ["y"] = 9, ["param1"] = 56, ["z"] = 29, ["name"] = "default:wood"}, {["x"] = 8, ["y"] = 9, ["param1"] = 56, ["z"] = 30, ["name"] = "default:wood"}, {["x"] = 8, ["y"] = 9, ["param1"] = 56, ["z"] = 31, ["name"] = "default:wood"}, {["x"] = 8, ["y"] = 10, ["param1"] = 56, ["z"] = 20, ["name"] = "default:wood"}, {["x"] = 8, ["y"] = 10, ["param1"] = 56, ["z"] = 21, ["name"] = "default:wood"}, {["x"] = 8, ["y"] = 10, ["param1"] = 56, ["z"] = 22, ["name"] = "default:wood"}, {["x"] = 8, ["y"] = 10, ["param1"] = 56, ["z"] = 23, ["name"] = "default:wood"}, {["x"] = 8, ["y"] = 10, ["param1"] = 56, ["z"] = 24, ["name"] = "default:wood"}, {["x"] = 8, ["y"] = 10, ["param1"] = 56, ["z"] = 25, ["name"] = "default:wood"}, {["x"] = 8, ["y"] = 10, ["param1"] = 56, ["z"] = 26, ["name"] = "default:wood"}, {["x"] = 8, ["y"] = 10, ["param1"] = 56, ["z"] = 27, ["name"] = "default:wood"}, {["x"] = 8, ["y"] = 10, ["param1"] = 56, ["z"] = 28, ["name"] = "default:wood"}, {["x"] = 8, ["y"] = 10, ["param1"] = 56, ["z"] = 29, ["name"] = "default:wood"}, {["x"] = 8, ["y"] = 10, ["param1"] = 56, ["z"] = 30, ["name"] = "default:wood"}, {["x"] = 8, ["y"] = 10, ["param1"] = 56, ["z"] = 31, ["name"] = "default:wood"}, {["x"] = 8, ["y"] = 10, ["z"] = 32, ["name"] = "default:wood"}, {["x"] = 8, ["y"] = 11, ["param1"] = 56, ["z"] = 21, ["name"] = "default:wood"}, {["x"] = 8, ["y"] = 11, ["param1"] = 56, ["z"] = 22, ["name"] = "default:wood"}, {["x"] = 8, ["y"] = 11, ["param1"] = 56, ["z"] = 23, ["name"] = "default:wood"}, {["x"] = 8, ["y"] = 11, ["param1"] = 56, ["z"] = 24, ["name"] = "default:wood"}, {["x"] = 8, ["y"] = 11, ["param1"] = 56, ["z"] = 25, ["name"] = "default:wood"}, {["x"] = 8, ["y"] = 11, ["param1"] = 56, ["z"] = 26, ["name"] = "default:wood"}, {["x"] = 8, ["y"] = 11, ["param1"] = 56, ["z"] = 27, ["name"] = "default:wood"}, {["x"] = 8, ["y"] = 11, ["param1"] = 56, ["z"] = 28, ["name"] = "default:wood"}, {["x"] = 8, ["y"] = 11, ["param1"] = 56, ["z"] = 29, ["name"] = "default:wood"}, {["x"] = 8, ["y"] = 11, ["param1"] = 56, ["z"] = 30, ["name"] = "default:wood"}, {["x"] = 8, ["y"] = 11, ["param1"] = 56, ["z"] = 31, ["name"] = "default:wood"}, {["x"] = 8, ["y"] = 11, ["z"] = 32, ["name"] = "default:wood"}, {["x"] = 8, ["y"] = 11, ["z"] = 33, ["name"] = "default:wood"}, {["x"] = 8, ["y"] = 12, ["param1"] = 56, ["z"] = 22, ["name"] = "default:wood"}, {["x"] = 8, ["y"] = 12, ["param1"] = 56, ["z"] = 23, ["name"] = "default:wood"}, {["x"] = 8, ["y"] = 12, ["param1"] = 56, ["z"] = 24, ["name"] = "default:wood"}, {["x"] = 8, ["y"] = 12, ["param1"] = 56, ["z"] = 25, ["name"] = "default:wood"}, {["x"] = 8, ["y"] = 12, ["param1"] = 56, ["z"] = 26, ["name"] = "default:wood"}, {["x"] = 8, ["y"] = 12, ["param1"] = 56, ["z"] = 27, ["name"] = "default:wood"}, {["x"] = 8, ["y"] = 12, ["param1"] = 56, ["z"] = 28, ["name"] = "default:wood"}, {["x"] = 8, ["y"] = 12, ["param1"] = 56, ["z"] = 29, ["name"] = "default:wood"}, {["x"] = 8, ["y"] = 12, ["param1"] = 56, ["z"] = 30, ["name"] = "default:wood"}, {["x"] = 8, ["y"] = 12, ["param1"] = 56, ["z"] = 31, ["name"] = "default:wood"}, {["x"] = 8, ["y"] = 12, ["z"] = 32, ["name"] = "default:wood"}, {["x"] = 8, ["y"] = 12, ["z"] = 33, ["name"] = "default:wood"}, {["x"] = 8, ["y"] = 12, ["z"] = 34, ["name"] = "default:wood"}, {["x"] = 8, ["y"] = 13, ["param1"] = 56, ["z"] = 23, ["name"] = "default:wood"}, {["x"] = 8, ["y"] = 13, ["param1"] = 56, ["z"] = 24, ["name"] = "default:wood"}, {["x"] = 8, ["y"] = 13, ["param1"] = 56, ["z"] = 25, ["name"] = "default:wood"}, {["x"] = 8, ["y"] = 13, ["param1"] = 56, ["z"] = 26, ["name"] = "default:wood"}, {["x"] = 8, ["y"] = 13, ["param1"] = 56, ["z"] = 27, ["name"] = "default:wood"}, {["x"] = 8, ["y"] = 13, ["param1"] = 56, ["z"] = 28, ["name"] = "default:wood"}, {["x"] = 8, ["y"] = 13, ["param1"] = 56, ["z"] = 29, ["name"] = "default:wood"}, {["x"] = 8, ["y"] = 13, ["param1"] = 56, ["z"] = 30, ["name"] = "default:wood"}, {["x"] = 8, ["y"] = 13, ["param1"] = 56, ["z"] = 31, ["name"] = "default:wood"}, {["x"] = 8, ["y"] = 13, ["z"] = 32, ["name"] = "default:wood"}, {["x"] = 8, ["y"] = 13, ["z"] = 33, ["name"] = "default:wood"}, {["x"] = 8, ["y"] = 13, ["z"] = 34, ["name"] = "default:wood"}, {["x"] = 8, ["y"] = 14, ["param1"] = 56, ["z"] = 24, ["name"] = "default:wood"}, {["x"] = 8, ["y"] = 14, ["param1"] = 56, ["z"] = 25, ["name"] = "default:wood"}, {["x"] = 8, ["y"] = 14, ["param1"] = 56, ["z"] = 26, ["name"] = "default:wood"}, {["x"] = 8, ["y"] = 14, ["param1"] = 56, ["z"] = 27, ["name"] = "default:wood"}, {["x"] = 8, ["y"] = 14, ["param1"] = 56, ["z"] = 28, ["name"] = "default:wood"}, {["x"] = 8, ["y"] = 14, ["param1"] = 56, ["z"] = 29, ["name"] = "default:wood"}, {["x"] = 8, ["y"] = 14, ["param1"] = 56, ["z"] = 30, ["name"] = "default:wood"}, {["x"] = 8, ["y"] = 14, ["param1"] = 56, ["z"] = 31, ["name"] = "default:wood"}, {["x"] = 8, ["y"] = 14, ["z"] = 32, ["name"] = "default:wood"}, {["x"] = 8, ["y"] = 14, ["z"] = 33, ["name"] = "default:wood"}, {["x"] = 8, ["y"] = 15, ["param1"] = 56, ["z"] = 25, ["name"] = "default:wood"}, {["x"] = 8, ["y"] = 15, ["param1"] = 56, ["z"] = 26, ["name"] = "default:wood"}, {["x"] = 8, ["y"] = 15, ["param1"] = 56, ["z"] = 27, ["name"] = "default:wood"}, {["x"] = 8, ["y"] = 15, ["param1"] = 56, ["z"] = 28, ["name"] = "default:wood"}, {["x"] = 8, ["y"] = 15, ["param1"] = 56, ["z"] = 29, ["name"] = "default:wood"}, {["x"] = 8, ["y"] = 15, ["param1"] = 56, ["z"] = 30, ["name"] = "default:wood"}, {["x"] = 8, ["y"] = 15, ["param1"] = 56, ["z"] = 31, ["name"] = "default:wood"}, {["x"] = 8, ["y"] = 15, ["z"] = 32, ["name"] = "default:wood"}, {["x"] = 8, ["y"] = 16, ["z"] = 26, ["name"] = "default:wood"}, {["x"] = 8, ["y"] = 16, ["z"] = 27, ["name"] = "default:wood"}, {["x"] = 8, ["y"] = 16, ["z"] = 28, ["name"] = "default:wood"}, {["x"] = 8, ["y"] = 16, ["z"] = 29, ["name"] = "default:wood"}, {["x"] = 8, ["y"] = 16, ["z"] = 30, ["name"] = "default:wood"}, {["x"] = 8, ["y"] = 16, ["z"] = 31, ["name"] = "default:wood"}, {["x"] = 8, ["y"] = 17, ["z"] = 27, ["name"] = "default:wood"}, {["x"] = 8, ["y"] = 17, ["z"] = 28, ["name"] = "default:wood"}, {["x"] = 8, ["y"] = 17, ["z"] = 29, ["name"] = "default:wood"}, {["x"] = 8, ["y"] = 17, ["z"] = 30, ["name"] = "default:wood"}, {["x"] = 8, ["y"] = 18, ["z"] = 28, ["name"] = "default:wood"}, {["x"] = 8, ["y"] = 18, ["z"] = 29, ["name"] = "default:wood"}, {["x"] = 9, ["y"] = 0, ["param1"] = 56, ["z"] = 16, ["name"] = "default:wood"}, {["x"] = 9, ["y"] = 0, ["param1"] = 56, ["z"] = 17, ["name"] = "default:wood"}, {["x"] = 9, ["y"] = 0, ["param1"] = 56, ["z"] = 18, ["name"] = "default:wood"}, {["x"] = 9, ["y"] = 0, ["param1"] = 56, ["z"] = 19, ["name"] = "default:wood"}, {["x"] = 9, ["y"] = 0, ["param1"] = 56, ["z"] = 20, ["name"] = "default:wood"}, {["x"] = 9, ["y"] = 0, ["param1"] = 56, ["z"] = 21, ["name"] = "default:wood"}, {["x"] = 9, ["y"] = 0, ["param1"] = 56, ["z"] = 22, ["name"] = "default:wood"}, {["x"] = 9, ["y"] = 1, ["param1"] = 56, ["z"] = 15, ["name"] = "default:wood"}, {["x"] = 9, ["y"] = 1, ["param1"] = 56, ["z"] = 16, ["name"] = "default:wood"}, {["x"] = 9, ["y"] = 1, ["param1"] = 56, ["z"] = 17, ["name"] = "default:wood"}, {["x"] = 9, ["y"] = 1, ["param1"] = 56, ["z"] = 18, ["name"] = "default:wood"}, {["x"] = 9, ["y"] = 1, ["param1"] = 56, ["z"] = 19, ["name"] = "default:wood"}, {["x"] = 9, ["y"] = 1, ["param1"] = 56, ["z"] = 20, ["name"] = "default:wood"}, {["x"] = 9, ["y"] = 1, ["param1"] = 56, ["z"] = 21, ["name"] = "default:wood"}, {["x"] = 9, ["y"] = 1, ["param1"] = 56, ["z"] = 22, ["name"] = "default:wood"}, {["x"] = 9, ["y"] = 1, ["param1"] = 56, ["z"] = 23, ["name"] = "default:wood"}, {["x"] = 9, ["y"] = 2, ["param1"] = 56, ["z"] = 14, ["name"] = "default:wood"}, {["x"] = 9, ["y"] = 2, ["param1"] = 56, ["z"] = 15, ["name"] = "default:wood"}, {["x"] = 9, ["y"] = 2, ["param1"] = 56, ["z"] = 16, ["name"] = "default:wood"}, {["x"] = 9, ["y"] = 2, ["param1"] = 56, ["z"] = 17, ["name"] = "default:wood"}, {["x"] = 9, ["y"] = 2, ["param1"] = 56, ["z"] = 18, ["name"] = "default:wood"}, {["x"] = 9, ["y"] = 2, ["param1"] = 56, ["z"] = 19, ["name"] = "default:wood"}, {["x"] = 9, ["y"] = 2, ["param1"] = 56, ["z"] = 20, ["name"] = "default:wood"}, {["x"] = 9, ["y"] = 2, ["param1"] = 56, ["z"] = 21, ["name"] = "default:wood"}, {["x"] = 9, ["y"] = 2, ["param1"] = 56, ["z"] = 22, ["name"] = "default:wood"}, {["x"] = 9, ["y"] = 2, ["param1"] = 56, ["z"] = 23, ["name"] = "default:wood"}, {["x"] = 9, ["y"] = 2, ["param1"] = 56, ["z"] = 24, ["name"] = "default:wood"}, {["x"] = 9, ["y"] = 3, ["param1"] = 56, ["z"] = 13, ["name"] = "default:wood"}, {["x"] = 9, ["y"] = 3, ["param1"] = 56, ["z"] = 14, ["name"] = "default:wood"}, {["x"] = 9, ["y"] = 3, ["param1"] = 56, ["z"] = 15, ["name"] = "default:wood"}, {["x"] = 9, ["y"] = 3, ["param1"] = 56, ["z"] = 16, ["name"] = "default:wood"}, {["x"] = 9, ["y"] = 3, ["param1"] = 56, ["z"] = 17, ["name"] = "default:wood"}, {["x"] = 9, ["y"] = 3, ["param1"] = 56, ["z"] = 18, ["name"] = "default:wood"}, {["x"] = 9, ["y"] = 3, ["param1"] = 56, ["z"] = 19, ["name"] = "default:wood"}, {["x"] = 9, ["y"] = 3, ["param1"] = 56, ["z"] = 20, ["name"] = "default:wood"}, {["x"] = 9, ["y"] = 3, ["param1"] = 56, ["z"] = 21, ["name"] = "default:wood"}, {["x"] = 9, ["y"] = 3, ["param1"] = 56, ["z"] = 22, ["name"] = "default:wood"}, {["x"] = 9, ["y"] = 3, ["param1"] = 56, ["z"] = 23, ["name"] = "default:wood"}, {["x"] = 9, ["y"] = 3, ["param1"] = 56, ["z"] = 24, ["name"] = "default:wood"}, {["x"] = 9, ["y"] = 3, ["param1"] = 56, ["z"] = 25, ["name"] = "default:wood"}, {["x"] = 9, ["y"] = 4, ["param1"] = 56, ["z"] = 14, ["name"] = "default:wood"}, {["x"] = 9, ["y"] = 4, ["param1"] = 56, ["z"] = 15, ["name"] = "default:wood"}, {["x"] = 9, ["y"] = 4, ["param1"] = 56, ["z"] = 16, ["name"] = "default:wood"}, {["x"] = 9, ["y"] = 4, ["param1"] = 56, ["z"] = 17, ["name"] = "default:wood"}, {["x"] = 9, ["y"] = 4, ["param1"] = 56, ["z"] = 18, ["name"] = "default:wood"}, {["x"] = 9, ["y"] = 4, ["param1"] = 56, ["z"] = 19, ["name"] = "default:wood"}, {["x"] = 9, ["y"] = 4, ["param1"] = 56, ["z"] = 20, ["name"] = "default:wood"}, {["x"] = 9, ["y"] = 4, ["param1"] = 56, ["z"] = 21, ["name"] = "default:wood"}, {["x"] = 9, ["y"] = 4, ["param1"] = 56, ["z"] = 22, ["name"] = "default:wood"}, {["x"] = 9, ["y"] = 4, ["param1"] = 56, ["z"] = 23, ["name"] = "default:wood"}, {["x"] = 9, ["y"] = 4, ["param1"] = 56, ["z"] = 24, ["name"] = "default:wood"}, {["x"] = 9, ["y"] = 4, ["param1"] = 56, ["z"] = 25, ["name"] = "default:wood"}, {["x"] = 9, ["y"] = 4, ["param1"] = 56, ["z"] = 26, ["name"] = "default:wood"}, {["x"] = 9, ["y"] = 5, ["param1"] = 56, ["z"] = 15, ["name"] = "default:wood"}, {["x"] = 9, ["y"] = 5, ["param1"] = 56, ["z"] = 16, ["name"] = "default:wood"}, {["x"] = 9, ["y"] = 5, ["param1"] = 56, ["z"] = 17, ["name"] = "default:wood"}, {["x"] = 9, ["y"] = 5, ["param1"] = 56, ["z"] = 18, ["name"] = "default:wood"}, {["x"] = 9, ["y"] = 5, ["param1"] = 56, ["z"] = 19, ["name"] = "default:wood"}, {["x"] = 9, ["y"] = 5, ["param1"] = 56, ["z"] = 20, ["name"] = "default:wood"}, {["x"] = 9, ["y"] = 5, ["param1"] = 56, ["z"] = 21, ["name"] = "default:wood"}, {["x"] = 9, ["y"] = 5, ["param1"] = 56, ["z"] = 22, ["name"] = "default:wood"}, {["x"] = 9, ["y"] = 5, ["param1"] = 56, ["z"] = 23, ["name"] = "default:wood"}, {["x"] = 9, ["y"] = 5, ["param1"] = 56, ["z"] = 24, ["name"] = "default:wood"}, {["x"] = 9, ["y"] = 5, ["param1"] = 56, ["z"] = 25, ["name"] = "default:wood"}, {["x"] = 9, ["y"] = 5, ["param1"] = 56, ["z"] = 26, ["name"] = "default:wood"}, {["x"] = 9, ["y"] = 5, ["param1"] = 56, ["z"] = 27, ["name"] = "default:wood"}, {["x"] = 9, ["y"] = 6, ["param1"] = 56, ["z"] = 16, ["name"] = "default:wood"}, {["x"] = 9, ["y"] = 6, ["param1"] = 56, ["z"] = 17, ["name"] = "default:wood"}, {["x"] = 9, ["y"] = 6, ["param1"] = 56, ["z"] = 18, ["name"] = "default:wood"}, {["x"] = 9, ["y"] = 6, ["param1"] = 56, ["z"] = 19, ["name"] = "default:wood"}, {["x"] = 9, ["y"] = 6, ["param1"] = 56, ["z"] = 20, ["name"] = "default:wood"}, {["x"] = 9, ["y"] = 6, ["param1"] = 56, ["z"] = 21, ["name"] = "default:wood"}, {["x"] = 9, ["y"] = 6, ["param1"] = 56, ["z"] = 22, ["name"] = "default:wood"}, {["x"] = 9, ["y"] = 6, ["param1"] = 56, ["z"] = 23, ["name"] = "default:wood"}, {["x"] = 9, ["y"] = 6, ["param1"] = 56, ["z"] = 24, ["name"] = "default:wood"}, {["x"] = 9, ["y"] = 6, ["param1"] = 56, ["z"] = 25, ["name"] = "default:wood"}, {["x"] = 9, ["y"] = 6, ["param1"] = 56, ["z"] = 26, ["name"] = "default:wood"}, {["x"] = 9, ["y"] = 6, ["param1"] = 56, ["z"] = 27, ["name"] = "default:wood"}, {["x"] = 9, ["y"] = 6, ["param1"] = 56, ["z"] = 28, ["name"] = "default:wood"}, {["x"] = 9, ["y"] = 7, ["param1"] = 56, ["z"] = 17, ["name"] = "default:wood"}, {["x"] = 9, ["y"] = 7, ["param1"] = 56, ["z"] = 18, ["name"] = "default:wood"}, {["x"] = 9, ["y"] = 7, ["param1"] = 56, ["z"] = 19, ["name"] = "default:wood"}, {["x"] = 9, ["y"] = 7, ["param1"] = 56, ["z"] = 20, ["name"] = "default:wood"}, {["x"] = 9, ["y"] = 7, ["param1"] = 56, ["z"] = 21, ["name"] = "default:wood"}, {["x"] = 9, ["y"] = 7, ["param1"] = 56, ["z"] = 22, ["name"] = "default:wood"}, {["x"] = 9, ["y"] = 7, ["param1"] = 56, ["z"] = 23, ["name"] = "default:wood"}, {["x"] = 9, ["y"] = 7, ["param1"] = 56, ["z"] = 24, ["name"] = "default:wood"}, {["x"] = 9, ["y"] = 7, ["param1"] = 56, ["z"] = 25, ["name"] = "default:wood"}, {["x"] = 9, ["y"] = 7, ["param1"] = 56, ["z"] = 26, ["name"] = "default:wood"}, {["x"] = 9, ["y"] = 7, ["param1"] = 56, ["z"] = 27, ["name"] = "default:wood"}, {["x"] = 9, ["y"] = 7, ["param1"] = 56, ["z"] = 28, ["name"] = "default:wood"}, {["x"] = 9, ["y"] = 7, ["param1"] = 56, ["z"] = 29, ["name"] = "default:wood"}, {["x"] = 9, ["y"] = 8, ["param1"] = 56, ["z"] = 18, ["name"] = "default:wood"}, {["x"] = 9, ["y"] = 8, ["param1"] = 56, ["z"] = 19, ["name"] = "default:wood"}, {["x"] = 9, ["y"] = 8, ["param1"] = 56, ["z"] = 20, ["name"] = "default:wood"}, {["x"] = 9, ["y"] = 8, ["param1"] = 56, ["z"] = 21, ["name"] = "default:wood"}, {["x"] = 9, ["y"] = 8, ["param1"] = 56, ["z"] = 22, ["name"] = "default:wood"}, {["x"] = 9, ["y"] = 8, ["param1"] = 56, ["z"] = 23, ["name"] = "default:wood"}, {["x"] = 9, ["y"] = 8, ["param1"] = 56, ["z"] = 24, ["name"] = "default:wood"}, {["x"] = 9, ["y"] = 8, ["param1"] = 56, ["z"] = 25, ["name"] = "default:wood"}, {["x"] = 9, ["y"] = 8, ["param1"] = 56, ["z"] = 26, ["name"] = "default:wood"}, {["x"] = 9, ["y"] = 8, ["param1"] = 56, ["z"] = 27, ["name"] = "default:wood"}, {["x"] = 9, ["y"] = 8, ["param1"] = 56, ["z"] = 28, ["name"] = "default:wood"}, {["x"] = 9, ["y"] = 8, ["param1"] = 56, ["z"] = 29, ["name"] = "default:wood"}, {["x"] = 9, ["y"] = 8, ["param1"] = 56, ["z"] = 30, ["name"] = "default:wood"}, {["x"] = 9, ["y"] = 9, ["param1"] = 56, ["z"] = 19, ["name"] = "default:wood"}, {["x"] = 9, ["y"] = 9, ["param1"] = 56, ["z"] = 20, ["name"] = "default:wood"}, {["x"] = 9, ["y"] = 9, ["param1"] = 56, ["z"] = 21, ["name"] = "default:wood"}, {["x"] = 9, ["y"] = 9, ["param1"] = 56, ["z"] = 22, ["name"] = "default:wood"}, {["x"] = 9, ["y"] = 9, ["param1"] = 56, ["z"] = 23, ["name"] = "default:wood"}, {["x"] = 9, ["y"] = 9, ["param1"] = 56, ["z"] = 24, ["name"] = "default:wood"}, {["x"] = 9, ["y"] = 9, ["param1"] = 56, ["z"] = 25, ["name"] = "default:wood"}, {["x"] = 9, ["y"] = 9, ["param1"] = 56, ["z"] = 26, ["name"] = "default:wood"}, {["x"] = 9, ["y"] = 9, ["param1"] = 56, ["z"] = 27, ["name"] = "default:wood"}, {["x"] = 9, ["y"] = 9, ["param1"] = 56, ["z"] = 28, ["name"] = "default:wood"}, {["x"] = 9, ["y"] = 9, ["param1"] = 56, ["z"] = 29, ["name"] = "default:wood"}, {["x"] = 9, ["y"] = 9, ["param1"] = 56, ["z"] = 30, ["name"] = "default:wood"}, {["x"] = 9, ["y"] = 9, ["param1"] = 56, ["z"] = 31, ["name"] = "default:wood"}, {["x"] = 9, ["y"] = 10, ["param1"] = 56, ["z"] = 20, ["name"] = "default:wood"}, {["x"] = 9, ["y"] = 10, ["param1"] = 56, ["z"] = 21, ["name"] = "default:wood"}, {["x"] = 9, ["y"] = 10, ["param1"] = 56, ["z"] = 22, ["name"] = "default:wood"}, {["x"] = 9, ["y"] = 10, ["param1"] = 56, ["z"] = 23, ["name"] = "default:wood"}, {["x"] = 9, ["y"] = 10, ["param1"] = 56, ["z"] = 24, ["name"] = "default:wood"}, {["x"] = 9, ["y"] = 10, ["param1"] = 56, ["z"] = 25, ["name"] = "default:wood"}, {["x"] = 9, ["y"] = 10, ["param1"] = 56, ["z"] = 26, ["name"] = "default:wood"}, {["x"] = 9, ["y"] = 10, ["param1"] = 56, ["z"] = 27, ["name"] = "default:wood"}, {["x"] = 9, ["y"] = 10, ["param1"] = 56, ["z"] = 28, ["name"] = "default:wood"}, {["x"] = 9, ["y"] = 10, ["param1"] = 56, ["z"] = 29, ["name"] = "default:wood"}, {["x"] = 9, ["y"] = 10, ["param1"] = 56, ["z"] = 30, ["name"] = "default:wood"}, {["x"] = 9, ["y"] = 10, ["param1"] = 56, ["z"] = 31, ["name"] = "default:wood"}, {["x"] = 9, ["y"] = 10, ["z"] = 32, ["name"] = "default:wood"}, {["x"] = 9, ["y"] = 11, ["param1"] = 56, ["z"] = 21, ["name"] = "default:wood"}, {["x"] = 9, ["y"] = 11, ["param1"] = 56, ["z"] = 22, ["name"] = "default:wood"}, {["x"] = 9, ["y"] = 11, ["param1"] = 56, ["z"] = 23, ["name"] = "default:wood"}, {["x"] = 9, ["y"] = 11, ["param1"] = 56, ["z"] = 24, ["name"] = "default:wood"}, {["x"] = 9, ["y"] = 11, ["param1"] = 56, ["z"] = 25, ["name"] = "default:wood"}, {["x"] = 9, ["y"] = 11, ["param1"] = 56, ["z"] = 26, ["name"] = "default:wood"}, {["x"] = 9, ["y"] = 11, ["param1"] = 56, ["z"] = 27, ["name"] = "default:wood"}, {["x"] = 9, ["y"] = 11, ["param1"] = 56, ["z"] = 28, ["name"] = "default:wood"}, {["x"] = 9, ["y"] = 11, ["param1"] = 56, ["z"] = 29, ["name"] = "default:wood"}, {["x"] = 9, ["y"] = 11, ["param1"] = 56, ["z"] = 30, ["name"] = "default:wood"}, {["x"] = 9, ["y"] = 11, ["param1"] = 56, ["z"] = 31, ["name"] = "default:wood"}, {["x"] = 9, ["y"] = 11, ["z"] = 32, ["name"] = "default:wood"}, {["x"] = 9, ["y"] = 11, ["z"] = 33, ["name"] = "default:wood"}, {["x"] = 9, ["y"] = 12, ["param1"] = 56, ["z"] = 22, ["name"] = "default:wood"}, {["x"] = 9, ["y"] = 12, ["param1"] = 56, ["z"] = 23, ["name"] = "default:wood"}, {["x"] = 9, ["y"] = 12, ["param1"] = 56, ["z"] = 24, ["name"] = "default:wood"}, {["x"] = 9, ["y"] = 12, ["param1"] = 56, ["z"] = 25, ["name"] = "default:wood"}, {["x"] = 9, ["y"] = 12, ["param1"] = 56, ["z"] = 26, ["name"] = "default:wood"}, {["x"] = 9, ["y"] = 12, ["param1"] = 56, ["z"] = 27, ["name"] = "default:wood"}, {["x"] = 9, ["y"] = 12, ["param1"] = 56, ["z"] = 28, ["name"] = "default:wood"}, {["x"] = 9, ["y"] = 12, ["param1"] = 56, ["z"] = 29, ["name"] = "default:wood"}, {["x"] = 9, ["y"] = 12, ["param1"] = 56, ["z"] = 30, ["name"] = "default:wood"}, {["x"] = 9, ["y"] = 12, ["param1"] = 56, ["z"] = 31, ["name"] = "default:wood"}, {["x"] = 9, ["y"] = 12, ["z"] = 32, ["name"] = "default:wood"}, {["x"] = 9, ["y"] = 12, ["z"] = 33, ["name"] = "default:wood"}, {["x"] = 9, ["y"] = 12, ["z"] = 34, ["name"] = "default:wood"}, {["x"] = 9, ["y"] = 13, ["param1"] = 56, ["z"] = 23, ["name"] = "default:wood"}, {["x"] = 9, ["y"] = 13, ["param1"] = 56, ["z"] = 24, ["name"] = "default:wood"}, {["x"] = 9, ["y"] = 13, ["param1"] = 56, ["z"] = 25, ["name"] = "default:wood"}, {["x"] = 9, ["y"] = 13, ["param1"] = 56, ["z"] = 26, ["name"] = "default:wood"}, {["x"] = 9, ["y"] = 13, ["param1"] = 56, ["z"] = 27, ["name"] = "default:wood"}, {["x"] = 9, ["y"] = 13, ["param1"] = 56, ["z"] = 28, ["name"] = "default:wood"}, {["x"] = 9, ["y"] = 13, ["param1"] = 56, ["z"] = 29, ["name"] = "default:wood"}, {["x"] = 9, ["y"] = 13, ["param1"] = 56, ["z"] = 30, ["name"] = "default:wood"}, {["x"] = 9, ["y"] = 13, ["param1"] = 56, ["z"] = 31, ["name"] = "default:wood"}, {["x"] = 9, ["y"] = 13, ["z"] = 32, ["name"] = "default:wood"}, {["x"] = 9, ["y"] = 13, ["z"] = 33, ["name"] = "default:wood"}, {["x"] = 9, ["y"] = 13, ["z"] = 34, ["name"] = "default:wood"}, {["x"] = 9, ["y"] = 14, ["param1"] = 56, ["z"] = 24, ["name"] = "default:wood"}, {["x"] = 9, ["y"] = 14, ["param1"] = 56, ["z"] = 25, ["name"] = "default:wood"}, {["x"] = 9, ["y"] = 14, ["param1"] = 56, ["z"] = 26, ["name"] = "default:wood"}, {["x"] = 9, ["y"] = 14, ["param1"] = 56, ["z"] = 27, ["name"] = "default:wood"}, {["x"] = 9, ["y"] = 14, ["param1"] = 56, ["z"] = 28, ["name"] = "default:wood"}, {["x"] = 9, ["y"] = 14, ["param1"] = 56, ["z"] = 29, ["name"] = "default:wood"}, {["x"] = 9, ["y"] = 14, ["param1"] = 56, ["z"] = 30, ["name"] = "default:wood"}, {["x"] = 9, ["y"] = 14, ["param1"] = 56, ["z"] = 31, ["name"] = "default:wood"}, {["x"] = 9, ["y"] = 14, ["z"] = 32, ["name"] = "default:wood"}, {["x"] = 9, ["y"] = 14, ["z"] = 33, ["name"] = "default:wood"}, {["x"] = 9, ["y"] = 15, ["param1"] = 56, ["z"] = 25, ["name"] = "default:wood"}, {["x"] = 9, ["y"] = 15, ["param1"] = 56, ["z"] = 26, ["name"] = "default:wood"}, {["x"] = 9, ["y"] = 15, ["param1"] = 56, ["z"] = 27, ["name"] = "default:wood"}, {["x"] = 9, ["y"] = 15, ["param1"] = 56, ["z"] = 28, ["name"] = "default:wood"}, {["x"] = 9, ["y"] = 15, ["param1"] = 56, ["z"] = 29, ["name"] = "default:wood"}, {["x"] = 9, ["y"] = 15, ["param1"] = 56, ["z"] = 30, ["name"] = "default:wood"}, {["x"] = 9, ["y"] = 15, ["param1"] = 56, ["z"] = 31, ["name"] = "default:wood"}, {["x"] = 9, ["y"] = 15, ["z"] = 32, ["name"] = "default:wood"}, {["x"] = 9, ["y"] = 16, ["z"] = 26, ["name"] = "default:wood"}, {["x"] = 9, ["y"] = 16, ["z"] = 27, ["name"] = "default:wood"}, {["x"] = 9, ["y"] = 16, ["z"] = 28, ["name"] = "default:wood"}, {["x"] = 9, ["y"] = 16, ["z"] = 29, ["name"] = "default:wood"}, {["x"] = 9, ["y"] = 16, ["z"] = 30, ["name"] = "default:wood"}, {["x"] = 9, ["y"] = 16, ["z"] = 31, ["name"] = "default:wood"}, {["x"] = 9, ["y"] = 17, ["z"] = 27, ["name"] = "default:wood"}, {["x"] = 9, ["y"] = 17, ["z"] = 28, ["name"] = "default:wood"}, {["x"] = 9, ["y"] = 17, ["z"] = 29, ["name"] = "default:wood"}, {["x"] = 9, ["y"] = 17, ["z"] = 30, ["name"] = "default:wood"}, {["x"] = 9, ["y"] = 18, ["z"] = 28, ["name"] = "default:wood"}, {["x"] = 9, ["y"] = 18, ["z"] = 29, ["name"] = "default:wood"}, {["x"] = 10, ["y"] = 0, ["param1"] = 56, ["z"] = 16, ["name"] = "default:wood"}, {["x"] = 10, ["y"] = 0, ["param1"] = 56, ["z"] = 17, ["name"] = "default:wood"}, {["x"] = 10, ["y"] = 0, ["param1"] = 56, ["z"] = 18, ["name"] = "default:wood"}, {["x"] = 10, ["y"] = 0, ["param1"] = 56, ["z"] = 19, ["name"] = "default:wood"}, {["x"] = 10, ["y"] = 0, ["param1"] = 56, ["z"] = 20, ["name"] = "default:wood"}, {["x"] = 10, ["y"] = 1, ["param1"] = 56, ["z"] = 15, ["name"] = "default:wood"}, {["x"] = 10, ["y"] = 1, ["param1"] = 56, ["z"] = 16, ["name"] = "default:wood"}, {["x"] = 10, ["y"] = 1, ["param1"] = 56, ["z"] = 17, ["name"] = "default:wood"}, {["x"] = 10, ["y"] = 1, ["param1"] = 56, ["z"] = 18, ["name"] = "default:wood"}, {["x"] = 10, ["y"] = 1, ["param1"] = 56, ["z"] = 19, ["name"] = "default:wood"}, {["x"] = 10, ["y"] = 1, ["param1"] = 56, ["z"] = 20, ["name"] = "default:wood"}, {["x"] = 10, ["y"] = 1, ["param1"] = 56, ["z"] = 21, ["name"] = "default:wood"}, {["x"] = 10, ["y"] = 2, ["param1"] = 56, ["z"] = 14, ["name"] = "default:wood"}, {["x"] = 10, ["y"] = 2, ["param1"] = 56, ["z"] = 15, ["name"] = "default:wood"}, {["x"] = 10, ["y"] = 2, ["param1"] = 56, ["z"] = 16, ["name"] = "default:wood"}, {["x"] = 10, ["y"] = 2, ["param1"] = 56, ["z"] = 17, ["name"] = "default:wood"}, {["x"] = 10, ["y"] = 2, ["param1"] = 56, ["z"] = 18, ["name"] = "default:wood"}, {["x"] = 10, ["y"] = 2, ["param1"] = 56, ["z"] = 19, ["name"] = "default:wood"}, {["x"] = 10, ["y"] = 2, ["param1"] = 56, ["z"] = 20, ["name"] = "default:wood"}, {["x"] = 10, ["y"] = 2, ["param1"] = 56, ["z"] = 21, ["name"] = "default:wood"}, {["x"] = 10, ["y"] = 2, ["param1"] = 56, ["z"] = 22, ["name"] = "default:wood"}, {["x"] = 10, ["y"] = 3, ["param1"] = 56, ["z"] = 15, ["name"] = "default:wood"}, {["x"] = 10, ["y"] = 3, ["param1"] = 56, ["z"] = 16, ["name"] = "default:wood"}, {["x"] = 10, ["y"] = 3, ["param1"] = 56, ["z"] = 17, ["name"] = "default:wood"}, {["x"] = 10, ["y"] = 3, ["param1"] = 56, ["z"] = 18, ["name"] = "default:wood"}, {["x"] = 10, ["y"] = 3, ["param1"] = 56, ["z"] = 19, ["name"] = "default:wood"}, {["x"] = 10, ["y"] = 3, ["param1"] = 56, ["z"] = 20, ["name"] = "default:wood"}, {["x"] = 10, ["y"] = 3, ["param1"] = 56, ["z"] = 21, ["name"] = "default:wood"}, {["x"] = 10, ["y"] = 3, ["param1"] = 56, ["z"] = 22, ["name"] = "default:wood"}, {["x"] = 10, ["y"] = 3, ["param1"] = 56, ["z"] = 23, ["name"] = "default:wood"}, {["x"] = 10, ["y"] = 4, ["param1"] = 56, ["z"] = 16, ["name"] = "default:wood"}, {["x"] = 10, ["y"] = 4, ["param1"] = 56, ["z"] = 17, ["name"] = "default:wood"}, {["x"] = 10, ["y"] = 4, ["param1"] = 56, ["z"] = 18, ["name"] = "default:wood"}, {["x"] = 10, ["y"] = 4, ["param1"] = 56, ["z"] = 19, ["name"] = "default:wood"}, {["x"] = 10, ["y"] = 4, ["param1"] = 56, ["z"] = 20, ["name"] = "default:wood"}, {["x"] = 10, ["y"] = 4, ["param1"] = 56, ["z"] = 21, ["name"] = "default:wood"}, {["x"] = 10, ["y"] = 4, ["param1"] = 56, ["z"] = 22, ["name"] = "default:wood"}, {["x"] = 10, ["y"] = 4, ["param1"] = 56, ["z"] = 23, ["name"] = "default:wood"}, {["x"] = 10, ["y"] = 4, ["param1"] = 56, ["z"] = 24, ["name"] = "default:wood"}, {["x"] = 10, ["y"] = 5, ["param1"] = 56, ["z"] = 17, ["name"] = "default:wood"}, {["x"] = 10, ["y"] = 5, ["param1"] = 56, ["z"] = 18, ["name"] = "default:wood"}, {["x"] = 10, ["y"] = 5, ["param1"] = 56, ["z"] = 19, ["name"] = "default:wood"}, {["x"] = 10, ["y"] = 5, ["param1"] = 56, ["z"] = 20, ["name"] = "default:wood"}, {["x"] = 10, ["y"] = 5, ["param1"] = 56, ["z"] = 21, ["name"] = "default:wood"}, {["x"] = 10, ["y"] = 5, ["param1"] = 56, ["z"] = 22, ["name"] = "default:wood"}, {["x"] = 10, ["y"] = 5, ["param1"] = 56, ["z"] = 23, ["name"] = "default:wood"}, {["x"] = 10, ["y"] = 5, ["param1"] = 56, ["z"] = 24, ["name"] = "default:wood"}, {["x"] = 10, ["y"] = 5, ["param1"] = 56, ["z"] = 25, ["name"] = "default:wood"}, {["x"] = 10, ["y"] = 6, ["param1"] = 56, ["z"] = 18, ["name"] = "default:wood"}, {["x"] = 10, ["y"] = 6, ["param1"] = 56, ["z"] = 19, ["name"] = "default:wood"}, {["x"] = 10, ["y"] = 6, ["param1"] = 56, ["z"] = 20, ["name"] = "default:wood"}, {["x"] = 10, ["y"] = 6, ["param1"] = 56, ["z"] = 21, ["name"] = "default:wood"}, {["x"] = 10, ["y"] = 6, ["param1"] = 56, ["z"] = 22, ["name"] = "default:wood"}, {["x"] = 10, ["y"] = 6, ["param1"] = 56, ["z"] = 23, ["name"] = "default:wood"}, {["x"] = 10, ["y"] = 6, ["param1"] = 56, ["z"] = 24, ["name"] = "default:wood"}, {["x"] = 10, ["y"] = 6, ["param1"] = 56, ["z"] = 25, ["name"] = "default:wood"}, {["x"] = 10, ["y"] = 6, ["param1"] = 56, ["z"] = 26, ["name"] = "default:wood"}, {["x"] = 10, ["y"] = 7, ["param1"] = 56, ["z"] = 19, ["name"] = "default:wood"}, {["x"] = 10, ["y"] = 7, ["param1"] = 56, ["z"] = 20, ["name"] = "default:wood"}, {["x"] = 10, ["y"] = 7, ["param1"] = 56, ["z"] = 21, ["name"] = "default:wood"}, {["x"] = 10, ["y"] = 7, ["param1"] = 56, ["z"] = 22, ["name"] = "default:wood"}, {["x"] = 10, ["y"] = 7, ["param1"] = 56, ["z"] = 23, ["name"] = "default:wood"}, {["x"] = 10, ["y"] = 7, ["param1"] = 56, ["z"] = 24, ["name"] = "default:wood"}, {["x"] = 10, ["y"] = 7, ["param1"] = 56, ["z"] = 25, ["name"] = "default:wood"}, {["x"] = 10, ["y"] = 7, ["param1"] = 56, ["z"] = 26, ["name"] = "default:wood"}, {["x"] = 10, ["y"] = 7, ["param1"] = 56, ["z"] = 27, ["name"] = "default:wood"}, {["x"] = 10, ["y"] = 8, ["param1"] = 56, ["z"] = 20, ["name"] = "default:wood"}, {["x"] = 10, ["y"] = 8, ["param1"] = 56, ["z"] = 21, ["name"] = "default:wood"}, {["x"] = 10, ["y"] = 8, ["param1"] = 56, ["z"] = 22, ["name"] = "default:wood"}, {["x"] = 10, ["y"] = 8, ["param1"] = 56, ["z"] = 23, ["name"] = "default:wood"}, {["x"] = 10, ["y"] = 8, ["param1"] = 56, ["z"] = 24, ["name"] = "default:wood"}, {["x"] = 10, ["y"] = 8, ["param1"] = 56, ["z"] = 25, ["name"] = "default:wood"}, {["x"] = 10, ["y"] = 8, ["param1"] = 56, ["z"] = 26, ["name"] = "default:wood"}, {["x"] = 10, ["y"] = 8, ["param1"] = 56, ["z"] = 27, ["name"] = "default:wood"}, {["x"] = 10, ["y"] = 8, ["param1"] = 56, ["z"] = 28, ["name"] = "default:wood"}, {["x"] = 10, ["y"] = 9, ["param1"] = 56, ["z"] = 21, ["name"] = "default:wood"}, {["x"] = 10, ["y"] = 9, ["param1"] = 56, ["z"] = 22, ["name"] = "default:wood"}, {["x"] = 10, ["y"] = 9, ["param1"] = 56, ["z"] = 23, ["name"] = "default:wood"}, {["x"] = 10, ["y"] = 9, ["param1"] = 56, ["z"] = 24, ["name"] = "default:wood"}, {["x"] = 10, ["y"] = 9, ["param1"] = 56, ["z"] = 25, ["name"] = "default:wood"}, {["x"] = 10, ["y"] = 9, ["param1"] = 56, ["z"] = 26, ["name"] = "default:wood"}, {["x"] = 10, ["y"] = 9, ["param1"] = 56, ["z"] = 27, ["name"] = "default:wood"}, {["x"] = 10, ["y"] = 9, ["param1"] = 56, ["z"] = 28, ["name"] = "default:wood"}, {["x"] = 10, ["y"] = 9, ["param1"] = 56, ["z"] = 29, ["name"] = "default:wood"}, {["x"] = 10, ["y"] = 10, ["param1"] = 56, ["z"] = 22, ["name"] = "default:wood"}, {["x"] = 10, ["y"] = 10, ["param1"] = 56, ["z"] = 23, ["name"] = "default:wood"}, {["x"] = 10, ["y"] = 10, ["param1"] = 56, ["z"] = 24, ["name"] = "default:wood"}, {["x"] = 10, ["y"] = 10, ["param1"] = 56, ["z"] = 25, ["name"] = "default:wood"}, {["x"] = 10, ["y"] = 10, ["param1"] = 56, ["z"] = 26, ["name"] = "default:wood"}, {["x"] = 10, ["y"] = 10, ["param1"] = 56, ["z"] = 27, ["name"] = "default:wood"}, {["x"] = 10, ["y"] = 10, ["param1"] = 56, ["z"] = 28, ["name"] = "default:wood"}, {["x"] = 10, ["y"] = 10, ["param1"] = 56, ["z"] = 29, ["name"] = "default:wood"}, {["x"] = 10, ["y"] = 10, ["param1"] = 56, ["z"] = 30, ["name"] = "default:wood"}, {["x"] = 10, ["y"] = 11, ["param1"] = 56, ["z"] = 23, ["name"] = "default:wood"}, {["x"] = 10, ["y"] = 11, ["param1"] = 56, ["z"] = 24, ["name"] = "default:wood"}, {["x"] = 10, ["y"] = 11, ["param1"] = 56, ["z"] = 25, ["name"] = "default:wood"}, {["x"] = 10, ["y"] = 11, ["param1"] = 56, ["z"] = 26, ["name"] = "default:wood"}, {["x"] = 10, ["y"] = 11, ["param1"] = 56, ["z"] = 27, ["name"] = "default:wood"}, {["x"] = 10, ["y"] = 11, ["param1"] = 56, ["z"] = 28, ["name"] = "default:wood"}, {["x"] = 10, ["y"] = 11, ["param1"] = 56, ["z"] = 29, ["name"] = "default:wood"}, {["x"] = 10, ["y"] = 11, ["param1"] = 56, ["z"] = 30, ["name"] = "default:wood"}, {["x"] = 10, ["y"] = 11, ["param1"] = 56, ["z"] = 31, ["name"] = "default:wood"}, {["x"] = 10, ["y"] = 12, ["param1"] = 56, ["z"] = 24, ["name"] = "default:wood"}, {["x"] = 10, ["y"] = 12, ["param1"] = 56, ["z"] = 25, ["name"] = "default:wood"}, {["x"] = 10, ["y"] = 12, ["param1"] = 56, ["z"] = 26, ["name"] = "default:wood"}, {["x"] = 10, ["y"] = 12, ["param1"] = 56, ["z"] = 27, ["name"] = "default:wood"}, {["x"] = 10, ["y"] = 12, ["param1"] = 56, ["z"] = 28, ["name"] = "default:wood"}, {["x"] = 10, ["y"] = 12, ["param1"] = 56, ["z"] = 29, ["name"] = "default:wood"}, {["x"] = 10, ["y"] = 12, ["param1"] = 56, ["z"] = 30, ["name"] = "default:wood"}, {["x"] = 10, ["y"] = 12, ["param1"] = 56, ["z"] = 31, ["name"] = "default:wood"}, {["x"] = 10, ["y"] = 12, ["z"] = 32, ["name"] = "default:wood"}, {["x"] = 10, ["y"] = 13, ["param1"] = 56, ["z"] = 25, ["name"] = "default:wood"}, {["x"] = 10, ["y"] = 13, ["param1"] = 56, ["z"] = 26, ["name"] = "default:wood"}, {["x"] = 10, ["y"] = 13, ["param1"] = 56, ["z"] = 27, ["name"] = "default:wood"}, {["x"] = 10, ["y"] = 13, ["param1"] = 56, ["z"] = 28, ["name"] = "default:wood"}, {["x"] = 10, ["y"] = 13, ["param1"] = 56, ["z"] = 29, ["name"] = "default:wood"}, {["x"] = 10, ["y"] = 13, ["param1"] = 56, ["z"] = 30, ["name"] = "default:wood"}, {["x"] = 10, ["y"] = 13, ["param1"] = 56, ["z"] = 31, ["name"] = "default:wood"}, {["x"] = 10, ["y"] = 13, ["z"] = 32, ["name"] = "default:wood"}, {["x"] = 10, ["y"] = 13, ["z"] = 33, ["name"] = "default:wood"}, {["x"] = 10, ["y"] = 14, ["param1"] = 56, ["z"] = 26, ["name"] = "default:wood"}, {["x"] = 10, ["y"] = 14, ["param1"] = 56, ["z"] = 27, ["name"] = "default:wood"}, {["x"] = 10, ["y"] = 14, ["param1"] = 56, ["z"] = 28, ["name"] = "default:wood"}, {["x"] = 10, ["y"] = 14, ["param1"] = 56, ["z"] = 29, ["name"] = "default:wood"}, {["x"] = 10, ["y"] = 14, ["param1"] = 56, ["z"] = 30, ["name"] = "default:wood"}, {["x"] = 10, ["y"] = 14, ["param1"] = 56, ["z"] = 31, ["name"] = "default:wood"}, {["x"] = 10, ["y"] = 14, ["z"] = 32, ["name"] = "default:wood"}, {["x"] = 10, ["y"] = 14, ["z"] = 33, ["name"] = "default:wood"}, {["x"] = 10, ["y"] = 15, ["param1"] = 56, ["z"] = 27, ["name"] = "default:wood"}, {["x"] = 10, ["y"] = 15, ["param1"] = 56, ["z"] = 28, ["name"] = "default:wood"}, {["x"] = 10, ["y"] = 15, ["param1"] = 56, ["z"] = 29, ["name"] = "default:wood"}, {["x"] = 10, ["y"] = 15, ["param1"] = 56, ["z"] = 30, ["name"] = "default:wood"}, {["x"] = 10, ["y"] = 15, ["param1"] = 56, ["z"] = 31, ["name"] = "default:wood"}, {["x"] = 10, ["y"] = 15, ["z"] = 32, ["name"] = "default:wood"}, {["x"] = 10, ["y"] = 16, ["z"] = 28, ["name"] = "default:wood"}, {["x"] = 10, ["y"] = 16, ["z"] = 29, ["name"] = "default:wood"}, {["x"] = 10, ["y"] = 16, ["z"] = 30, ["name"] = "default:wood"}, {["x"] = 10, ["y"] = 16, ["z"] = 31, ["name"] = "default:wood"}, {["x"] = 10, ["y"] = 17, ["z"] = 29, ["name"] = "default:wood"}, {["x"] = 10, ["y"] = 17, ["z"] = 30, ["name"] = "default:wood"}, {["x"] = 11, ["y"] = 0, ["param1"] = 56, ["z"] = 16, ["name"] = "default:wood"}, {["x"] = 11, ["y"] = 0, ["param1"] = 56, ["z"] = 17, ["name"] = "default:wood"}, {["x"] = 11, ["y"] = 0, ["param1"] = 56, ["z"] = 18, ["name"] = "default:wood"}, {["x"] = 11, ["y"] = 1, ["param1"] = 56, ["z"] = 15, ["name"] = "default:wood"}, {["x"] = 11, ["y"] = 1, ["param1"] = 56, ["z"] = 16, ["name"] = "default:wood"}, {["x"] = 11, ["y"] = 1, ["param1"] = 56, ["z"] = 17, ["name"] = "default:wood"}, {["x"] = 11, ["y"] = 1, ["param1"] = 56, ["z"] = 18, ["name"] = "default:wood"}, {["x"] = 11, ["y"] = 1, ["param1"] = 56, ["z"] = 19, ["name"] = "default:wood"}, {["x"] = 11, ["y"] = 2, ["param1"] = 56, ["z"] = 16, ["name"] = "default:wood"}, {["x"] = 11, ["y"] = 2, ["param1"] = 56, ["z"] = 17, ["name"] = "default:wood"}, {["x"] = 11, ["y"] = 2, ["param1"] = 56, ["z"] = 18, ["name"] = "default:wood"}, {["x"] = 11, ["y"] = 2, ["param1"] = 56, ["z"] = 19, ["name"] = "default:wood"}, {["x"] = 11, ["y"] = 2, ["param1"] = 56, ["z"] = 20, ["name"] = "default:wood"}, {["x"] = 11, ["y"] = 3, ["param1"] = 56, ["z"] = 17, ["name"] = "default:wood"}, {["x"] = 11, ["y"] = 3, ["param1"] = 56, ["z"] = 18, ["name"] = "default:wood"}, {["x"] = 11, ["y"] = 3, ["param1"] = 56, ["z"] = 19, ["name"] = "default:wood"}, {["x"] = 11, ["y"] = 3, ["param1"] = 56, ["z"] = 20, ["name"] = "default:wood"}, {["x"] = 11, ["y"] = 3, ["param1"] = 56, ["z"] = 21, ["name"] = "default:wood"}, {["x"] = 11, ["y"] = 4, ["param1"] = 56, ["z"] = 18, ["name"] = "default:wood"}, {["x"] = 11, ["y"] = 4, ["param1"] = 56, ["z"] = 19, ["name"] = "default:wood"}, {["x"] = 11, ["y"] = 4, ["param1"] = 56, ["z"] = 20, ["name"] = "default:wood"}, {["x"] = 11, ["y"] = 4, ["param1"] = 56, ["z"] = 21, ["name"] = "default:wood"}, {["x"] = 11, ["y"] = 4, ["param1"] = 56, ["z"] = 22, ["name"] = "default:wood"}, {["x"] = 11, ["y"] = 5, ["param1"] = 56, ["z"] = 19, ["name"] = "default:wood"}, {["x"] = 11, ["y"] = 5, ["param1"] = 56, ["z"] = 20, ["name"] = "default:wood"}, {["x"] = 11, ["y"] = 5, ["param1"] = 56, ["z"] = 21, ["name"] = "default:wood"}, {["x"] = 11, ["y"] = 5, ["param1"] = 56, ["z"] = 22, ["name"] = "default:wood"}, {["x"] = 11, ["y"] = 5, ["param1"] = 56, ["z"] = 23, ["name"] = "default:wood"}, {["x"] = 11, ["y"] = 6, ["param1"] = 56, ["z"] = 20, ["name"] = "default:wood"}, {["x"] = 11, ["y"] = 6, ["param1"] = 56, ["z"] = 21, ["name"] = "default:wood"}, {["x"] = 11, ["y"] = 6, ["param1"] = 56, ["z"] = 22, ["name"] = "default:wood"}, {["x"] = 11, ["y"] = 6, ["param1"] = 56, ["z"] = 23, ["name"] = "default:wood"}, {["x"] = 11, ["y"] = 6, ["param1"] = 56, ["z"] = 24, ["name"] = "default:wood"}, {["x"] = 11, ["y"] = 7, ["param1"] = 56, ["z"] = 21, ["name"] = "default:wood"}, {["x"] = 11, ["y"] = 7, ["param1"] = 56, ["z"] = 22, ["name"] = "default:wood"}, {["x"] = 11, ["y"] = 7, ["param1"] = 56, ["z"] = 23, ["name"] = "default:wood"}, {["x"] = 11, ["y"] = 7, ["param1"] = 56, ["z"] = 24, ["name"] = "default:wood"}, {["x"] = 11, ["y"] = 7, ["param1"] = 56, ["z"] = 25, ["name"] = "default:wood"}, {["x"] = 11, ["y"] = 8, ["param1"] = 56, ["z"] = 22, ["name"] = "default:wood"}, {["x"] = 11, ["y"] = 8, ["param1"] = 56, ["z"] = 23, ["name"] = "default:wood"}, {["x"] = 11, ["y"] = 8, ["param1"] = 56, ["z"] = 24, ["name"] = "default:wood"}, {["x"] = 11, ["y"] = 8, ["param1"] = 56, ["z"] = 25, ["name"] = "default:wood"}, {["x"] = 11, ["y"] = 8, ["param1"] = 56, ["z"] = 26, ["name"] = "default:wood"}, {["x"] = 11, ["y"] = 9, ["param1"] = 56, ["z"] = 23, ["name"] = "default:wood"}, {["x"] = 11, ["y"] = 9, ["param1"] = 56, ["z"] = 24, ["name"] = "default:wood"}, {["x"] = 11, ["y"] = 9, ["param1"] = 56, ["z"] = 25, ["name"] = "default:wood"}, {["x"] = 11, ["y"] = 9, ["param1"] = 56, ["z"] = 26, ["name"] = "default:wood"}, {["x"] = 11, ["y"] = 9, ["param1"] = 56, ["z"] = 27, ["name"] = "default:wood"}, {["x"] = 11, ["y"] = 10, ["param1"] = 56, ["z"] = 24, ["name"] = "default:wood"}, {["x"] = 11, ["y"] = 10, ["param1"] = 56, ["z"] = 25, ["name"] = "default:wood"}, {["x"] = 11, ["y"] = 10, ["param1"] = 56, ["z"] = 26, ["name"] = "default:wood"}, {["x"] = 11, ["y"] = 10, ["param1"] = 56, ["z"] = 27, ["name"] = "default:wood"}, {["x"] = 11, ["y"] = 10, ["param1"] = 56, ["z"] = 28, ["name"] = "default:wood"}, {["x"] = 11, ["y"] = 11, ["param1"] = 56, ["z"] = 25, ["name"] = "default:wood"}, {["x"] = 11, ["y"] = 11, ["param1"] = 56, ["z"] = 26, ["name"] = "default:wood"}, {["x"] = 11, ["y"] = 11, ["param1"] = 56, ["z"] = 27, ["name"] = "default:wood"}, {["x"] = 11, ["y"] = 11, ["param1"] = 56, ["z"] = 28, ["name"] = "default:wood"}, {["x"] = 11, ["y"] = 11, ["param1"] = 56, ["z"] = 29, ["name"] = "default:wood"}, {["x"] = 11, ["y"] = 12, ["param1"] = 56, ["z"] = 26, ["name"] = "default:wood"}, {["x"] = 11, ["y"] = 12, ["param1"] = 56, ["z"] = 27, ["name"] = "default:wood"}, {["x"] = 11, ["y"] = 12, ["param1"] = 56, ["z"] = 28, ["name"] = "default:wood"}, {["x"] = 11, ["y"] = 12, ["param1"] = 56, ["z"] = 29, ["name"] = "default:wood"}, {["x"] = 11, ["y"] = 12, ["param1"] = 56, ["z"] = 30, ["name"] = "default:wood"}, {["x"] = 11, ["y"] = 13, ["param1"] = 56, ["z"] = 27, ["name"] = "default:wood"}, {["x"] = 11, ["y"] = 13, ["param1"] = 56, ["z"] = 28, ["name"] = "default:wood"}, {["x"] = 11, ["y"] = 13, ["param1"] = 56, ["z"] = 29, ["name"] = "default:wood"}, {["x"] = 11, ["y"] = 13, ["param1"] = 56, ["z"] = 30, ["name"] = "default:wood"}, {["x"] = 11, ["y"] = 13, ["param1"] = 56, ["z"] = 31, ["name"] = "default:wood"}, {["x"] = 11, ["y"] = 14, ["param1"] = 56, ["z"] = 28, ["name"] = "default:wood"}, {["x"] = 11, ["y"] = 14, ["param1"] = 56, ["z"] = 29, ["name"] = "default:wood"}, {["x"] = 11, ["y"] = 14, ["param1"] = 56, ["z"] = 30, ["name"] = "default:wood"}, {["x"] = 11, ["y"] = 14, ["param1"] = 56, ["z"] = 31, ["name"] = "default:wood"}, {["x"] = 11, ["y"] = 14, ["z"] = 32, ["name"] = "default:wood"}, {["x"] = 11, ["y"] = 15, ["param1"] = 56, ["z"] = 29, ["name"] = "default:wood"}, {["x"] = 11, ["y"] = 15, ["param1"] = 56, ["z"] = 30, ["name"] = "default:wood"}, {["x"] = 11, ["y"] = 15, ["param1"] = 56, ["z"] = 31, ["name"] = "default:wood"}, {["x"] = 11, ["y"] = 15, ["z"] = 32, ["name"] = "default:wood"}, {["x"] = 11, ["y"] = 16, ["z"] = 30, ["name"] = "default:wood"}, {["x"] = 11, ["y"] = 16, ["z"] = 31, ["name"] = "default:wood"}}